Workbook

Sheet DCF>

Sheet WACC
B3: Weighted Average Cost of Capital
B6: All figures are in INR unless stated otherwise
B8: Peer Comps
H10: Debt/ | I10: Debt/ | J10: Levered | K10: Unlevered
B11: Name of the Comp | D11: Country | E11: Total Debt | F11: Total Equity | G11: Tax Rate | H11: Equity | I11: Capital | J11: Beta2 | K11: Beta3
B13: Apollo Hospitals | D13: India | E13: 7864 | F13: =100780.84 -> 100780.84 | G13: 0.18 | H13: =E13/F13 -> 0.078030705 | I13: =E13/(F13+E13) -> 0.072382637 | J13: ='Beta Calculation - Apollo'!N8 -> 0.88912475 | K13: =J13/(1+(1-G13)*H13) -> 0.83565521
B14: Fortis Health | D14: India | E14: 2475 | F14: =57815.14 -> 57815.14 | G14: 0.18 | H14: =E14/F14 -> 0.042808856 | I14: =E14/(F14+E14) -> 0.041051489 | J14: ='Beta Calculation - Fortis'!N8 -> 0.88775227 | K14: =J14/(1+(1-G14)*H14) -> 0.8576461
B15: Dr Lal Pathlabs | D15: India | E15: 157 | F15: =22939.24 -> 22939.24 | G15: 0.18 | H15: =E15/F15 -> 0.0068441675 | I15: =E15/(F15+E15) -> 0.0067976433 | J15: ='Beta Calculation - Dr Lal'!N8 -> 0.58250537 | K15: =J15/(1+(1-G15)*H15) -> 0.57925447
B16: Sun Pharma.Inds | D16: India | E16: 2362 | F16: =398901.44 -> 398901.44 | G16: 0.18 | H16: =E16/F16 -> 0.0059212622 | I16: =E16/(F16+E16) -> 0.0058864072 | J16: ='Beta Calculation - Sun Pharma '!N8 -> 0.67898559 | K16: =J16/(1+(1-G16)*H16) -> 0.67570475
B17: Aurobindo Pharma | D17: India | E17: 8263 | F17: =64696.4 -> 64696.4 | G17: 0.18 | H17: =E17/F17 -> 0.12771963 | I17: =E17/(F17+E17) -> 0.11325477 | J17: ='Beta Calculation - Aurobindo'!N8 -> 1.0808851 | K17: =J17/(1+(1-G17)*H17) -> 0.97841551
B18: Biocon | D18: India | E18: 18362 | F18: =41936.86 -> 41936.86 | G18: 0.18 | H18: =E18/F18 -> 0.43784871 | I18: =E18/(F18+E18) -> 0.30451654 | J18: ='Beta Calculation - Biocon '!N8 -> 1.4958582 | K18: =J18/(1+(1-G18)*H18) -> 1.100676
B19: Max Healthcare | D19: India | E19: 3010 | F19: =116287.18 -> 116287.18 | G19: 0.18 | H19: =E19/F19 -> 0.025884195 | I19: =E19/(F19+E19) -> 0.025231108 | J19: ='Beta Calculation - Max Health'!N8 -> 1.351525 | K19: =J19/(1+(1-G19)*H19) -> 1.323435
B20: Gland Pharma | D20: India | E20: 314 | F20: =29087.87 -> 29087.87 | G20: 0.18 | H20: =E20/F20 -> 0.010794878 | I20: =E20/(F20+E20) -> 0.010679593 | J20: ='Beta Calculation - Gland'!N8 -> 0.59069484 | K20: =J20/(1+(1-G20)*H20) -> 0.58551201
B21: Cipla | D21: India | E21: 438 | F21: =121410.77 -> 121410.77 | G21: 0.18 | H21: =E21/F21 -> 0.0036075877 | I21: =E21/(F21+E21) -> 0.0035946198 | J21: ='Beta Calculation - Cipla'!N8 -> 0.59166256 | K21: =J21/(1+(1-G21)*H21) -> 0.58991745
B22: Metropolis Healthcare | D22: India | E22: 204 | F22: =8772.46 -> 8772.46 | G22: 0.18 | H22: =E22/F22 -> 0.023254594 | I22: =E22/(F22+E22) -> 0.022726108 | J22: ='Beta Calculation - Metropolis '!N8 -> 0.93845271 | K22: =J22/(1+(1-G22)*H22) -> 0.92089242
F24: Average | G24: =AVERAGE(G13:G22) -> 0.18 | H24: =AVERAGE(H13:H22) -> 0.076271458 | I24: =AVERAGE(I13:I22) -> 0.060612091 | J24: =AVERAGE(J13:J22) -> 0.90874464 | K24: =AVERAGE(K13:K22) -> 0.84471089
F25: Median | G25: =MEDIAN(G13:G22) -> 0.18 | H25: =MEDIAN(H13:H22) -> 0.024569395 | I25: =MEDIAN(I13:I22) -> 0.023978608 | J25: =MEDIAN(J13:J22) -> 0.88843851 | K25: =MEDIAN(K13:K22) -> 0.84665065
B26: ="For "&B18 -> For Biocon
B28: Cost of Debt | G28: Cost of Equity
B30: Pre-Tax cost of Debt | E30: =897/E18 -> 0.048850888 | G30: Risk free Rate | K30: 0.06247
B31: Tax Rate | E31: =G18 -> 0.18 | G31: Equity Risk Premium | K31: =Rm!F9-WACC!K30 -> 0.090878
B32: Post Tax Cost of Debt | E32: =E30*(1-E31) -> 0.040057728 | G32: Levered Beta | K32: =K41 -> 0.89144595
G33: Cost of Equity | K33: =K30+K31*K32 -> 0.14348282
B36: Capital Structure | G36: Levered Beta
D38: Current | E38: Target | G38: Comps Median Unlevered Beta | K38: =K25 -> 0.84665065
B39: Total Debt | C39: =E18 -> 18362 | D39: =C39/C41 -> 0.30451654 | E39: =I24 -> 0.060612091 | G39: Target Debt/ Equity | K39: =E43 -> 0.064522963
B40: Market Capitalization | C40: =F18 -> 41936.86 | D40: =C40/C41 -> 0.69548346 | E40: =E41-E39 -> 0.93938791 | G40: Tax Rate | K40: =G18 -> 0.18
B41: Total Capital | C41: =C40+C39 -> 60298.86 | D41: =D40+D39 -> 1 | E41: =100% -> 1 | G41: Levered Beta | K41: =K38*(1+(1-K40)*K39) -> 0.89144595
B43: Debt/ Equity | D43: =D39/D40 -> 0.43784871 | E43: =E39/E40 -> 0.064522963 | G43: Weighted Average Cost of Capital (WACC)
J45: Total Cost | K45: Total Weight
B46: Notes: | G46: Debt | J46: =E32 -> 0.040057728 | K46: =E39 -> 0.060612091
B47: 1. Tax Rate considered as Marginal Tax Rate for the country | G47: Equity | J47: =K33 -> 0.14348282 | K47: =E40 -> 0.93938791
B48: 2. Levered beta is based on 5 year monthly data | G48: Weighted Average Cost of Capital | K48: =SUMPRODUCT(J46:J47,K46:K47) -> 0.13721401
B49: 3. Unlevered Beta = Levered Beta/(1+(1-Tax Rate)*Debt / Equity)
B50: 4. Levered Beta = Unlevered Beta*(1+(1-Tax Rate)*Debt / Equity)

Sheet Rm
B2: Return on Markets
B6: Year | C6: Annual
B7: 2000 | C7: -0.1465 | E7: Average Return | F7: =AVERAGE(C7:C31) -> 0.153348
B8: 2001 | C8: -0.1618 | E8: Dividend Yield | F8: 1.29%1
B9: 2002 | C9: 0.0325 | E9: Total Market Return | F9: =SUM(F7:F8) -> 0.153348
B10: 2003 | C10: 0.719
B11: 2004 | C11: 0.1068
B12: 2005 | C12: 0.3634
B13: 2006 | C13: 0.3983
B14: 2007 | C14: 0.5477
B15: 2008 | C15: -0.5179
B16: 2009 | C16: 0.7576
B17: 2010 | C17: 0.1795
B18: 2011 | C18: -0.2462
B19: 2012 | C19: 0.277
B20: 2013 | C20: 0.0676
B21: 2014 | C21: 0.3139
... B31: 2024 | C31: 0.0875
B32: 2025

Sheet Data>

Sheet Beta Calculation - Apollo
B3: Regression Beta - 2 Years Weekly
B5: Apollo Hospital Weekly Returns | G5: Nifty Returns | J5: Beta Drifting | M5: Beta 1 (Slope) | N5: =SLOPE(D9:D109,H9:H109) -> 0.88912475
J6: Levered Raw Beta | K6: =N8 -> 0.88912475 | M6: Beta 2 (Formula) | N6: =_xlfn.COVARIANCE.S(D9:D109,H9:H109)/_xlfn.VAR.S(H9:H109) -> 0.88912475
B7: Date | C7: Closing Price | D7: Return | G7: Closing Price | H7: Return | J7: Raw Beta Weight | K7: 0.75
B8: 45100 | C8: 5016.8123 | G8: 18665.5 | J8: Market Beta Weight | K8: 0.25 | M8: Beta 3 (Regression) | N8: =N31 -> 0.88912475
B9: 45107 | C9: 5069.2628 | D9: =C8/C9-1 -> -0.010346789 | G9: 19189.05 | H9: =G8/G9-1 -> -0.027283789 | J9: Market Beta | K9: 1
B10: 45114 | C10: 5117.0401 | D10: =C9/C10-1 -> -0.0093368958 | G10: 19331.8 | H10: =G9/G10-1 -> -0.0073842063
B11: 45121 | C11: 5142.4451 | D11: =C10/C11-1 -> -0.0049402529 | G11: 19564.5 | H11: =G10/G11-1 -> -0.011893992 | J11: Adjusted Beta | K11: =(K6*K7)+(K8*K9) -> 0.91684357
B12: 45128 | C12: 5175.3572 | D12: =C11/C12-1 -> -0.0063593921 | G12: 19745 | H12: =G11/G12-1 -> -0.0091415548
B13: 45135 | C13: 5316.601 | D13: =C12/C13-1 -> -0.026566547 | G13: 19646.05 | H13: =G12/G13-1 -> 0.0050366359
B14: 45142 | C14: 4952.032 | D14: =C13/C14-1 -> 0.073620063 | G14: 19517 | H14: =G13/G14-1 -> 0.0066121842 | M14: SUMMARY OUTPUT
B15: 45149 | C15: 4878.3029 | D15: =C14/C15-1 -> 0.015113684 | G15: 19428.3 | H15: =G14/G15-1 -> 0.004565505
B16: 45156 | C16: 4829.715 | D16: =C15/C16-1 -> 0.010060196 | G16: 19310.15 | H16: =G15/G16-1 -> 0.0061185439 | M16: Regression Statistics
B17: 45163 | C17: 4846.7991 | D17: =C16/C17-1 -> -0.0035248176 | G17: 19265.8 | H17: =G16/G17-1 -> 0.0023020067 | M17: Multiple R | N17: 0.49089289
B18: 45170 | C18: 4821.7458 | D18: =C17/C18-1 -> 0.0051959053 | G18: 19435.3 | H18: =G17/G18-1 -> -0.0087212443 | M18: R Square | N18: 0.24097583
B19: 45177 | C19: 4965.9892 | D19: =C18/C19-1 -> -0.029046267 | G19: 19819.95 | H19: =G18/G19-1 -> -0.019407213 | M19: Adjusted R Square | N19: 0.23330892
B20: 45184 | C20: 5072.2293 | D20: =C19/C20-1 -> -0.020945442 | G20: 20192.35 | H20: =G19/G20-1 -> -0.018442628 | M20: Standard Error | N20: 0.026602858
B21: 45191 | C21: 4970.3723 | D21: =C20/C21-1 -> 0.02049283 | G21: 19674.25 | H21: =G20/G21-1 -> 0.026333914 | M21: Observations | N21: 101
B22: 45198 | C22: 5118.0027 | D22: =C21/C22-1 -> -0.028845312 | G22: 19638.3 | H22: =G21/G22-1 -> 0.0018306065
B23: 45205 | C23: 5040.8006 | D23: =C22/C23-1 -> 0.015315449 | G23: 19653.5 | H23: =G22/G23-1 -> -0.00077339914 | M23: ANOVA
B24: 45212 | C24: 4998.0157 | D24: =C23/C24-1 -> 0.0085603811 | G24: 19751.05 | H24: =G23/G24-1 -> -0.0049389779 | N24: df | O24: SS | P24: MS | Q24: F | R24: Significance F
B25: 45219 | C25: 4958.4184 | D25: =C24/C25-1 -> 0.0079858565 | G25: 19542.65 | H25: =G24/G25-1 -> 0.010663856 | M25: Regression | N25: 1 | O25: 0.022243835 | P25: 0.022243835 | Q25: 31.430629 | R25: 1.8709078e-07
B26: 45226 | C26: 4811.6348 | D26: =C25/C26-1 -> 0.030505983 | G26: 19047.25 | H26: =G25/G26-1 -> 0.026009004 | M26: Residual | N26: 99 | O26: 0.070063495 | P26: 0.00070771207
B27: 45233 | C27: 5133.3933 | D27: =C26/C27-1 -> -0.0626795 | G27: 19230.6 | H27: =G26/G27-1 -> -0.0095342839 | M27: Total | N27: 100 | O27: 0.09230733
B28: 45240 | C28: 5258.2117 | D28: =C27/C28-1 -> -0.023737804 | G28: 19425.35 | H28: =G27/G28-1 -> -0.010025559
B29: 45247 | C29: 5457.8913 | D29: =C28/C29-1 -> -0.036585477 | G29: 19731.8 | H29: =G28/G29-1 -> -0.015530768 | N29: Coefficients | O29: Standard Error | P29: t Stat | Q29: P-value | R29: Lower 95% | S29: Upper 95% | T29: Lower 95.0% | U29: Upper 95.0%
B30: 45254 | C30: 5380.5397 | D30: =C29/C30-1 -> 0.014376169 | G30: 19794.7 | H30: =G29/G30-1 -> -0.0031776183 | M30: Intercept | N30: -0.00028462044 | O30: 0.0026810797 | P30: -0.10615889 | Q30: 0.9156711 | R30: -0.0056044643 | S30: 0.0050352234 | T30: -0.0056044643 | U30: 0.0050352234
B31: 45261 | C31: 5569.66 | D31: =C30/C31-1 -> -0.033955447 | G31: 20267.9 | H31: =G30/G31-1 -> -0.023347263 | M31: X Variable 1 | N31: 0.88912475 | O31: 0.15859379 | P31: 5.6063026 | Q31: 1.8709078e-07 | R31: 0.57444028 | S31: 1.2038092 | T31: 0.57444028 | U31: 1.2038092
B32: 45268 | C32: 5533.9976 | D32: =C31/C32-1 -> 0.0064442384 | G32: 20969.4 | H32: =G31/G32-1 -> -0.033453508
B33: 45275 | C33: 5529.8636 | D33: =C32/C33-1 -> 0.00074758611 | G33: 21456.65 | H33: =G32/G33-1 -> -0.022708578
B34: 45282 | C34: 5520.1012 | D34: =C33/C34-1 -> 0.0017685062 | G34: 21349.4 | H34: =G33/G34-1 -> 0.0050235604
B35: 45289 | C35: 5682.1759 | D35: =C34/C35-1 -> -0.028523343 | G35: 21731.4 | H35: =G34/G35-1 -> -0.017578251
B36: 45296 | C36: 5732.1331 | D36: =C35/C36-1 -> -0.0087152974 | G36: 21710.8 | H36: =G35/G36-1 -> 0.00094883652
B37: 45303 | C37: 5773.4238 | D37: =C36/C37-1 -> -0.007151854 | G37: 21894.55 | H37: =G36/G37-1 -> -0.0083924995
B38: 45311 | C38: 6099.0176 | D38: =C37/C38-1 -> -0.053384619 | G38: 21622.4 | H38: =G37/G38-1 -> 0.012586484
B39: 45316 | C39: 6145.1396 | D39: =C38/C39-1 -> -0.0075054508 | G39: 21352.6 | H39: =G38/G39-1 -> 0.012635464
B40: 45324 | C40: 6296.2565 | D40: =C39/C40-1 -> -0.024001076 | G40: 21853.8 | H40: =G39/G40-1 -> -0.022934227
B41: 45331 | C41: 6412.6076 | D41: =C40/C41-1 -> -0.018144112 | G41: 21782.5 | H41: =G40/G41-1 -> 0.0032732698
B42: 45338 | C42: 6575.1803 | D42: =C41/C42-1 -> -0.024725212 | G42: 22040.7 | H42: =G41/G42-1 -> -0.011714691
B43: 45345 | C43: 6754.1009 | D43: =C42/C43-1 -> -0.02649065 | G43: 22212.7 | H43: =G42/G43-1 -> -0.007743318
...

Sheet Beta Calculation - Dr Lal
B3: Regression Beta - 2 Years Weekly
B5: Dr Lal Pathlabs Weekly Returns | G5: Nifty Returns | J5: Beta Drifting | M5: Beta 1 (Slope) | N5: =SLOPE(D9:D109,H9:H109) -> 0.58250537
J6: Levered Raw Beta | K6: =N8 -> 0.58250537 | M6: Beta 2 (Formula) | N6: =_xlfn.COVARIANCE.S(H9:H109,D9:D109)/_xlfn.VAR.S(H9:H109) -> 0.58250537
B7: Date | C7: Closing Price | D7: Return | G7: Closing Price | H7: Return | J7: Raw Beta Weight | K7: 0.75
B8: 45100 | C8: 2067.8061 | G8: 18665.5 | J8: Market Beta Weight | K8: 0.25 | M8: Beta 3 (Regression) | N8: =N31 -> 0.58250537
B9: 45107 | C9: 2214.3759 | D9: =C9/C8-1 -> 0.070881816 | G9: 19189.05 | H9: =G9/G8-1 -> 0.028049074 | J9: Market Beta | K9: 1
B10: 45114 | C10: 2312.5792 | D10: =C10/C9-1 -> 0.044348057 | G10: 19331.8 | H10: =G10/G9-1 -> 0.0074391385
B11: 45121 | C11: 2309.59 | D11: =C11/C10-1 -> -0.001292592 | G11: 19564.5 | H11: =G11/G10-1 -> 0.012037162 | J11: Adjusted Beta | K11: =(K6*K7)+(K8*K9) -> 0.68687903
B12: 45128 | C12: 2241.3279 | D12: =C12/C11-1 -> -0.029555919 | G12: 19745 | H12: =G12/G11-1 -> 0.0092258938
B13: 45135 | C13: 2307.7278 | D13: =C13/C12-1 -> 0.029625257 | G13: 19646.05 | H13: =G13/G12-1 -> -0.0050113953
B14: 45142 | C14: 2303.1215 | D14: =C14/C13-1 -> -0.0019960504 | G14: 19517 | H14: =G14/G13-1 -> -0.0065687505 | M14: SUMMARY OUTPUT
B15: 45149 | C15: 2263.7147 | D15: =C15/C14-1 -> -0.017110167 | G15: 19428.3 | H15: =G15/G14-1 -> -0.0045447559
B16: 45156 | C16: 2208.5009 | D16: =C16/C15-1 -> -0.024390775 | G16: 19310.15 | H16: =G16/G15-1 -> -0.006081335 | M16: Regression Statistics
B17: 45163 | C17: 2171.6589 | D17: =C17/C16-1 -> -0.016681906 | G17: 19265.8 | H17: =G17/G16-1 -> -0.0022967196 | M17: Multiple R | N17: 0.25444408
B18: 45170 | C18: 2168.4082 | D18: =C18/C17-1 -> -0.0014969041 | G18: 19435.3 | H18: =G18/G17-1 -> 0.0087979736 | M18: R Square | N18: 0.064741791
B19: 45177 | C19: 2184.3172 | D19: =C19/C18-1 -> 0.0073367405 | G19: 19819.95 | H19: =G19/G18-1 -> 0.019791308 | M19: Adjusted R Square | N19: 0.055294738
B20: 45184 | C20: 2300.9507 | D20: =C20/C19-1 -> 0.053395869 | G20: 20192.35 | H20: =G20/G19-1 -> 0.018789149 | M20: Standard Error | N20: 0.037412555
B21: 45191 | C21: 2304.694 | D21: =C21/C20-1 -> 0.0016268516 | G21: 19674.25 | H21: =G21/G20-1 -> -0.025658232 | M21: Observations | N21: 101
B22: 45198 | C22: 2486.6876 | D22: =C22/C21-1 -> 0.07896649 | G22: 19638.3 | H22: =G22/G21-1 -> -0.0018272615
B23: 45205 | C23: 2442.6545 | D23: =C23/C22-1 -> -0.017707529 | G23: 19653.5 | H23: =G23/G22-1 -> 0.00077399775 | M23: ANOVA
B24: 45212 | C24: 2509.3937 | D24: =C24/C23-1 -> 0.027322404 | G24: 19751.05 | H24: =G24/G23-1 -> 0.0049634925 | N24: df | O24: SS | P24: MS | Q24: F | R24: Significance F
B25: 45219 | C25: 2474.2264 | D25: =C25/C24-1 -> -0.014014289 | G25: 19542.65 | H25: =G25/G24-1 -> -0.010551338 | M25: Regression | N25: 1 | O25: 0.009592308 | P25: 0.009592308 | Q25: 6.8531206 | R25: 0.010237271
B26: 45226 | C26: 2327.6464 | D26: =C26/C25-1 -> -0.059242744 | G26: 19047.25 | H26: =G26/G25-1 -> -0.025349684 | M26: Residual | N26: 99 | O26: 0.13857023 | P26: 0.0013996993
B27: 45233 | C27: 2555.9388 | D27: =C27/C26-1 -> 0.098078632 | G27: 19230.6 | H27: =G27/G26-1 -> 0.0096260615 | M27: Total | N27: 100 | O27: 0.14816254
B28: 45240 | C28: 2636.9616 | D28: =C28/C27-1 -> 0.031699844 | G28: 19425.35 | H28: =G28/G27-1 -> 0.010127089
B29: 45247 | C29: 2658.4856 | D29: =C29/C28-1 -> 0.0081624267 | G29: 19731.8 | H29: =G29/G28-1 -> 0.015775778 | N29: Coefficients | O29: Standard Error | P29: t Stat | Q29: P-value | R29: Lower 95% | S29: Upper 95% | T29: Lower 95.0% | U29: Upper 95.0%
B30: 45254 | C30: 2647.4035 | D30: =C30/C29-1 -> -0.0041685966 | G30: 19794.7 | H30: =G30/G29-1 -> 0.0031877477 | M30: Intercept | N30: 0.0019383514 | O30: 0.0037809222 | P30: 0.51266631 | Q30: 0.60932674 | R30: -0.0055638184 | S30: 0.0094405213 | T30: -0.0055638184 | U30: 0.0094405213
B31: 45261 | C31: 2702.1247 | D31: =C31/C30-1 -> 0.020669767 | G31: 20267.9 | H31: =G31/G30-1 -> 0.023905389 | M31: X Variable 1 | N31: 0.58250537 | O31: 0.22251318 | P31: 2.6178466 | Q31: 0.010237271 | R31: 0.14099094 | S31: 1.0240198 | T31: 0.14099094 | U31: 1.0240198
B32: 45268 | C32: 2599.1838 | D32: =C32/C31-1 -> -0.03809628 | G32: 20969.4 | H32: =G32/G31-1 -> 0.034611381
B33: 45275 | C33: 2490.2832 | D33: =C33/C32-1 -> -0.041898012 | G33: 21456.65 | H33: =G33/G32-1 -> 0.023236239
B34: 45282 | C34: 2557.7612 | D34: =C34/C33-1 -> 0.027096519 | G34: 21349.4 | H34: =G34/G33-1 -> -0.0049984504
B35: 45289 | C35: 2539.2417 | D35: =C35/C34-1 -> -0.0072405161 | G35: 21731.4 | H35: =G35/G34-1 -> 0.017892775
B36: 45296 | C36: 2558.8448 | D36: =C36/C35-1 -> 0.0077200605 | G36: 21710.8 | H36: =G36/G35-1 -> -0.00094793709
B37: 45303 | C37: 2416.8454 | D37: =C37/C36-1 -> -0.055493532 | G37: 21894.55 | H37: =G37/G36-1 -> 0.0084635297
B38: 45311 | C38: 2388.5736 | D38: =C38/C37-1 -> -0.011697813 | G38: 21622.4 | H38: =G38/G37-1 -> -0.012430034
B39: 45316 | C39: 2364.6854 | D39: =C39/C38-1 -> -0.010001031 | G39: 21352.6 | H39: =G39/G38-1 -> -0.012477801
B40: 45324 | C40: 2416.6484 | D40: =C40/C39-1 -> 0.021974589 | G40: 21853.8 | H40: =G40/G39-1 -> 0.023472551
B41: 45331 | C41: 2415.3186 | D41: =C41/C40-1 -> -0.00055029043 | G41: 21782.5 | H41: =G41/G40-1 -> -0.0032625905
B42: 45338 | C42: 2446.6657 | D42: =C42/C41-1 -> 0.012978456 | G42: 22040.7 | H42: =G42/G41-1 -> 0.011853552
B43: 45345 | C43: 2423.3037 | D43: =C43/C42-1 -> -0.0095484706 | G43: 22212.7 | H43: =G43/G42-1 -> 0.0078037449
...

Sheet Beta Calculation - Gland
B3: Regression Beta - 2 Years Weekly
B5: Gland Pharma Weekly Returns | G5: Nifty Returns | J5: Beta Drifting | M5: Beta 1 (Slope) | N5: =SLOPE(D9:D109,H9:H109) -> 0.59069484
J6: Levered Raw Beta | K6: =N8 -> 0.59069484 | M6: Beta 2 (Formula) | N6: =_xlfn.COVARIANCE.S(D9:D109,H9:H109)/_xlfn.VAR.S(H9:H109) -> 0.59069484
B7: Date | C7: Closing Price | D7: Return | G7: Closing Price | H7: Return | J7: Raw Beta Weight | K7: 0.75
B8: 45100 | C8: 969.99106 | G8: 18665.5 | J8: Market Beta Weight | K8: 0.25 | M8: Beta 3 (Regression) | N8: =N31 -> 0.59069484
B9: 45107 | C9: 1051.6485 | D9: =C9/C8-1 -> 0.084183673 | G9: 19189.05 | H9: =G9/G8-1 -> 0.028049074 | J9: Market Beta | K9: 1
B10: 45114 | C10: 1035.4655 | D10: =C10/C9-1 -> -0.015388235 | G10: 19331.8 | H10: =G10/G9-1 -> 0.0074391385
B11: 45121 | C11: 1125.1401 | D11: =C11/C10-1 -> 0.08660326 | G11: 19564.5 | H11: =G11/G10-1 -> 0.012037162 | J11: Adjusted Beta | K11: =(K6*K7)+(K8*K9) -> 0.69302113
B12: 45128 | C12: 1223.0301 | D12: =C12/C11-1 -> 0.087002419 | G12: 19745 | H12: =G12/G11-1 -> 0.0092258938
B13: 45135 | C13: 1278.8045 | D13: =C13/C12-1 -> 0.045603529 | G13: 19646.05 | H13: =G13/G12-1 -> -0.0050113953
B14: 45142 | C14: 1321.8108 | D14: =C14/C13-1 -> 0.033630031 | G14: 19517 | H14: =G14/G13-1 -> -0.0065687505 | M14: SUMMARY OUTPUT
B15: 45149 | C15: 1631.1686 | D15: =C15/C14-1 -> 0.23404096 | G15: 19428.3 | H15: =G15/G14-1 -> -0.0045447559
B16: 45156 | C16: 1552.6786 | D16: =C16/C15-1 -> -0.048118932 | G16: 19310.15 | H16: =G16/G15-1 -> -0.006081335 | M16: Regression Statistics
B17: 45163 | C17: 1530.8043 | D17: =C17/C16-1 -> -0.014088098 | G17: 19265.8 | H17: =G17/G16-1 -> -0.0022967196 | M17: Multiple R | N17: 0.21170528
B18: 45170 | C18: 1750.042 | D18: =C18/C17-1 -> 0.14321738 | G18: 19435.3 | H18: =G18/G17-1 -> 0.0087979736 | M18: R Square | N18: 0.044819127
B19: 45177 | C19: 1675.0657 | D19: =C19/C18-1 -> -0.042842599 | G19: 19819.95 | H19: =G19/G18-1 -> 0.019791308 | M19: Adjusted R Square | N19: 0.035170836
B20: 45184 | C20: 1678.8269 | D20: =C20/C19-1 -> 0.0022453984 | G20: 20192.35 | H20: =G20/G19-1 -> 0.018789149 | M20: Standard Error | N20: 0.046080621
B21: 45191 | C21: 1675.907 | D21: =C21/C20-1 -> -0.001739233 | G21: 19674.25 | H21: =G21/G20-1 -> -0.025658232 | M21: Observations | N21: 101
B22: 45198 | C22: 1657.9919 | D22: =C22/C21-1 -> -0.010689818 | G22: 19638.3 | H22: =G22/G21-1 -> -0.0018272615
B23: 45205 | C23: 1654.4286 | D23: =C23/C22-1 -> -0.0021491254 | G23: 19653.5 | H23: =G23/G22-1 -> 0.00077399775 | M23: ANOVA
B24: 45212 | C24: 1605.5827 | D24: =C24/C23-1 -> -0.029524379 | G24: 19751.05 | H24: =G24/G23-1 -> 0.0049634925 | N24: df | O24: SS | P24: MS | Q24: F | R24: Significance F
B25: 45219 | C25: 1542.9786 | D25: =C25/C24-1 -> -0.038991462 | G25: 19542.65 | H25: =G25/G24-1 -> -0.010551338 | M25: Regression | N25: 1 | O25: 0.0098639215 | P25: 0.0098639215 | Q25: 4.6452915 | R25: 0.033563159
B26: 45226 | C26: 1535.1098 | D26: =C26/C25-1 -> -0.0050997498 | G26: 19047.25 | H26: =G26/G25-1 -> -0.025349684 | M26: Residual | N26: 99 | O26: 0.21021894 | P26: 0.0021234236
B27: 45233 | C27: 1495.073 | D27: =C27/C26-1 -> -0.026080789 | G27: 19230.6 | H27: =G27/G26-1 -> 0.0096260615 | M27: Total | N27: 100 | O27: 0.22008286
B28: 45240 | C28: 1610.4326 | D28: =C28/C27-1 -> 0.077159881 | G28: 19425.35 | H28: =G28/G27-1 -> 0.010127089
B29: 45247 | C29: 1612.2142 | D29: =C29/C28-1 -> 0.0011062967 | G29: 19731.8 | H29: =G29/G28-1 -> 0.015775778 | N29: Coefficients | O29: Standard Error | P29: t Stat | Q29: P-value | R29: Lower 95% | S29: Upper 95% | T29: Lower 95.0% | U29: Upper 95.0%
B30: 45254 | C30: 1738.5605 | D30: =C30/C29-1 -> 0.078368174 | G30: 19794.7 | H30: =G30/G29-1 -> 0.0031877477 | M30: Intercept | N30: 0.0041825924 | O30: 0.004656919 | P30: 0.89814584 | Q30: 0.37128695 | R30: -0.0050577452 | S30: 0.01342293 | T30: -0.0050577452 | U30: 0.01342293
B31: 45261 | C31: 1790.8707 | D31: =C31/C30-1 -> 0.030088244 | G31: 20267.9 | H31: =G31/G30-1 -> 0.023905389 | M31: X Variable 1 | N31: 0.59069484 | O31: 0.27406697 | P31: 2.1552938 | Q31: 0.033563159 | R31: 0.046886522 | S31: 1.1345032 | T31: 0.046886522 | U31: 1.1345032
B32: 45268 | C32: 1759.5935 | D32: =C32/C31-1 -> -0.017464835 | G32: 20969.4 | H32: =G32/G31-1 -> 0.034611381
B33: 45275 | C33: 1793.3947 | D33: =C33/C32-1 -> 0.019209675 | G33: 21456.65 | H33: =G33/G32-1 -> 0.023236239
B34: 45282 | C34: 1848.3279 | D34: =C34/C33-1 -> 0.03063083 | G34: 21349.4 | H34: =G34/G33-1 -> -0.0049984504
B35: 45289 | C35: 1904.8447 | D35: =C35/C34-1 -> 0.030577273 | G35: 21731.4 | H35: =G35/G34-1 -> 0.017892775
B36: 45296 | C36: 1969.4283 | D36: =C36/C35-1 -> 0.03390491 | G36: 21710.8 | H36: =G36/G35-1 -> -0.00094793709
B37: 45303 | C37: 1945.7724 | D37: =C37/C36-1 -> -0.012011559 | G37: 21894.55 | H37: =G37/G36-1 -> 0.0084635297
B38: 45311 | C38: 1919.6915 | D38: =C38/C37-1 -> -0.013403871 | G38: 21622.4 | H38: =G38/G37-1 -> -0.012430034
B39: 45316 | C39: 1879.6546 | D39: =C39/C38-1 -> -0.020855891 | G39: 21352.6 | H39: =G39/G38-1 -> -0.012477801
B40: 45324 | C40: 1978.1384 | D40: =C40/C39-1 -> 0.052394618 | G40: 21853.8 | H40: =G40/G39-1 -> 0.023472551
B41: 45331 | C41: 1986.7496 | D41: =C41/C40-1 -> 0.004353156 | G41: 21782.5 | H41: =G41/G40-1 -> -0.0032625905
B42: 45338 | C42: 1980.7119 | D42: =C42/C41-1 -> -0.0030389837 | G42: 22040.7 | H42: =G42/G41-1 -> 0.011853552
B43: 45345 | C43: 1842.0922 | D43: =C43/C42-1 -> -0.069984759 | G43: 22212.7 | H43: =G43/G42-1 -> 0.0078037449
...

Sheet Beta Calculation - Sun Pharma 
B3: Regression Beta - 2 Years Weekly
B5: Sun Pharma Weekly Returns | G5: Nifty Returns | J5: Beta Drifting | M5: Beta 1 (Slope) | N5: =SLOPE(D9:D109,H9:H109) -> 0.67898559
J6: Levered Raw Beta | K6: =N8 -> 0.67898559 | M6: Beta 2 (Formula) | N6: =_xlfn.COVARIANCE.S(D9:D109,H9:H109)/_xlfn.VAR.S(H9:H109) -> 0.67898559
B7: Date | C7: Closing Price | D7: Return | G7: Closing Price | H7: Return | J7: Raw Beta Weight | K7: 0.75
B8: 45100 | C8: 973.38427 | G8: 18665.5 | J8: Market Beta Weight | K8: 0.25 | M8: Beta 3 (Regression) | N8: =N31 -> 0.67898559
B9: 45107 | C9: 1032.4382 | D9: =C9/C8-1 -> 0.060668718 | G9: 19189.05 | H9: =G9/G8-1 -> 0.028049074 | J9: Market Beta | K9: 1
B10: 45114 | C10: 1016.828 | D10: =C10/C9-1 -> -0.015119817 | G10: 19331.8 | H10: =G10/G9-1 -> 0.0074391385
B11: 45121 | C11: 1053.3992 | D11: =C11/C10-1 -> 0.035966013 | G11: 19564.5 | H11: =G11/G10-1 -> 0.012037162 | J11: Adjusted Beta | K11: =(K6*K7)+(K8*K9) -> 0.75923919
B12: 45128 | C12: 1077.1583 | D12: =C12/C11-1 -> 0.022554639 | G12: 19745 | H12: =G12/G11-1 -> 0.0092258938
B13: 45135 | C13: 1121.7574 | D13: =C13/C12-1 -> 0.041404439 | G13: 19646.05 | H13: =G13/G12-1 -> -0.0050113953
B14: 45142 | C14: 1122.1515 | D14: =C14/C13-1 -> 0.00035132405 | G14: 19517 | H14: =G14/G13-1 -> -0.0065687505 | M14: SUMMARY OUTPUT
B15: 45149 | C15: 1115.6488 | D15: =C15/C14-1 -> -0.005794811 | G15: 19428.3 | H15: =G15/G14-1 -> -0.0045447559
B16: 45156 | C16: 1118.1612 | D16: =C16/C15-1 -> 0.0022519539 | G16: 19310.15 | H16: =G16/G15-1 -> -0.006081335 | M16: Regression Statistics
B17: 45163 | C17: 1089.9831 | D17: =C17/C16-1 -> -0.025200458 | G17: 19265.8 | H17: =G17/G16-1 -> -0.0022967196 | M17: Multiple R | N17: 0.42767051
B18: 45170 | C18: 1092.6432 | D18: =C18/C17-1 -> 0.0024405677 | G18: 19435.3 | H18: =G18/G17-1 -> 0.0087979736 | M18: R Square | N18: 0.18290207
B19: 45177 | C19: 1113.7769 | D19: =C19/C18-1 -> 0.019341749 | G19: 19819.95 | H19: =G19/G18-1 -> 0.019791308 | M19: Adjusted R Square | N19: 0.17464855
B20: 45184 | C20: 1132.8415 | D20: =C20/C19-1 -> 0.017117077 | G20: 20192.35 | H20: =G20/G19-1 -> 0.018789149 | M20: Standard Error | N20: 0.02425115
B21: 45191 | C21: 1115.6488 | D21: =C21/C20-1 -> -0.015176552 | G21: 19674.25 | H21: =G21/G20-1 -> -0.025658232 | M21: Observations | N21: 101
B22: 45198 | C22: 1141.5609 | D22: =C22/C21-1 -> 0.023226034 | G22: 19638.3 | H22: =G22/G21-1 -> -0.0018272615
B23: 45205 | C23: 1110.6733 | D23: =C23/C22-1 -> -0.027057351 | G23: 19653.5 | H23: =G23/G22-1 -> 0.00077399775 | M23: ANOVA
B24: 45212 | C24: 1128.4078 | D24: =C24/C23-1 -> 0.015967356 | G24: 19751.05 | H24: =G24/G23-1 -> 0.0049634925 | N24: df | O24: SS | P24: MS | Q24: F | R24: Significance F
B25: 45219 | C25: 1125.3536 | D25: =C25/C24-1 -> -0.0027067144 | G25: 19542.65 | H25: =G25/G24-1 -> -0.010551338 | M25: Regression | N25: 1 | O25: 0.013032999 | P25: 0.013032999 | Q25: 22.160507 | R25: 8.1660379e-06
B26: 45226 | C26: 1094.9093 | D26: =C26/C25-1 -> -0.027053056 | G26: 19047.25 | H26: =G26/G25-1 -> -0.025349684 | M26: Residual | N26: 99 | O26: 0.058223708 | P26: 0.00058811826
B27: 45233 | C27: 1124.2698 | D27: =C27/C26-1 -> 0.026815441 | G27: 19230.6 | H27: =G27/G26-1 -> 0.0096260615 | M27: Total | N27: 100 | O27: 0.071256707
B28: 45240 | C28: 1161.9556 | D28: =C28/C27-1 -> 0.033520287 | G28: 19425.35 | H28: =G28/G27-1 -> 0.010127089
B29: 45247 | C29: 1176.9807 | D29: =C29/C28-1 -> 0.012930852 | G29: 19731.8 | H29: =G29/G28-1 -> 0.015775778 | N29: Coefficients | O29: Standard Error | P29: t Stat | Q29: P-value | R29: Lower 95% | S29: Upper 95% | T29: Lower 95.0% | U29: Upper 95.0%
B30: 45254 | C30: 1177.8182 | D30: =C30/C29-1 -> 0.00071153524 | G30: 19794.7 | H30: =G30/G29-1 -> 0.0031877477 | M30: Intercept | N30: 0.003734866 | O30: 0.0024508272 | P30: 1.5239206 | Q30: 0.13071671 | R30: -0.001128107 | S30: 0.0085978389 | T30: -0.001128107 | U30: 0.0085978389
B31: 45261 | C31: 1213.0901 | D31: =C31/C30-1 -> 0.029946882 | G31: 20267.9 | H31: =G31/G30-1 -> 0.023905389 | M31: X Variable 1 | N31: 0.67898559 | O31: 0.14423502 | P31: 4.7074948 | Q31: 8.1660379e-06 | R31: 0.39279203 | S31: 0.96517915 | T31: 0.39279203 | U31: 0.96517915
B32: 45268 | C32: 1217.573 | D32: =C32/C31-1 -> 0.0036954315 | G32: 20969.4 | H32: =G32/G31-1 -> 0.034611381
B33: 45275 | C33: 1217.5238 | D33: =C33/C32-1 -> -4.0459621e-05 | G33: 21456.65 | H33: =G33/G32-1 -> 0.023236239
B34: 45282 | C34: 1225.3073 | D34: =C34/C33-1 -> 0.0063928788 | G34: 21349.4 | H34: =G34/G33-1 -> -0.0049984504
B35: 45289 | C35: 1240.8742 | D35: =C35/C34-1 -> 0.012704539 | G35: 21731.4 | H35: =G35/G34-1 -> 0.017892775
B36: 45296 | C36: 1281.0232 | D36: =C36/C35-1 -> 0.032355393 | G36: 21710.8 | H36: =G36/G35-1 -> -0.00094793709
B37: 45303 | C37: 1306.3934 | D37: =C37/C36-1 -> 0.019804645 | G37: 21894.55 | H37: =G37/G36-1 -> 0.0084635297
B38: 45311 | C38: 1306.5905 | D38: =C38/C37-1 -> 0.00015083525 | G38: 21622.4 | H38: =G38/G37-1 -> -0.012430034
B39: 45316 | C39: 1348.1188 | D39: =C39/C38-1 -> 0.031783735 | G39: 21352.6 | H39: =G39/G38-1 -> -0.012477801
B40: 45324 | C40: 1395.7557 | D40: =C40/C39-1 -> 0.035335818 | G40: 21853.8 | H40: =G40/G39-1 -> 0.023472551
B41: 45331 | C41: 1520.7831 | D41: =C41/C40-1 -> 0.089576897 | G41: 21782.5 | H41: =G41/G40-1 -> -0.0032625905
B42: 45338 | C42: 1496.1601 | D42: =C42/C41-1 -> -0.016191035 | G42: 22040.7 | H42: =G42/G41-1 -> 0.011853552
B43: 45345 | C43: 1546.9916 | D43: =C43/C42-1 -> 0.033974635 | G43: 22212.7 | H43: =G43/G42-1 -> 0.0078037449
...

Sheet Beta Calculation - Aurobindo
B3: Regression Beta - 2 Years Weekly
B5: Apollo Hospital Weekly Returns | G5: Nifty Returns | J5: Beta Drifting | M5: Beta 1 (Slope) | N5: =SLOPE(D9:D109,H9:H109) -> 1.0808851
J6: Levered Raw Beta | K6: =N8 -> 1.0808851 | M6: Beta 2 (Formula) | N6: =_xlfn.COVARIANCE.S(D9:D109,H9:H109)/_xlfn.VAR.S(H9:H109) -> 1.0808851
B7: Date | C7: Closing Price | D7: Return | G7: Closing Price | H7: Return | J7: Raw Beta Weight | K7: 0.75
B8: 45100 | C8: 696.0629 | G8: 18665.5 | J8: Market Beta Weight | K8: 0.25 | M8: Beta 3 (Regression) | N8: =N31 -> 1.0808851
B9: 45107 | C9: 724.13839 | D9: =C9/C8-1 -> 0.040334692 | G9: 19189.05 | H9: =G9/G8-1 -> 0.028049074 | J9: Market Beta | K9: 1
B10: 45114 | C10: 742.3078 | D10: =C10/C9-1 -> 0.025091084 | G10: 19331.8 | H10: =G10/G9-1 -> 0.0074391385
B11: 45121 | C11: 735.68717 | D11: =C11/C10-1 -> -0.0089189914 | G11: 19564.5 | H11: =G11/G10-1 -> 0.012037162 | J11: Adjusted Beta | K11: =(K6*K7)+(K8*K9) -> 1.0606638
B12: 45128 | C12: 776.1079 | D12: =C12/C11-1 -> 0.054942824 | G12: 19745 | H12: =G12/G11-1 -> 0.0092258938
B13: 45135 | C13: 833.30423 | D13: =C13/C12-1 -> 0.073696363 | G13: 19646.05 | H13: =G13/G12-1 -> -0.0050113953
B14: 45142 | C14: 837.83413 | D14: =C14/C13-1 -> 0.0054360812 | G14: 19517 | H14: =G14/G13-1 -> -0.0065687505 | M14: SUMMARY OUTPUT
B15: 45149 | C15: 859.33876 | D15: =C15/C14-1 -> 0.025666924 | G15: 19428.3 | H15: =G15/G14-1 -> -0.0045447559
B16: 45156 | C16: 854.01238 | D16: =C16/C15-1 -> -0.0061982274 | G16: 19310.15 | H16: =G16/G15-1 -> -0.006081335 | M16: Regression Statistics
B17: 45163 | C17: 824.84176 | D17: =C17/C16-1 -> -0.034157146 | G17: 19265.8 | H17: =G17/G16-1 -> -0.0022967196 | M17: Multiple R | N17: 0.44914452
B18: 45170 | C18: 821.90478 | D18: =C18/C17-1 -> -0.0035606518 | G18: 19435.3 | H18: =G18/G17-1 -> 0.0087979736 | M18: R Square | N18: 0.2017308
B19: 45177 | C19: 854.70929 | D19: =C19/C18-1 -> 0.039912785 | G19: 19819.95 | H19: =G19/G18-1 -> 0.019791308 | M19: Adjusted R Square | N19: 0.19366747
B20: 45184 | C20: 894.88113 | D20: =C20/C19-1 -> 0.047000582 | G20: 20192.35 | H20: =G20/G19-1 -> 0.018789149 | M20: Standard Error | N20: 0.036333909
B21: 45191 | C21: 862.57441 | D21: =C21/C20-1 -> -0.036101685 | G21: 19674.25 | H21: =G21/G20-1 -> -0.025658232 | M21: Observations | N21: 101
B22: 45198 | C22: 910.31269 | D22: =C22/C21-1 -> 0.055343952 | G22: 19638.3 | H22: =G22/G21-1 -> -0.0018272615
B23: 45205 | C23: 896.8723 | D23: =C23/C22-1 -> -0.014764587 | G23: 19653.5 | H23: =G23/G22-1 -> 0.00077399775 | M23: ANOVA
B24: 45212 | C24: 915.93774 | D24: =C24/C23-1 -> 0.021257701 | G24: 19751.05 | H24: =G24/G23-1 -> 0.0049634925 | N24: df | O24: SS | P24: MS | Q24: F | R24: Significance F
B25: 45219 | C25: 862.37529 | D25: =C25/C24-1 -> -0.058478261 | G25: 19542.65 | H25: =G25/G24-1 -> -0.010551338 | M25: Regression | N25: 1 | O25: 0.033028 | P25: 0.033028 | Q25: 25.018313 | R25: 2.4626633e-06
B26: 45226 | C26: 850.67717 | D26: =C26/C25-1 -> -0.013564997 | G26: 19047.25 | H26: =G26/G25-1 -> -0.025349684 | M26: Residual | N26: 99 | O26: 0.13069514 | P26: 0.001320153
B27: 45233 | C27: 850.52784 | D27: =C27/C26-1 -> -0.00017555152 | G27: 19230.6 | H27: =G27/G26-1 -> 0.0096260615 | M27: Total | N27: 100 | O27: 0.16372314
B28: 45240 | C28: 975.37413 | D28: =C28/C27-1 -> 0.14678684 | G28: 19425.35 | H28: =G28/G27-1 -> 0.010127089
B29: 45247 | C29: 1002.902 | D29: =C29/C28-1 -> 0.028222925 | G29: 19731.8 | H29: =G29/G28-1 -> 0.015775778 | N29: Coefficients | O29: Standard Error | P29: t Stat | Q29: P-value | R29: Lower 95% | S29: Upper 95% | T29: Lower 95.0% | U29: Upper 95.0%
B30: 45254 | C30: 1031.311 | D30: =C30/C29-1 -> 0.028326779 | G30: 19794.7 | H30: =G30/G29-1 -> 0.0031877477 | M30: Intercept | N30: 0.0025545493 | O30: 0.0036719139 | P30: 0.69569967 | Q30: 0.48824686 | R30: -0.0047313245 | S30: 0.0098404232 | T30: -0.0047313245 | U30: 0.0098404232
B31: 45261 | C31: 1032.2597 | D31: =C31/C30-1 -> 0.00091982959 | G31: 20267.9 | H31: =G31/G30-1 -> 0.023905389 | M31: X Variable 1 | N31: 1.0808851 | O31: 0.21609788 | P31: 5.001831 | Q31: 2.4626633e-06 | R31: 0.65209999 | S31: 1.5096701 | T31: 0.65209999 | U31: 1.5096701
B32: 45268 | C32: 1015.9332 | D32: =C32/C31-1 -> -0.015816203 | G32: 20969.4 | H32: =G32/G31-1 -> 0.034611381
B33: 45275 | C33: 1024.9203 | D33: =C33/C32-1 -> 0.0088460782 | G33: 21456.65 | H33: =G33/G32-1 -> 0.023236239
B34: 45282 | C34: 1064.8626 | D34: =C34/C33-1 -> 0.038971161 | G34: 21349.4 | H34: =G34/G33-1 -> -0.0049984504
B35: 45289 | C35: 1082.4372 | D35: =C35/C34-1 -> 0.016504126 | G35: 21731.4 | H35: =G35/G34-1 -> 0.017892775
B36: 45296 | C36: 1122.3296 | D36: =C36/C35-1 -> 0.036854244 | G36: 21710.8 | H36: =G36/G35-1 -> -0.00094793709
B37: 45303 | C37: 1093.2716 | D37: =C37/C36-1 -> -0.025890831 | G37: 21894.55 | H37: =G37/G36-1 -> 0.0084635297
B38: 45311 | C38: 1142.4006 | D38: =C38/C37-1 -> 0.044937663 | G38: 21622.4 | H38: =G38/G37-1 -> -0.012430034
B39: 45316 | C39: 1149.1908 | D39: =C39/C38-1 -> 0.0059437962 | G39: 21352.6 | H39: =G39/G38-1 -> -0.012477801
B40: 45324 | C40: 1065.2121 | D40: =C40/C39-1 -> -0.073076422 | G40: 21853.8 | H40: =G40/G39-1 -> 0.023472551
B41: 45331 | C41: 1001.7038 | D41: =C41/C40-1 -> -0.059620342 | G41: 21782.5 | H41: =G41/G40-1 -> -0.0032625905
B42: 45338 | C42: 1032.709 | D42: =C42/C41-1 -> 0.0309525 | G42: 22040.7 | H42: =G42/G41-1 -> 0.011853552
B43: 45345 | C43: 1043.8 | D43: =C43/C42-1 -> 0.010739704 | G43: 22212.7 | H43: =G43/G42-1 -> 0.0078037449
...

Sheet Beta Calculation - Biocon 
B3: Regression Beta - 2 Years Weekly
B5: Biocon Weekly Returns | G5: Nifty Returns | J5: Beta Drifting | M5: Beta 1 (Slope) | N5: =SLOPE(D9:D109,H9:H109) -> 1.4958582
J6: Levered Raw Beta | K6: =N8 -> 1.4958582 | M6: Beta 2 (Formula) | N6: =_xlfn.COVARIANCE.S(H9:H109,D9:D109)/_xlfn.VAR.S(H9:H109) -> 1.4958582
B7: Date | C7: Closing Price | D7: Return | G7: Closing Price | H7: Return | J7: Raw Beta Weight | K7: 0.75
B8: 45100 | C8: 235.20469 | G8: 18665.5 | J8: Market Beta Weight | K8: 0.25 | M8: Beta 3 (Regression) | N8: =N31 -> 1.4958582
B9: 45107 | C9: 263.60002 | D9: =C9/C8-1 -> 0.12072604 | G9: 19189.05 | H9: =G9/G8-1 -> 0.028049074 | J9: Market Beta | K9: 1
B10: 45114 | C10: 253.59856 | D10: =C10/C9-1 -> -0.037941795 | G10: 19331.8 | H10: =G10/G9-1 -> 0.0074391385
B11: 45121 | C11: 261.83714 | D11: =C11/C10-1 -> 0.03248671 | G11: 19564.5 | H11: =G11/G10-1 -> 0.012037162 | J11: Adjusted Beta | K11: =(K6*K7)+(K8*K9) -> 1.3718937
B12: 45128 | C12: 263.58472 | D12: =C12/C11-1 -> 0.0066742944 | G12: 19745 | H12: =G12/G11-1 -> 0.0092258938
B13: 45135 | C13: 256.39469 | D13: =C13/C12-1 -> -0.027277894 | G13: 19646.05 | H13: =G13/G12-1 -> -0.0050113953
B14: 45142 | C14: 253.19911 | D14: =C14/C13-1 -> -0.012463486 | G14: 19517 | H14: =G14/G13-1 -> -0.0065687505 | M14: SUMMARY OUTPUT
B15: 45149 | C15: 255.84545 | D15: =C15/C14-1 -> 0.010451587 | G15: 19428.3 | H15: =G15/G14-1 -> -0.0045447559
B16: 45156 | C16: 257.84268 | D16: =C16/C15-1 -> 0.0078064012 | G16: 19310.15 | H16: =G16/G15-1 -> -0.006081335 | M16: Regression Statistics
B17: 45163 | C17: 255.04655 | D17: =C17/C16-1 -> -0.010844307 | G17: 19265.8 | H17: =G17/G16-1 -> -0.0022967196 | M17: Multiple R | N17: 0.48956284
B18: 45170 | C18: 260.43908 | D18: =C18/C17-1 -> 0.021143305 | G18: 19435.3 | H18: =G18/G17-1 -> 0.0087979736 | M18: R Square | N18: 0.23967177
B19: 45177 | C19: 266.03133 | D19: =C19/C18-1 -> 0.021472393 | G19: 19819.95 | H19: =G19/G18-1 -> 0.019791308 | M19: Adjusted R Square | N19: 0.23199169
B20: 45184 | C20: 276.36701 | D20: =C20/C19-1 -> 0.038851351 | G20: 20192.35 | H20: =G20/G19-1 -> 0.018789149 | M20: Standard Error | N20: 0.045022187
B21: 45191 | C21: 263.98417 | D21: =C21/C20-1 -> -0.044805781 | G21: 19674.25 | H21: =G21/G20-1 -> -0.025658232 | M21: Observations | N21: 101
B22: 45198 | C22: 271.8233 | D22: =C22/C21-1 -> 0.029695479 | G22: 19638.3 | H22: =G22/G21-1 -> -0.0018272615
B23: 45205 | C23: 264.18389 | D23: =C23/C22-1 -> -0.028104335 | G23: 19653.5 | H23: =G23/G22-1 -> 0.00077399775 | M23: ANOVA
B24: 45212 | C24: 254.19773 | D24: =C24/C23-1 -> -0.037800038 | G24: 19751.05 | H24: =G24/G23-1 -> 0.0049634925 | N24: df | O24: SS | P24: MS | Q24: F | R24: Significance F
B25: 45219 | C25: 230.63039 | D25: =C25/C24-1 -> -0.09271263 | G25: 19542.65 | H25: =G25/G24-1 -> -0.010551338 | M25: Regression | N25: 1 | O25: 0.06325635 | P25: 0.06325635 | Q25: 31.206924 | R25: 2.0419661e-07
B26: 45226 | C26: 222.39181 | D26: =C26/C25-1 -> -0.035722018 | G26: 19047.25 | H26: =G26/G25-1 -> -0.025349684 | M26: Residual | N26: 99 | O26: 0.20067273 | P26: 0.0020269973
B27: 45233 | C27: 224.18932 | D27: =C27/C26-1 -> 0.0080826224 | G27: 19230.6 | H27: =G27/G26-1 -> 0.0096260615 | M27: Total | N27: 100 | O27: 0.26392908
B28: 45240 | C28: 227.0853 | D28: =C28/C27-1 -> 0.012917595 | G28: 19425.35 | H28: =G28/G27-1 -> 0.010127089
B29: 45247 | C29: 232.4279 | D29: =C29/C28-1 -> 0.023526825 | G29: 19731.8 | H29: =G29/G28-1 -> 0.015775778 | N29: Coefficients | O29: Standard Error | P29: t Stat | Q29: P-value | R29: Lower 95% | S29: Upper 95% | T29: Lower 95.0% | U29: Upper 95.0%
B30: 45254 | C30: 235.0243 | D30: =C30/C29-1 -> 0.011170784 | G30: 19794.7 | H30: =G30/G29-1 -> 0.0031877477 | M30: Intercept | N30: 0.00037033953 | O30: 0.0045499534 | P30: 0.081394138 | Q30: 0.93529284 | R30: -0.0086577551 | S30: 0.0093984342 | T30: -0.0086577551 | U30: 0.0093984342
B31: 45261 | C31: 240.31697 | D31: =C31/C30-1 -> 0.022519652 | G31: 20267.9 | H31: =G31/G30-1 -> 0.023905389 | M31: X Variable 1 | N31: 1.4958582 | O31: 0.26777187 | P31: 5.5863158 | Q31: 2.0419661e-07 | R31: 0.96454075 | S31: 2.0271757 | T31: 0.96454075 | U31: 2.0271757
B32: 45268 | C32: 238.66925 | D32: =C32/C31-1 -> -0.0068564305 | G32: 20969.4 | H32: =G32/G31-1 -> 0.034611381
B33: 45275 | C33: 251.35167 | D33: =C33/C32-1 -> 0.053138075 | G33: 21456.65 | H33: =G33/G32-1 -> 0.023236239
B34: 45282 | C34: 245.95915 | D34: =C34/C33-1 -> -0.021454112 | G34: 21349.4 | H34: =G34/G33-1 -> -0.0049984504
B35: 45289 | C35: 249.30451 | D35: =C35/C34-1 -> 0.013601299 | G35: 21731.4 | H35: =G35/G34-1 -> 0.017892775
B36: 45296 | C36: 290.89687 | D36: =C36/C35-1 -> 0.16683357 | G36: 21710.8 | H36: =G36/G35-1 -> -0.00094793709
B37: 45303 | C37: 273.82054 | D37: =C37/C36-1 -> -0.058702369 | G37: 21894.55 | H37: =G37/G36-1 -> 0.0084635297
B38: 45311 | C38: 273.57088 | D38: =C38/C37-1 -> -0.00091174325 | G38: 21622.4 | H38: =G38/G37-1 -> -0.012430034
B39: 45316 | C39: 258.34199 | D39: =C39/C38-1 -> -0.055667093 | G39: 21352.6 | H39: =G39/G38-1 -> -0.012477801
B40: 45324 | C40: 274.31985 | D40: =C40/C39-1 -> 0.0618477 | G40: 21853.8 | H40: =G40/G39-1 -> 0.023472551
B41: 45331 | C41: 273.02164 | D41: =C41/C40-1 -> -0.0047324354 | G41: 21782.5 | H41: =G41/G40-1 -> -0.0032625905
B42: 45338 | C42: 286.45303 | D42: =C42/C41-1 -> 0.049195318 | G42: 22040.7 | H42: =G42/G41-1 -> 0.011853552
B43: 45345 | C43: 272.67213 | D43: =C43/C42-1 -> -0.048108768 | G43: 22212.7 | H43: =G43/G42-1 -> 0.0078037449
...

Sheet Beta Calculation - Max Health
B3: Regression Beta - 2 Years Weekly
B5: Apollo Hospital Weekly Returns | G5: Nifty Returns | J5: Beta Drifting | M5: Beta 1 (Slope) | N5: =SLOPE(D9:D109,H9:H109) -> 1.351525
J6: Levered Raw Beta | K6: =N8 -> 1.351525 | M6: Beta 2 (Formula) | N6: =_xlfn.COVARIANCE.S(D9:D109,H9:H109)/_xlfn.VAR.S(H9:H109) -> 1.351525
B7: Date | C7: Closing Price | D7: Return | G7: Closing Price | H7: Return | J7: Raw Beta Weight | K7: 0.75
B8: 45100 | C8: 578.58596 | G8: 18665.5 | J8: Market Beta Weight | K8: 0.25 | M8: Beta 3 (Regression) | N8: =N31 -> 1.351525
B9: 45107 | C9: 597.42202 | D9: =C9/C8-1 -> 0.032555335 | G9: 19189.05 | H9: =G9/G8-1 -> 0.028049074 | J9: Market Beta | K9: 1
B10: 45114 | C10: 607.83667 | D10: =C10/C9-1 -> 0.017432647 | G10: 19331.8 | H10: =G10/G9-1 -> 0.0074391385
B11: 45121 | C11: 598.71763 | D11: =C11/C10-1 -> -0.015002459 | G11: 19564.5 | H11: =G11/G10-1 -> 0.012037162 | J11: Adjusted Beta | K11: =(K6*K7)+(K8*K9) -> 1.2636437
B12: 45128 | C12: 600.71086 | D12: =C12/C11-1 -> 0.0033291719 | G12: 19745 | H12: =G12/G11-1 -> 0.0092258938
B13: 45135 | C13: 603.9997 | D13: =C13/C12-1 -> 0.0054749067 | G13: 19646.05 | H13: =G13/G12-1 -> -0.0050113953
B14: 45142 | C14: 536.4789 | D14: =C14/C13-1 -> -0.11178946 | G14: 19517 | H14: =G14/G13-1 -> -0.0065687505 | M14: SUMMARY OUTPUT
B15: 45149 | C15: 528.05748 | D15: =C15/C14-1 -> -0.015697566 | G15: 19428.3 | H15: =G15/G14-1 -> -0.0045447559
B16: 45156 | C16: 531.59548 | D16: =C16/C15-1 -> 0.0067000094 | G16: 19310.15 | H16: =G16/G15-1 -> -0.006081335 | M16: Regression Statistics
B17: 45163 | C17: 551.72714 | D17: =C17/C16-1 -> 0.037870266 | G17: 19265.8 | H17: =G17/G16-1 -> -0.0022967196 | M17: Multiple R | N17: 0.4101704
B18: 45170 | C18: 573.00491 | D18: =C18/C17-1 -> 0.038565751 | G18: 19435.3 | H18: =G18/G17-1 -> 0.0087979736 | M18: R Square | N18: 0.16823975
B19: 45177 | C19: 601.95837 | D19: =C19/C18-1 -> 0.050529167 | G19: 19819.95 | H19: =G19/G18-1 -> 0.019791308 | M19: Adjusted R Square | N19: 0.15983813
B20: 45184 | C20: 571.46114 | D20: =C20/C19-1 -> -0.05066335 | G20: 20192.35 | H20: =G20/G19-1 -> 0.018789149 | M20: Standard Error | N20: 0.05078119
B21: 45191 | C21: 542.31158 | D21: =C21/C20-1 -> -0.051008822 | G21: 19674.25 | H21: =G21/G20-1 -> -0.025658232 | M21: Observations | N21: 101
B22: 45198 | C22: 566.41987 | D22: =C22/C21-1 -> 0.044454671 | G22: 19638.3 | H22: =G22/G21-1 -> -0.0018272615
B23: 45205 | C23: 559.73144 | D23: =C23/C22-1 -> -0.011808248 | G23: 19653.5 | H23: =G23/G22-1 -> 0.00077399775 | M23: ANOVA
B24: 45212 | C24: 581.79326 | D24: =C24/C23-1 -> 0.039415017 | G24: 19751.05 | H24: =G24/G23-1 -> 0.0049634925 | N24: df | O24: SS | P24: MS | Q24: F | R24: Significance F
B25: 45219 | C25: 583.0411 | D25: =C25/C24-1 -> 0.0021448181 | G25: 19542.65 | H25: =G25/G24-1 -> -0.010551338 | M25: Regression | N25: 1 | O25: 0.051638237 | P25: 0.051638237 | Q25: 20.024683 | R25: 2.0455201e-05
B26: 45226 | C26: 562.82608 | D26: =C26/C25-1 -> -0.034671689 | G26: 19047.25 | H26: =G26/G25-1 -> -0.025349684 | M26: Residual | N26: 99 | O26: 0.2552942 | P26: 0.0025787293
B27: 45233 | C27: 577.1513 | D27: =C27/C26-1 -> 0.025452288 | G27: 19230.6 | H27: =G27/G26-1 -> 0.0096260615 | M27: Total | N27: 100 | O27: 0.30693243
B28: 45240 | C28: 591.87582 | D28: =C28/C27-1 -> 0.02551241 | G28: 19425.35 | H28: =G28/G27-1 -> 0.010127089
B29: 45247 | C29: 606.70016 | D29: =C29/C28-1 -> 0.025046382 | G29: 19731.8 | H29: =G29/G28-1 -> 0.015775778 | N29: Coefficients | O29: Standard Error | P29: t Stat | Q29: P-value | R29: Lower 95% | S29: Upper 95% | T29: Lower 95.0% | U29: Upper 95.0%
B30: 45254 | C30: 611.69153 | D30: =C30/C29-1 -> 0.0082270671 | G30: 19794.7 | H30: =G30/G29-1 -> 0.0031877477 | M30: Intercept | N30: 0.0040850804 | O30: 0.0051319597 | P30: 0.79600789 | Q30: 0.42793204 | R30: -0.006097841 | S30: 0.014268002 | T30: -0.006097841 | U30: 0.014268002
B31: 45261 | C31: 651.22312 | D31: =C31/C30-1 -> 0.064626683 | G31: 20267.9 | H31: =G31/G30-1 -> 0.023905389 | M31: X Variable 1 | N31: 1.351525 | O31: 0.30202386 | P31: 4.4748948 | Q31: 2.0455201e-05 | R31: 0.75224413 | S31: 1.9508058 | T31: 0.75224413 | U31: 1.9508058
B32: 45268 | C32: 677.02847 | D32: =C32/C31-1 -> 0.039625968 | G32: 20969.4 | H32: =G32/G31-1 -> 0.034611381
B33: 45275 | C33: 687.01119 | D33: =C33/C32-1 -> 0.014744913 | G33: 21456.65 | H33: =G33/G32-1 -> 0.023236239
B34: 45282 | C34: 647.77908 | D34: =C34/C33-1 -> -0.057105493 | G34: 21349.4 | H34: =G34/G33-1 -> -0.0049984504
B35: 45289 | C35: 685.06456 | D35: =C35/C34-1 -> 0.057558946 | G35: 21731.4 | H35: =G35/G34-1 -> 0.017892775
B36: 45296 | C36: 713.51533 | D36: =C36/C35-1 -> 0.041530055 | G36: 21710.8 | H36: =G36/G35-1 -> -0.00094793709
B37: 45303 | C37: 736.17612 | D37: =C37/C36-1 -> 0.031759356 | G37: 21894.55 | H37: =G37/G36-1 -> 0.0084635297
B38: 45311 | C38: 747.60634 | D38: =C38/C37-1 -> 0.015526476 | G38: 21622.4 | H38: =G38/G37-1 -> -0.012430034
B39: 45316 | C39: 731.23467 | D39: =C39/C38-1 -> -0.021898785 | G39: 21352.6 | H39: =G39/G38-1 -> -0.012477801
B40: 45324 | C40: 765.07611 | D40: =C40/C39-1 -> 0.046279863 | G40: 21853.8 | H40: =G40/G39-1 -> 0.023472551
B41: 45331 | C41: 872.88955 | D41: =C41/C40-1 -> 0.14091858 | G41: 21782.5 | H41: =G41/G40-1 -> -0.0032625905
B42: 45338 | C42: 863.95501 | D42: =C42/C41-1 -> -0.01023559 | G42: 22040.7 | H42: =G42/G41-1 -> 0.011853552
B43: 45345 | C43: 850.42842 | D43: =C43/C42-1 -> -0.015656595 | G43: 22212.7 | H43: =G43/G42-1 -> 0.0078037449
...

Sheet Beta Calculation - Fortis
B3: Regression Beta - 2 Years Weekly
B5: Apollo Hospital Weekly Returns | G5: Nifty Returns | J5: Beta Drifting | M5: Beta 1 (Slope) | N5: =SLOPE(D9:D109,H9:H109) -> 0.88775227
J6: Levered Raw Beta | K6: =N8 -> 0.88775227 | M6: Beta 2 (Formula) | N6: =_xlfn.COVARIANCE.S(D9:D109,H9:H109)/_xlfn.VAR.S(H9:H109) -> 0.88775227
B7: Date | C7: Closing Price | D7: Return | G7: Closing Price | H7: Return | J7: Raw Beta Weight | K7: 0.75
B8: 45100 | C8: 303.24998 | G8: 18665.5 | J8: Market Beta Weight | K8: 0.25 | M8: Beta 3 (Regression) | N8: =N31 -> 0.88775227
B9: 45107 | C9: 313.44786 | D9: =C9/C8-1 -> 0.033628609 | G9: 19189.05 | H9: =G9/G8-1 -> 0.028049074 | J9: Market Beta | K9: 1
B10: 45114 | C10: 324.14319 | D10: =C10/C9-1 -> 0.034121568 | G10: 19331.8 | H10: =G10/G9-1 -> 0.0074391385
B11: 45121 | C11: 325.38683 | D11: =C11/C10-1 -> 0.0038367096 | G11: 19564.5 | H11: =G11/G10-1 -> 0.012037162 | J11: Adjusted Beta | K11: =(K7*K6)+(K8*K9) -> 0.91581421
B12: 45128 | C12: 334.51199 | D12: =C12/C11-1 -> 0.028044016 | G12: 19745 | H12: =G12/G11-1 -> 0.0092258938
B13: 45135 | C13: 334.56188 | D13: =C13/C12-1 -> 0.00014916468 | G13: 19646.05 | H13: =G13/G12-1 -> -0.0050113953
B14: 45142 | C14: 337.80521 | D14: =C14/C13-1 -> 0.009694258 | G14: 19517 | H14: =G14/G13-1 -> -0.0065687505 | M14: SUMMARY OUTPUT
B15: 45149 | C15: 317.29739 | D15: =C15/C14-1 -> -0.06070901 | G15: 19428.3 | H15: =G15/G14-1 -> -0.0045447559
B16: 45156 | C16: 315.55099 | D16: =C16/C15-1 -> -0.0055040101 | G16: 19310.15 | H16: =G16/G15-1 -> -0.006081335 | M16: Regression Statistics
B17: 45163 | C17: 332.76558 | D17: =C17/C16-1 -> 0.05455408 | G17: 19265.8 | H17: =G17/G16-1 -> -0.0022967196 | M17: Multiple R | N17: 0.38052513
B18: 45170 | C18: 323.73415 | D18: =C18/C17-1 -> -0.027140501 | G18: 19435.3 | H18: =G18/G17-1 -> 0.0087979736 | M18: R Square | N18: 0.14479938
B19: 45177 | C19: 338.60357 | D19: =C19/C18-1 -> 0.045930949 | G19: 19819.95 | H19: =G19/G18-1 -> 0.019791308 | M19: Adjusted R Square | N19: 0.13616099
B20: 45184 | C20: 329.82163 | D20: =C20/C19-1 -> -0.02593575 | G20: 20192.35 | H20: =G20/G19-1 -> 0.018789149 | M20: Standard Error | N20: 0.036457466
B21: 45191 | C21: 330.61999 | D21: =C21/C20-1 -> 0.0024205749 | G21: 19674.25 | H21: =G21/G20-1 -> -0.025658232 | M21: Observations | N21: 101
B22: 45198 | C22: 339.25224 | D22: =C22/C21-1 -> 0.026109267 | G22: 19638.3 | H22: =G22/G21-1 -> -0.0018272615
B23: 45205 | C23: 327.22697 | D23: =C23/C22-1 -> -0.035446389 | G23: 19653.5 | H23: =G23/G22-1 -> 0.00077399775 | M23: ANOVA
B24: 45212 | C24: 337.80521 | D24: =C24/C23-1 -> 0.032326929 | G24: 19751.05 | H24: =G24/G23-1 -> 0.0049634925 | N24: df | O24: SS | P24: MS | Q24: F | R24: Significance F
B25: 45219 | C25: 331.51814 | D25: =C25/C24-1 -> -0.018611521 | G25: 19542.65 | H25: =G25/G24-1 -> -0.010551338 | M25: Regression | N25: 1 | O25: 0.022279572 | P25: 0.022279572 | Q25: 16.76231 | R25: 8.6597533e-05
B26: 45226 | C26: 324.38282 | D26: =C26/C25-1 -> -0.021523179 | G26: 19047.25 | H26: =G26/G25-1 -> -0.025349684 | M26: Residual | N26: 99 | O26: 0.13158554 | P26: 0.0013291468
B27: 45233 | C27: 333.41424 | D27: =C27/C26-1 -> 0.02784187 | G27: 19230.6 | H27: =G27/G26-1 -> 0.0096260615 | M27: Total | N27: 100 | O27: 0.15386511
B28: 45240 | C28: 358.66232 | D28: =C28/C27-1 -> 0.075725831 | G28: 19425.35 | H28: =G28/G27-1 -> 0.010127089
B29: 45247 | C29: 355.56868 | D29: =C29/C28-1 -> -0.0086254869 | G29: 19731.8 | H29: =G29/G28-1 -> 0.015775778 | N29: Coefficients | O29: Standard Error | P29: t Stat | Q29: P-value | R29: Lower 95% | S29: Upper 95% | T29: Lower 95.0% | U29: Upper 95.0%
B30: 45254 | C30: 365.74774 | D30: =C30/C29-1 -> 0.028627561 | G30: 19794.7 | H30: =G30/G29-1 -> 0.0031877477 | M30: Intercept | N30: 0.006523087 | O30: 0.0036844006 | P30: 1.7704608 | Q30: 0.079728546 | R30: -0.00078756314 | S30: 0.013833737 | T30: -0.00078756314 | U30: 0.013833737
B31: 45261 | C31: 383.01223 | D31: =C31/C30-1 -> 0.047203274 | G31: 20267.9 | H31: =G31/G30-1 -> 0.023905389 | M31: X Variable 1 | N31: 0.88775227 | O31: 0.21683274 | P31: 4.09418 | Q31: 8.6597533e-05 | R31: 0.45750908 | S31: 1.3179955 | T31: 0.45750908 | U31: 1.3179955
B32: 45268 | C32: 381.26583 | D32: =C32/C31-1 -> -0.0045596665 | G32: 20969.4 | H32: =G32/G31-1 -> 0.034611381
B33: 45275 | C33: 393.39089 | D33: =C33/C32-1 -> 0.03180212 | G33: 21456.65 | H33: =G33/G32-1 -> 0.023236239
B34: 45282 | C34: 389.89807 | D34: =C34/C33-1 -> -0.0088787418 | G34: 21349.4 | H34: =G34/G33-1 -> -0.0049984504
B35: 45289 | C35: 418.33957 | D35: =C35/C34-1 -> 0.072945994 | G35: 21731.4 | H35: =G35/G34-1 -> 0.017892775
B36: 45296 | C36: 433.40858 | D36: =C36/C35-1 -> 0.036020992 | G36: 21710.8 | H36: =G36/G35-1 -> -0.00094793709
B37: 45303 | C37: 420.33547 | D37: =C37/C36-1 -> -0.030163481 | G37: 21894.55 | H37: =G37/G36-1 -> 0.0084635297
B38: 45311 | C38: 418.13998 | D38: =C38/C37-1 -> -0.0052231719 | G38: 21622.4 | H38: =G38/G37-1 -> -0.012430034
B39: 45316 | C39: 429.2671 | D39: =C39/C38-1 -> 0.026610979 | G39: 21352.6 | H39: =G39/G38-1 -> -0.012477801
B40: 45324 | C40: 428.86792 | D40: =C40/C39-1 -> -0.00092990817 | G40: 21853.8 | H40: =G40/G39-1 -> 0.023472551
B41: 45331 | C41: 434.05725 | D41: =C41/C40-1 -> 0.012100058 | G41: 21782.5 | H41: =G41/G40-1 -> -0.0032625905
B42: 45338 | C42: 433.25889 | D42: =C42/C41-1 -> -0.0018392919 | G42: 22040.7 | H42: =G42/G41-1 -> 0.011853552
B43: 45345 | C43: 437.69975 | D43: =C43/C42-1 -> 0.010249914 | G43: 22212.7 | H43: =G43/G42-1 -> 0.0078037449
...

Sheet Beta Calculation - Cipla
B3: Regression Beta - 2 Years Weekly
B5: Cipla Weekly Returns | G5: Nifty Returns | J5: Beta Drifting | M5: Beta 1 (Slope) | N5: =SLOPE(D9:D109,H9:H109) -> 0.59166256
J6: Levered Raw Beta | K6: =N8 -> 0.59166256 | M6: Beta 2 (Formula) | N6: =_xlfn.COVARIANCE.S(H9:H109,D9:D109)/_xlfn.VAR.S(H9:H109) -> 0.59166256
B7: Date | C7: Closing Price | D7: Return | G7: Closing Price | H7: Return | J7: Raw Beta Weight | K7: 0.75
B8: 45100 | C8: 973.18856 | G8: 18665.5 | J8: Market Beta Weight | K8: 0.25 | M8: Beta 3 (Regression) | N8: =N31 -> 0.59166256
B9: 45107 | C9: 998.31992 | D9: =C9/C8-1 -> 0.025823732 | G9: 19189.05 | H9: =G9/G8-1 -> 0.028049074 | J9: Market Beta | K9: 1
B10: 45114 | C10: 1003.9265 | D10: =C10/C9-1 -> 0.0056160402 | G10: 19331.8 | H10: =G10/G9-1 -> 0.0074391385
B11: 45121 | C11: 1014.0086 | D11: =C11/C10-1 -> 0.01004262 | G11: 19564.5 | H11: =G11/G10-1 -> 0.012037162 | J11: Adjusted Beta | K11: =(K6*K7)+(K8*K9) -> 0.69374692
B12: 45128 | C12: 1040.1307 | D12: =C12/C11-1 -> 0.025761276 | G12: 19745 | H12: =G12/G11-1 -> 0.0092258938
B13: 45135 | C13: 1167.8974 | D13: =C13/C12-1 -> 0.12283712 | G13: 19646.05 | H13: =G13/G12-1 -> -0.0050113953
B14: 45142 | C14: 1199.5788 | D14: =C14/C13-1 -> 0.027126847 | G14: 19517 | H14: =G14/G13-1 -> -0.0065687505 | M14: SUMMARY OUTPUT
B15: 45149 | C15: 1239.6887 | D15: =C15/C14-1 -> 0.03343666 | G15: 19428.3 | H15: =G15/G14-1 -> -0.0045447559
B16: 45156 | C16: 1226.0047 | D16: =C16/C15-1 -> -0.011038234 | G16: 19310.15 | H16: =G16/G15-1 -> -0.006081335 | M16: Regression Statistics
B17: 45163 | C17: 1199.2317 | D17: =C17/C16-1 -> -0.021837593 | G17: 19265.8 | H17: =G17/G16-1 -> -0.0022967196 | M17: Multiple R | N17: 0.33133282
B18: 45170 | C18: 1234.929 | D18: =C18/C17-1 -> 0.029766827 | G18: 19435.3 | H18: =G18/G17-1 -> 0.0087979736 | M18: R Square | N18: 0.10978144
B19: 45177 | C19: 1234.1358 | D19: =C19/C18-1 -> -0.0006423639 | G19: 19819.95 | H19: =G19/G18-1 -> 0.019791308 | M19: Adjusted R Square | N19: 0.10078933
B20: 45184 | C20: 1225.1123 | D20: =C20/C19-1 -> -0.0073115861 | G20: 20192.35 | H20: =G20/G19-1 -> 0.018789149 | M20: Standard Error | N20: 0.028470952
B21: 45191 | C21: 1175.9293 | D21: =C21/C20-1 -> -0.04014569 | G21: 19674.25 | H21: =G21/G20-1 -> -0.025658232 | M21: Observations | N21: 101
B22: 45198 | C22: 1176.1772 | D22: =C22/C21-1 -> 0.00021081036 | G22: 19638.3 | H22: =G22/G21-1 -> -0.0018272615
B23: 45205 | C23: 1153.2218 | D23: =C23/C22-1 -> -0.019516925 | G23: 19653.5 | H23: =G23/G22-1 -> 0.00077399775 | M23: ANOVA
B24: 45212 | C24: 1157.9319 | D24: =C24/C23-1 -> 0.0040842648 | G24: 19751.05 | H24: =G24/G23-1 -> 0.0049634925 | N24: df | O24: SS | P24: MS | Q24: F | R24: Significance F
B25: 45219 | C25: 1190.1091 | D25: =C25/C24-1 -> 0.027788482 | G25: 19542.65 | H25: =G25/G24-1 -> -0.010551338 | M25: Regression | N25: 1 | O25: 0.0098962676 | P25: 0.0098962676 | Q25: 12.208645 | R25: 0.00071297835
B26: 45226 | C26: 1164.3772 | D26: =C26/C25-1 -> -0.021621396 | G26: 19047.25 | H26: =G26/G25-1 -> -0.025349684 | M26: Residual | N26: 99 | O26: 0.080248913 | P26: 0.00081059508
B27: 45233 | C27: 1196.2074 | D27: =C27/C26-1 -> 0.027336598 | G27: 19230.6 | H27: =G27/G26-1 -> 0.0096260615 | M27: Total | N27: 100 | O27: 0.09014518
B28: 45240 | C28: 1229.6736 | D28: =C28/C27-1 -> 0.027976955 | G28: 19425.35 | H28: =G28/G27-1 -> 0.010127089
B29: 45247 | C29: 1238.8954 | D29: =C29/C28-1 -> 0.0074993952 | G29: 19731.8 | H29: =G29/G28-1 -> 0.015775778 | N29: Coefficients | O29: Standard Error | P29: t Stat | Q29: P-value | R29: Lower 95% | S29: Upper 95% | T29: Lower 95.0% | U29: Upper 95.0%
B30: 45254 | C30: 1188.5721 | D30: =C30/C29-1 -> -0.040619497 | G30: 19794.7 | H30: =G30/G29-1 -> 0.0031877477 | M30: Intercept | N30: 0.002746678 | O30: 0.0028772815 | P30: 0.95460873 | Q30: 0.34210074 | R30: -0.0029624727 | S30: 0.0084558286 | T30: -0.0029624727 | U30: 0.0084558286
B31: 45261 | C31: 1195.5628 | D31: =C31/C30-1 -> 0.0058816168 | G31: 20267.9 | H31: =G31/G30-1 -> 0.023905389 | M31: X Variable 1 | N31: 0.59166256 | O31: 0.16933251 | P31: 3.4940872 | Q31: 0.00071297835 | R31: 0.25567012 | S31: 0.927655 | T31: 0.25567012 | U31: 0.927655
B32: 45268 | C32: 1208.8502 | D32: =C32/C31-1 -> 0.011113876 | G32: 20969.4 | H32: =G32/G31-1 -> 0.034611381
B33: 45275 | C33: 1196.9511 | D33: =C33/C32-1 -> -0.009843327 | G33: 21456.65 | H33: =G33/G32-1 -> 0.023236239
B34: 45282 | C34: 1225.2114 | D34: =C34/C33-1 -> 0.023610306 | G34: 21349.4 | H34: =G34/G33-1 -> -0.0049984504
B35: 45289 | C35: 1235.8215 | D35: =C35/C34-1 -> 0.0086597604 | G35: 21731.4 | H35: =G35/G34-1 -> 0.017892775
B36: 45296 | C36: 1276.0801 | D36: =C36/C35-1 -> 0.032576426 | G36: 21710.8 | H36: =G36/G35-1 -> -0.00094793709
B37: 45303 | C37: 1297.0027 | D37: =C37/C36-1 -> 0.01639599 | G37: 21894.55 | H37: =G37/G36-1 -> 0.0084635297
B38: 45311 | C38: 1305.1834 | D38: =C38/C37-1 -> 0.0063073394 | G38: 21622.4 | H38: =G38/G37-1 -> -0.012430034
B39: 45316 | C39: 1358.1344 | D39: =C39/C38-1 -> 0.040569801 | G39: 21352.6 | H39: =G39/G38-1 -> -0.012477801
B40: 45324 | C40: 1380.941 | D40: =C40/C39-1 -> 0.016792611 | G40: 21853.8 | H40: =G40/G39-1 -> 0.023472551
B41: 45331 | C41: 1427.645 | D41: =C41/C40-1 -> 0.033820414 | G41: 21782.5 | H41: =G41/G40-1 -> -0.0032625905
B42: 45338 | C42: 1428.587 | D42: =C42/C41-1 -> 0.00065983678 | G42: 22040.7 | H42: =G42/G41-1 -> 0.011853552
B43: 45345 | C43: 1454.0709 | D43: =C43/C42-1 -> 0.017838551 | G43: 22212.7 | H43: =G43/G42-1 -> 0.0078037449
...

Sheet Beta Calculation - Metropolis 
B3: Regression Beta - 2 Years Weekly
B5: Apollo Hospital Weekly Returns | G5: Nifty Returns | J5: Beta Drifting | M5: Beta 1 (Slope) | N5: =SLOPE(D9:D109,H9:H109) -> 0.93845271
J6: Levered Raw Beta | K6: =N8 -> 0.93845271 | M6: Beta 2 (Formula) | N6: =_xlfn.COVARIANCE.S(D9:D109,H9:H109)/_xlfn.VAR.S(H9:H109) -> 0.93845271
B7: Date | C7: Closing Price | D7: Return | G7: Closing Price | H7: Return | J7: Raw Beta Weight | K7: 0.75
B8: 45100 | C8: 1382.5498 | G8: 18665.5 | J8: Market Beta Weight | K8: 0.25 | M8: Beta 3 (Regression) | N8: =N31 -> 0.93845271
B9: 45107 | C9: 1489.3832 | D9: =C9/C8-1 -> 0.077272727 | G9: 19189.05 | H9: =G9/G8-1 -> 0.028049074 | J9: Market Beta | K9: 1
B10: 45114 | C10: 1449.6324 | D10: =C10/C9-1 -> -0.026689438 | G10: 19331.8 | H10: =G10/G9-1 -> 0.0074391385
B11: 45121 | C11: 1432.8243 | D11: =C11/C10-1 -> -0.011594702 | G11: 19564.5 | H11: =G11/G10-1 -> 0.012037162 | J11: Adjusted Beta | K11: =(K6*K7)+(K8*K9) -> 0.95383953
B12: 45128 | C12: 1386.9388 | D12: =C12/C11-1 -> -0.032024506 | G12: 19745 | H12: =G12/G11-1 -> 0.0092258938
B13: 45135 | C13: 1387.0884 | D13: =C13/C12-1 -> 0.00010788262 | G13: 19646.05 | H13: =G13/G12-1 -> -0.0050113953
B14: 45142 | C14: 1355.8664 | D14: =C14/C13-1 -> -0.022509079 | G14: 19517 | H14: =G14/G13-1 -> -0.0065687505 | M14: SUMMARY OUTPUT
B15: 45149 | C15: 1375.8664 | D15: =C15/C14-1 -> 0.014750782 | G15: 19428.3 | H15: =G15/G14-1 -> -0.0045447559
B16: 45156 | C16: 1333.9211 | D16: =C16/C15-1 -> -0.030486479 | G16: 19310.15 | H16: =G16/G15-1 -> -0.006081335 | M16: Regression Statistics
B17: 45163 | C17: 1319.0083 | D17: =C17/C16-1 -> -0.01117966 | G17: 19265.8 | H17: =G17/G16-1 -> -0.0022967196 | M17: Multiple R | N17: 0.39928066
B18: 45170 | C18: 1359.5073 | D18: =C18/C17-1 -> 0.030704076 | G18: 19435.3 | H18: =G18/G17-1 -> 0.0087979736 | M18: R Square | N18: 0.15942505
B19: 45177 | C19: 1416.8641 | D19: =C19/C18-1 -> 0.042189449 | G19: 19819.95 | H19: =G19/G18-1 -> 0.019791308 | M19: Adjusted R Square | N19: 0.15093439
B20: 45184 | C20: 1473.1237 | D20: =C20/C19-1 -> 0.039707125 | G20: 20192.35 | H20: =G20/G19-1 -> 0.018789149 | M20: Standard Error | N20: 0.03641383
B21: 45191 | C21: 1414.2207 | D21: =C21/C20-1 -> -0.039985103 | G21: 19674.25 | H21: =G21/G20-1 -> -0.025658232 | M21: Observations | N21: 101
B22: 45198 | C22: 1456.1661 | D22: =C22/C21-1 -> 0.029659672 | G22: 19638.3 | H22: =G22/G21-1 -> -0.0018272615
B23: 45205 | C23: 1467.3881 | D23: =C23/C22-1 -> 0.0077065351 | G23: 19653.5 | H23: =G23/G22-1 -> 0.00077399775 | M23: ANOVA
B24: 45212 | C24: 1554.5206 | D24: =C24/C23-1 -> 0.059379355 | G24: 19751.05 | H24: =G24/G23-1 -> 0.0049634925 | N24: df | O24: SS | P24: MS | Q24: F | R24: Significance F
B25: 45219 | C25: 1503.0989 | D25: =C25/C24-1 -> -0.033078799 | G25: 19542.65 | H25: =G25/G24-1 -> -0.010551338 | M25: Regression | N25: 1 | O25: 0.024897058 | P25: 0.024897058 | Q25: 18.776529 | R25: 3.5315321e-05
B26: 45226 | C26: 1380.9039 | D26: =C26/C25-1 -> -0.081295418 | G26: 19047.25 | H26: =G26/G25-1 -> -0.025349684 | M26: Residual | N26: 99 | O26: 0.13127074 | P26: 0.001325967
B27: 45233 | C27: 1468.7846 | D27: =C27/C26-1 -> 0.063639975 | G27: 19230.6 | H27: =G27/G26-1 -> 0.0096260615 | M27: Total | N27: 100 | O27: 0.1561678
B28: 45240 | C28: 1620.8551 | D28: =C28/C27-1 -> 0.10353492 | G28: 19425.35 | H28: =G28/G27-1 -> 0.010127089
B29: 45247 | C29: 1617.4 | D29: =C29/C28-1 -> -0.0021316325 | G29: 19731.8 | H29: =G29/G28-1 -> 0.015775778 | N29: Coefficients | O29: Standard Error | P29: t Stat | Q29: P-value | R29: Lower 95% | S29: Upper 95% | T29: Lower 95.0% | U29: Upper 95.0%
B30: 45254 | C30: 1658.2 | D30: =C30/C29-1 -> 0.025225671 | G30: 19794.7 | H30: =G30/G29-1 -> 0.0031877477 | M30: Intercept | N30: -8.6728136e-05 | O30: 0.0036799908 | P30: -0.023567487 | Q30: 0.98124504 | R30: -0.0073886282 | S30: 0.0072151719 | T30: -0.0073886282 | U30: 0.0072151719
B31: 45261 | C31: 1688.1 | D31: =C31/C30-1 -> 0.018031601 | G31: 20267.9 | H31: =G31/G30-1 -> 0.023905389 | M31: X Variable 1 | N31: 0.93845271 | O31: 0.21657321 | P31: 4.3331892 | Q31: 3.5315321e-05 | R31: 0.50872447 | S31: 1.3681809 | T31: 0.50872447 | U31: 1.3681809
B32: 45268 | C32: 1653.7 | D32: =C32/C31-1 -> -0.02037794 | G32: 20969.4 | H32: =G32/G31-1 -> 0.034611381
B33: 45275 | C33: 1617.5 | D33: =C33/C32-1 -> -0.021890307 | G33: 21456.65 | H33: =G33/G32-1 -> 0.023236239
B34: 45282 | C34: 1714.55 | D34: =C34/C33-1 -> 0.06 | G34: 21349.4 | H34: =G34/G33-1 -> -0.0049984504
B35: 45289 | C35: 1678.15 | D35: =C35/C34-1 -> -0.02123006 | G35: 21731.4 | H35: =G35/G34-1 -> 0.017892775
