Workbook
Name UPDATE: 'Data Sheet'!$E$1

Sheet Profit & Loss
A1: ='Data Sheet'!B1 -> METROPOLIS HEALTHCARE LTD | H1: =UPDATE | M1: SCREENER.IN
A3: Narration | B3: ='Data Sheet'!B16 -> 42460 | C3: ='Data Sheet'!C16 -> 42825 | D3: ='Data Sheet'!D16 -> 43190 | E3: ='Data Sheet'!E16 -> 43555 | F3: ='Data Sheet'!F16 -> 43921 | G3: ='Data Sheet'!G16 -> 44286 | H3: ='Data Sheet'!H16 -> 44651 | I3: ='Data Sheet'!I16 -> 45016 | ... K3: ='Data Sheet'!K16 -> 45747 | L3: Trailing | M3: Best Case | N3: Worst Case
A4: Sales | B4: ='Data Sheet'!B17 -> 475.47 | C4: ='Data Sheet'!C17 -> 544.72 | D4: ='Data Sheet'!D17 -> 647.16 | E4: ='Data Sheet'!E17 -> 761.18 | F4: ='Data Sheet'!F17 -> 856.41 | G4: ='Data Sheet'!G17 -> 997.99 | H4: ='Data Sheet'!H17 -> 1228.34 | I4: ='Data Sheet'!I17 -> 1148.21 | ... K4: ='Data Sheet'!K17 -> 1331.2 | L4: =SUM(Quarters!H4:K4) -> 1331.21 | M4: =$K4+M23*K4 -> 1467.317 | N4: =$K4+N23*L4 -> 1367.3666
A5: Expenses | B5: =SUM('Data Sheet'!B18,'Data Sheet'!B20:B24, -1*'Data Sheet'!B19) -> 359.18 | C5: =SUM('Data Sheet'!C18,'Data Sheet'!C20:C24, -1*'Data Sheet'!C19) -> 404.52 | D5: =SUM('Data Sheet'!D18,'Data Sheet'!D20:D24, -1*'Data Sheet'!D19) -> 466.59 | E5: =SUM('Data Sheet'!E18,'Data Sheet'!E20:E24, -1*'Data Sheet'!E19) -> 558.61 | F5: =SUM('Data Sheet'!F18,'Data Sheet'!F20:F24, -1*'Data Sheet'!F19) -> 619.2 | G5: =SUM('Data Sheet'!G18,'Data Sheet'!G20:G24, -1*'Data Sheet'!G19) -> 708.2 | H5: =SUM('Data Sheet'!H18,'Data Sheet'!H20:H24, -1*'Data Sheet'!H19) -> 880.26 | I5: =SUM('Data Sheet'!I18,'Data Sheet'!I20:I24, -1*'Data Sheet'!I19) -> 854.86 | ... K5: =SUM('Data Sheet'!K18,'Data Sheet'!K20:K24, -1*'Data Sheet'!K19) -> 1028.21 | L5: =SUM(Quarters!H5:K5) -> 1028.23 | M5: =M4-M6 -> 1115.4152 | N5: =N4-N6 -> 1056.1574
A6: Operating Profit | B6: =B4-B5 -> 116.29 | C6: =C4-C5 -> 140.2 | D6: =D4-D5 -> 180.57 | E6: =E4-E5 -> 202.57 | F6: =F4-F5 -> 237.21 | G6: =G4-G5 -> 289.79 | H6: =H4-H5 -> 348.08 | I6: =I4-I5 -> 293.35 | ... K6: =K4-K5 -> 302.99 | L6: =SUM(Quarters!H6:K6) -> 302.98 | M6: =M4*M24 -> 351.90187 | N6: =N4*N24 -> 311.20915
A7: Other Income | B7: ='Data Sheet'!B25 -> 29.47 | C7: ='Data Sheet'!C25 -> 38.89 | D7: ='Data Sheet'!D25 -> 5.67 | E7: ='Data Sheet'!E25 -> 8.17 | F7: ='Data Sheet'!F25 -> -16.56 | G7: ='Data Sheet'!G25 -> 12.04 | H7: ='Data Sheet'!H25 -> 33.51 | I7: ='Data Sheet'!I25 -> 15.22 | ... K7: ='Data Sheet'!K25 -> 15.11 | L7: =SUM(Quarters!H7:K7) -> 15.12 | M7: 0 | N7: 0
A8: Depreciation | B8: ='Data Sheet'!B26 -> 16.64 | C8: ='Data Sheet'!C26 -> 17.23 | D8: ='Data Sheet'!D26 -> 19.02 | E8: ='Data Sheet'!E26 -> 20.07 | F8: ='Data Sheet'!F26 -> 39.27 | G8: ='Data Sheet'!G26 -> 45.94 | H8: ='Data Sheet'!H26 -> 63.22 | I8: ='Data Sheet'!I26 -> 89.22 | ... K8: ='Data Sheet'!K26 -> 108.68 | L8: =SUM(Quarters!H8:K8) -> 108.68 | M8: =+$L8 -> 108.68 | N8: =+$L8 -> 108.68
A9: Interest | B9: ='Data Sheet'!B27 -> 1.6 | C9: ='Data Sheet'!C27 -> 1.94 | D9: ='Data Sheet'!D27 -> 3.54 | E9: ='Data Sheet'!E27 -> 4.12 | F9: ='Data Sheet'!F27 -> 12.65 | G9: ='Data Sheet'!G27 -> 11.56 | H9: ='Data Sheet'!H27 -> 25.02 | I9: ='Data Sheet'!I27 -> 31.85 | ... K9: ='Data Sheet'!K27 -> 18.57 | L9: =SUM(Quarters!H9:K9) -> 18.57 | M9: =+$L9 -> 18.57 | N9: =+$L9 -> 18.57
A10: Profit before tax | B10: ='Data Sheet'!B28 -> 127.52 | C10: ='Data Sheet'!C28 -> 159.92 | D10: ='Data Sheet'!D28 -> 163.68 | E10: ='Data Sheet'!E28 -> 186.55 | F10: ='Data Sheet'!F28 -> 168.73 | G10: ='Data Sheet'!G28 -> 244.33 | H10: ='Data Sheet'!H28 -> 293.35 | I10: ='Data Sheet'!I28 -> 187.5 | ... K10: ='Data Sheet'!K28 -> 190.85 | L10: =SUM(Quarters!H10:K10) -> 190.85 | M10: =M6+M7-SUM(M8:M9) -> 224.65187 | N10: =N6+N7-SUM(N8:N9) -> 183.95915
A11: Tax | B11: ='Data Sheet'!B29 -> 45.57 | C11: ='Data Sheet'!C29 -> 52.66 | D11: ='Data Sheet'!D29 -> 51.84 | E11: ='Data Sheet'!E29 -> 62.94 | F11: ='Data Sheet'!F29 -> 41.18 | G11: ='Data Sheet'!G29 -> 60.97 | H11: ='Data Sheet'!H29 -> 78.66 | I11: ='Data Sheet'!I29 -> 44.11 | ... K11: ='Data Sheet'!K29 -> 45.34 | L11: =SUM(Quarters!H11:K11) -> 45.34 | M11: =IF($L10>0,$L11/$L10,0) -> 0.23756877 | N11: =IF($L10>0,$L11/$L10,0) -> 0.23756877
A12: Net profit | B12: ='Data Sheet'!B30 -> 76.8 | C12: ='Data Sheet'!C30 -> 101.66 | D12: ='Data Sheet'!D30 -> 104.24 | E12: ='Data Sheet'!E30 -> 120.15 | F12: ='Data Sheet'!F30 -> 127.33 | G12: ='Data Sheet'!G30 -> 183.1 | H12: ='Data Sheet'!H30 -> 214.18 | I12: ='Data Sheet'!I30 -> 142.88 | ... K12: ='Data Sheet'!K30 -> 144.97 | L12: =SUM(Quarters!H12:K12) -> 144.97 | M12: =M10-M11*M10 -> 171.2816 | N12: =N10-N11*N10 -> 140.2562
A13: EPS | B13: =IF('Data Sheet'!B93>0,B12/'Data Sheet'!B93,0) -> 80.842105 | C13: =IF('Data Sheet'!C93>0,C12/'Data Sheet'!C93,0) -> 107.01053 | D13: =IF('Data Sheet'!D93>0,D12/'Data Sheet'!D93,0) -> 109.72632 | E13: =IF('Data Sheet'!E93>0,E12/'Data Sheet'!E93,0) -> 23.934263 | F13: =IF('Data Sheet'!F93>0,F12/'Data Sheet'!F93,0) -> 25.164032 | G13: =IF('Data Sheet'!G93>0,G12/'Data Sheet'!G93,0) -> 35.831703 | H13: =IF('Data Sheet'!H93>0,H12/'Data Sheet'!H93,0) -> 41.832031 | I13: =IF('Data Sheet'!I93>0,I12/'Data Sheet'!I93,0) -> 27.90625 | ... K13: =IF('Data Sheet'!K93>0,K12/'Data Sheet'!K93,0) -> 27.986486 | L13: =IF('Data Sheet'!$B6>0,'Profit & Loss'!L12/'Data Sheet'!$B6,0) -> 27.922977 | M13: =IF('Data Sheet'!$B6>0,'Profit & Loss'!M12/'Data Sheet'!$B6,0) -> 32.99091 | N13: =IF('Data Sheet'!$B6>0,'Profit & Loss'!N12/'Data Sheet'!$B6,0) -> 27.015042
A14: Price to earning | B14: =IF(B15>0,B15/B13,"") | C14: =IF(C15>0,C15/C13,"") | D14: =IF(D15>0,D15/D13,"") | E14: =IF(E15>0,E15/E13,"") | F14: =IF(F15>0,F15/F13,"") -> 51.043093 | G14: =IF(G15>0,G15/G13,"") -> 62.547963 | H14: =IF(H15>0,H15/H13,"") -> 48.664861 | I14: =IF(I15>0,I15/I13,"") -> 44.731915 | ... K14: =IF(K15>0,K15/K13,"") -> 55.903766 | L14: =IF(L13>0,L15/L13,0) -> 60.964131 | M14: =M25 -> 60.964131 | N14: =N25 -> 56.128117
A15: Price | B15: ='Data Sheet'!B90 -> 0 | C15: ='Data Sheet'!C90 -> 0 | D15: ='Data Sheet'!D90 -> 0 | E15: ='Data Sheet'!E90 -> 0 | F15: ='Data Sheet'!F90 -> 1284.45 | G15: ='Data Sheet'!G90 -> 2241.2 | H15: ='Data Sheet'!H90 -> 2035.75 | I15: ='Data Sheet'!I90 -> 1248.3 | ... K15: ='Data Sheet'!K90 -> 1564.55 | L15: ='Data Sheet'!B8 -> 1702.3 | M15: =M13*M14 -> 2011.2621 | N15: =N13*N14 -> 1516.3034
A17: RATIOS:
A18: Dividend Payout | B18: =IF('Data Sheet'!B30>0, 'Data Sheet'!B31/'Data Sheet'!B30, 0) -> 0.99882812 | C18: =IF('Data Sheet'!C30>0, 'Data Sheet'!C31/'Data Sheet'!C30, 0) -> 0.4916388 | D18: =IF('Data Sheet'!D30>0, 'Data Sheet'!D31/'Data Sheet'!D30, 0) -> 0 | E18: =IF('Data Sheet'!E30>0, 'Data Sheet'!E31/'Data Sheet'!E30, 0) -> 0.55405743 | F18: =IF('Data Sheet'!F30>0, 'Data Sheet'!F31/'Data Sheet'!F30, 0) -> 0.31822823 | G18: =IF('Data Sheet'!G30>0, 'Data Sheet'!G31/'Data Sheet'!G30, 0) -> 0.22326597 | H18: =IF('Data Sheet'!H30>0, 'Data Sheet'!H31/'Data Sheet'!H30, 0) -> 0.19105425 | I18: =IF('Data Sheet'!I30>0, 'Data Sheet'!I31/'Data Sheet'!I30, 0) -> 0.28667413 | ... K18: =IF('Data Sheet'!K30>0, 'Data Sheet'!K31/'Data Sheet'!K30, 0) -> 0
A19: OPM | B19: =IF(B6>0,B6/B4,0) -> 0.24457905 | C19: =IF(C6>0,C6/C4,0) -> 0.25737994 | D19: =IF(D6>0,D6/D4,0) -> 0.2790191 | E19: =IF(E6>0,E6/E4,0) -> 0.26612628 | F19: =IF(F6>0,F6/F4,0) -> 0.27698182 | G19: =IF(G6>0,G6/G4,0) -> 0.29037365 | H19: =IF(H6>0,H6/H4,0) -> 0.28337431 | I19: =IF(I6>0,I6/I4,0) -> 0.25548462 | ... L19: =IF(L6>0,L6/L4,0) -> 0.22759745
G22: TRENDS: | H22: 10 YEARS | I22: 7 YEARS | J22: 5 YEARS | K22: 3 YEARS | L22: RECENT | M22: BEST | N22: WORST
G23: Sales Growth | H23: =IF(B4=0,"",POWER($K4/B4,1/9)-1) -> 0.12119208 | I23: =IF(D4=0,"",POWER($K4/D4,1/7)-1) -> 0.10852981 | J23: =IF(F4=0,"",POWER($K4/F4,1/5)-1) -> 0.09222551 | K23: =IF(H4=0,"",POWER($K4/H4, 1/3)-1) -> 0.027168214 | L23: =IF(ISERROR(MAX(IF(J4=0,"",(K4-J4)/J4),IF(K4=0,"",(L4-K4)/K4))),"",MAX(IF(J4=0,"",(K4-J4)/J4),IF(K4=0,"",(L4-K4)/K4))) -> 0.10225137 | M23: =MAX(K23:L23) -> 0.10225137 | N23: =MIN(H23:L23) -> 0.027168214
G24: OPM | H24: =IF(SUM(B4:$K$4)=0,"",SUMPRODUCT(B19:$K$19,B4:$K$4)/SUM(B4:$K$4)) -> 0.26080434 | I24: =IF(SUM(E4:$K$4)=0,"",SUMPRODUCT(E19:$K$19,E4:$K$4)/SUM(E4:$K$4)) -> 0.26051116 | J24: =IF(SUM(G4:$K$4)=0,"",SUMPRODUCT(G19:$K$19,G4:$K$4)/SUM(G4:$K$4)) -> 0.25740304 | K24: =IF(SUM(I4:$K$4)=0, "", SUMPRODUCT(I19:$K$19,I4:$K$4)/SUM(I4:$K$4)) -> 0.23982675 | L24: =L19 -> 0.22759745 | M24: =MAX(K24:L24) -> 0.23982675 | N24: =MIN(H24:L24) -> 0.22759745
G25: Price to Earning | H25: =IF(ISERROR(AVERAGEIF(B14:$L14,">0")),"",AVERAGEIF(B14:$L14,">0")) -> 56.128117 | I25: =IF(ISERROR(AVERAGEIF(E14:$L14,">0")),"",AVERAGEIF(E14:$L14,">0")) -> 56.128117 | J25: =IF(ISERROR(AVERAGEIF(G14:$L14,">0")),"",AVERAGEIF(G14:$L14,">0")) -> 56.975621 | K25: =IF(ISERROR(AVERAGEIF(I14:$L14,">0")),"",AVERAGEIF(I14:$L14,">0")) -> 57.660225 | L25: =L14 -> 60.964131 | M25: =MAX(K25:L25) -> 60.964131 | N25: =MIN(H25:L25) -> 56.128117

Sheet Quarters
A1: ='Profit & Loss'!A1 -> METROPOLIS HEALTHCARE LTD | E1: =UPDATE | J1: SCREENER.IN
A3: Narration | B3: ='Data Sheet'!B41 -> 44926 | C3: ='Data Sheet'!C41 -> 45016 | D3: ='Data Sheet'!D41 -> 45107 | E3: ='Data Sheet'!E41 -> 45199 | F3: ='Data Sheet'!F41 -> 45291 | G3: ='Data Sheet'!G41 -> 45382 | H3: ='Data Sheet'!H41 -> 45473 | I3: ='Data Sheet'!I41 -> 45565 | ... K3: ='Data Sheet'!K41 -> 45747
A4: Sales | B4: ='Data Sheet'!B42 -> 285.46 | C4: ='Data Sheet'!C42 -> 282.55 | D4: ='Data Sheet'!D42 -> 277.09 | E4: ='Data Sheet'!E42 -> 308.5 | F4: ='Data Sheet'!F42 -> 291.12 | G4: ='Data Sheet'!G42 -> 331 | H4: ='Data Sheet'!H42 -> 313.36 | I4: ='Data Sheet'!I42 -> 349.79 | ... K4: ='Data Sheet'!K42 -> 345.29
A5: Expenses | B5: ='Data Sheet'!B43 -> 214.97 | C5: ='Data Sheet'!C43 -> 212.27 | D5: ='Data Sheet'!D43 -> 214.15 | E5: ='Data Sheet'!E43 -> 233.69 | F5: ='Data Sheet'!F43 -> 226.27 | G5: ='Data Sheet'!G43 -> 251.02 | H5: ='Data Sheet'!H43 -> 234.55 | I5: ='Data Sheet'!I43 -> 259.92 | ... K5: ='Data Sheet'!K43 -> 282.99
A6: Operating Profit | B6: ='Data Sheet'!B50 -> 70.49 | C6: ='Data Sheet'!C50 -> 70.28 | D6: ='Data Sheet'!D50 -> 62.94 | E6: ='Data Sheet'!E50 -> 74.81 | F6: ='Data Sheet'!F50 -> 64.85 | G6: ='Data Sheet'!G50 -> 79.98 | H6: ='Data Sheet'!H50 -> 78.81 | I6: ='Data Sheet'!I50 -> 89.87 | ... K6: ='Data Sheet'!K50 -> 62.3
A7: Other Income | B7: ='Data Sheet'!B44 -> 6.62 | C7: ='Data Sheet'!C44 -> 1.23 | D7: ='Data Sheet'!D44 -> 3.05 | E7: ='Data Sheet'!E44 -> 1.22 | F7: ='Data Sheet'!F44 -> 2.31 | G7: ='Data Sheet'!G44 -> 2.54 | H7: ='Data Sheet'!H44 -> 2.46 | I7: ='Data Sheet'!I44 -> 3.13 | ... K7: ='Data Sheet'!K44 -> 6.97
A8: Depreciation | B8: ='Data Sheet'!B45 -> 23.03 | C8: ='Data Sheet'!C45 -> 23.43 | D8: ='Data Sheet'!D45 -> 20.82 | E8: ='Data Sheet'!E45 -> 22.24 | F8: ='Data Sheet'!F45 -> 24.99 | G8: ='Data Sheet'!G45 -> 26.42 | H8: ='Data Sheet'!H45 -> 25.54 | I8: ='Data Sheet'!I45 -> 26.82 | ... K8: ='Data Sheet'!K45 -> 28.62
A9: Interest | B9: ='Data Sheet'!B46 -> 6.11 | C9: ='Data Sheet'!C46 -> 6.17 | D9: ='Data Sheet'!D46 -> 5.98 | E9: ='Data Sheet'!E46 -> 5.68 | F9: ='Data Sheet'!F46 -> 5.31 | G9: ='Data Sheet'!G46 -> 5.57 | H9: ='Data Sheet'!H46 -> 4.65 | I9: ='Data Sheet'!I46 -> 4.79 | ... K9: ='Data Sheet'!K46 -> 4.6
A10: Profit before tax | B10: ='Data Sheet'!B47 -> 47.97 | C10: ='Data Sheet'!C47 -> 41.91 | D10: ='Data Sheet'!D47 -> 39.19 | E10: ='Data Sheet'!E47 -> 48.11 | F10: ='Data Sheet'!F47 -> 36.86 | G10: ='Data Sheet'!G47 -> 50.53 | H10: ='Data Sheet'!H47 -> 51.08 | I10: ='Data Sheet'!I47 -> 61.39 | ... K10: ='Data Sheet'!K47 -> 36.05
A11: Tax | B11: ='Data Sheet'!B48 -> 12.11 | C11: ='Data Sheet'!C48 -> 8.41 | D11: ='Data Sheet'!D48 -> 10.21 | E11: ='Data Sheet'!E48 -> 12.45 | F11: ='Data Sheet'!F48 -> 9.57 | G11: ='Data Sheet'!G48 -> 14.01 | H11: ='Data Sheet'!H48 -> 12.96 | I11: ='Data Sheet'!I48 -> 14.7 | ... K11: ='Data Sheet'!K48 -> 6.82
A12: Net profit | B12: ='Data Sheet'!B49 -> 35.8 | C12: ='Data Sheet'!C49 -> 33.36 | D12: ='Data Sheet'!D49 -> 28.8 | E12: ='Data Sheet'!E49 -> 35.45 | F12: ='Data Sheet'!F49 -> 27.16 | G12: ='Data Sheet'!G49 -> 36.41 | H12: ='Data Sheet'!H49 -> 37.95 | I12: ='Data Sheet'!I49 -> 46.52 | ... K12: ='Data Sheet'!K49 -> 29.14
A14: OPM | B14: =IF(B4>0,B6/B4,"") -> 0.24693477 | C14: =IF(C4>0,C6/C4,"") -> 0.24873474 | D14: =IF(D4>0,D6/D4,"") -> 0.22714641 | E14: =IF(E4>0,E6/E4,"") -> 0.24249595 | F14: =IF(F4>0,F6/F4,"") -> 0.22276037 | G14: =IF(G4>0,G6/G4,"") -> 0.24163142 | H14: =IF(H4>0,H6/H4,"") -> 0.25149987 | I14: =IF(I4>0,I6/I4,"") -> 0.25692558 | ... K14: =IF(K4>0,K6/K4,"") -> 0.18042805

Sheet Balance Sheet
A1: ='Profit & Loss'!A1 -> METROPOLIS HEALTHCARE LTD | E1: =UPDATE | J1: SCREENER.IN
A3: Narration | B3: ='Data Sheet'!B56 -> 42460 | C3: ='Data Sheet'!C56 -> 42825 | D3: ='Data Sheet'!D56 -> 43190 | E3: ='Data Sheet'!E56 -> 43555 | F3: ='Data Sheet'!F56 -> 43921 | G3: ='Data Sheet'!G56 -> 44286 | H3: ='Data Sheet'!H56 -> 44651 | I3: ='Data Sheet'!I56 -> 45016 | ... K3: ='Data Sheet'!K56 -> 45747
A4: Equity Share Capital | B4: ='Data Sheet'!B57 -> 9.54 | C4: ='Data Sheet'!C57 -> 9.54 | D4: ='Data Sheet'!D57 -> 9.54 | E4: ='Data Sheet'!E57 -> 10.04 | F4: ='Data Sheet'!F57 -> 10.13 | G4: ='Data Sheet'!G57 -> 10.22 | H4: ='Data Sheet'!H57 -> 10.23 | I4: ='Data Sheet'!I57 -> 10.24 | ... K4: ='Data Sheet'!K57 -> 10.36
A5: Reserves | B5: ='Data Sheet'!B58 -> 269.18 | C5: ='Data Sheet'!C58 -> 313.63 | D5: ='Data Sheet'!D58 -> 405.22 | E5: ='Data Sheet'!E58 -> 408.5 | F5: ='Data Sheet'!F58 -> 513.37 | G5: ='Data Sheet'!G58 -> 696.38 | H5: ='Data Sheet'!H58 -> 875.96 | I5: ='Data Sheet'!I58 -> 977.99 | ... K5: ='Data Sheet'!K58 -> 1320.61
A6: Borrowings | B6: ='Data Sheet'!B59 -> 4.7 | C6: ='Data Sheet'!C59 -> 0.93 | D6: ='Data Sheet'!D59 -> 0.73 | E6: ='Data Sheet'!E59 -> 17.78 | F6: ='Data Sheet'!F59 -> 66.7 | G6: ='Data Sheet'!G59 -> 112.27 | H6: ='Data Sheet'!H59 -> 378.56 | I6: ='Data Sheet'!I59 -> 266.38 | ... K6: ='Data Sheet'!K59 -> 204.13
A7: Other Liabilities | B7: ='Data Sheet'!B60 -> 107.24 | C7: ='Data Sheet'!C60 -> 187.63 | D7: ='Data Sheet'!D60 -> 110.4 | E7: ='Data Sheet'!E60 -> 113.42 | F7: ='Data Sheet'!F60 -> 160.3 | G7: ='Data Sheet'!G60 -> 181.39 | H7: ='Data Sheet'!H60 -> 255.76 | I7: ='Data Sheet'!I60 -> 240.11 | ... K7: ='Data Sheet'!K60 -> 332.24
A8: Total | B8: ='Data Sheet'!B61 -> 390.66 | C8: ='Data Sheet'!C61 -> 511.73 | D8: ='Data Sheet'!D61 -> 525.89 | E8: ='Data Sheet'!E61 -> 549.74 | F8: ='Data Sheet'!F61 -> 750.5 | G8: ='Data Sheet'!G61 -> 1000.26 | H8: ='Data Sheet'!H61 -> 1520.51 | I8: ='Data Sheet'!I61 -> 1494.72 | ... K8: ='Data Sheet'!K61 -> 1867.34
A10: Net Block | B10: ='Data Sheet'!B62 -> 141.66 | C10: ='Data Sheet'!C62 -> 202.36 | D10: ='Data Sheet'!D62 -> 207.44 | E10: ='Data Sheet'!E62 -> 212.81 | F10: ='Data Sheet'!F62 -> 296.37 | G10: ='Data Sheet'!G62 -> 343.11 | H10: ='Data Sheet'!H62 -> 1058.93 | I10: ='Data Sheet'!I62 -> 1120.67 | ... K10: ='Data Sheet'!K62 -> 1446.96
A11: Capital Work in Progress | B11: ='Data Sheet'!B63 -> 0.56 | C11: ='Data Sheet'!C63 -> 0.95 | D11: ='Data Sheet'!D63 -> 0 | E11: ='Data Sheet'!E63 -> 5.77 | F11: ='Data Sheet'!F63 -> 2.99 | G11: ='Data Sheet'!G63 -> 0 | H11: ='Data Sheet'!H63 -> 5.78 | I11: ='Data Sheet'!I63 -> 19.51 | ... K11: ='Data Sheet'!K63 -> 0
A12: Investments | B12: ='Data Sheet'!B64 -> 101.39 | C12: ='Data Sheet'!C64 -> 141.84 | D12: ='Data Sheet'!D64 -> 102.18 | E12: ='Data Sheet'!E64 -> 33.29 | F12: ='Data Sheet'!F64 -> 14.32 | G12: ='Data Sheet'!G64 -> 10.08 | H12: ='Data Sheet'!H64 -> 15.51 | I12: ='Data Sheet'!I64 -> 14.81 | ... K12: ='Data Sheet'!K64 -> 70.99
A13: Other Assets | B13: ='Data Sheet'!B65 -> 147.05 | C13: ='Data Sheet'!C65 -> 166.58 | D13: ='Data Sheet'!D65 -> 216.27 | E13: ='Data Sheet'!E65 -> 297.87 | F13: ='Data Sheet'!F65 -> 436.82 | G13: ='Data Sheet'!G65 -> 647.07 | H13: ='Data Sheet'!H65 -> 440.29 | I13: ='Data Sheet'!I65 -> 339.73 | ... K13: ='Data Sheet'!K65 -> 349.39
A14: Total | B14: ='Data Sheet'!B66 -> 390.66 | C14: ='Data Sheet'!C66 -> 511.73 | D14: ='Data Sheet'!D66 -> 525.89 | E14: ='Data Sheet'!E66 -> 549.74 | F14: ='Data Sheet'!F66 -> 750.5 | G14: ='Data Sheet'!G66 -> 1000.26 | H14: ='Data Sheet'!H66 -> 1520.51 | I14: ='Data Sheet'!I66 -> 1494.72 | ... K14: ='Data Sheet'!K66 -> 1867.34
A16: Working Capital | B16: =B13-B7 -> 39.81 | C16: =C13-C7 -> -21.05 | D16: =D13-D7 -> 105.87 | E16: =E13-E7 -> 184.45 | F16: =F13-F7 -> 276.52 | G16: =G13-G7 -> 465.68 | H16: =H13-H7 -> 184.53 | I16: =I13-I7 -> 99.62 | ... K16: =K13-K7 -> 17.15
A17: Debtors | B17: ='Data Sheet'!B67 -> 70.2 | C17: ='Data Sheet'!C67 -> 80.29 | D17: ='Data Sheet'!D67 -> 100.68 | E17: ='Data Sheet'!E67 -> 136.85 | F17: ='Data Sheet'!F67 -> 128.25 | G17: ='Data Sheet'!G67 -> 122.98 | H17: ='Data Sheet'!H67 -> 135.49 | I17: ='Data Sheet'!I67 -> 121.89 | ... K17: ='Data Sheet'!K67 -> 147.95
A18: Inventory | B18: ='Data Sheet'!B68 -> 15.57 | C18: ='Data Sheet'!C68 -> 14.13 | D18: ='Data Sheet'!D68 -> 21.19 | E18: ='Data Sheet'!E68 -> 26.1 | F18: ='Data Sheet'!F68 -> 24.4 | G18: ='Data Sheet'!G68 -> 40.55 | H18: ='Data Sheet'!H68 -> 51.11 | I18: ='Data Sheet'!I68 -> 44.59 | ... K18: ='Data Sheet'!K68 -> 47.84
A20: Debtor Days | B20: =IF('Profit & Loss'!B4>0,'Balance Sheet'!B17/('Profit & Loss'!B4/365),0) -> 53.889835 | C20: =IF('Profit & Loss'!C4>0,'Balance Sheet'!C17/('Profit & Loss'!C4/365),0) -> 53.799842 | D20: =IF('Profit & Loss'!D4>0,'Balance Sheet'!D17/('Profit & Loss'!D4/365),0) -> 56.783794 | E20: =IF('Profit & Loss'!E4>0,'Balance Sheet'!E17/('Profit & Loss'!E4/365),0) -> 65.622126 | F20: =IF('Profit & Loss'!F4>0,'Balance Sheet'!F17/('Profit & Loss'!F4/365),0) -> 54.659859 | G20: =IF('Profit & Loss'!G4>0,'Balance Sheet'!G17/('Profit & Loss'!G4/365),0) -> 44.978106 | H20: =IF('Profit & Loss'!H4>0,'Balance Sheet'!H17/('Profit & Loss'!H4/365),0) -> 40.260718 | I20: =IF('Profit & Loss'!I4>0,'Balance Sheet'!I17/('Profit & Loss'!I4/365),0) -> 38.747137 | ... K20: =IF('Profit & Loss'!K4>0,'Balance Sheet'!K17/('Profit & Loss'!K4/365),0) -> 40.566218
A21: Inventory Turnover | B21: =IF('Balance Sheet'!B18>0,'Profit & Loss'!B4/'Balance Sheet'!B18,0) -> 30.537572 | C21: =IF('Balance Sheet'!C18>0,'Profit & Loss'!C4/'Balance Sheet'!C18,0) -> 38.550602 | D21: =IF('Balance Sheet'!D18>0,'Profit & Loss'!D4/'Balance Sheet'!D18,0) -> 30.540821 | E21: =IF('Balance Sheet'!E18>0,'Profit & Loss'!E4/'Balance Sheet'!E18,0) -> 29.163985 | F21: =IF('Balance Sheet'!F18>0,'Profit & Loss'!F4/'Balance Sheet'!F18,0) -> 35.09877 | G21: =IF('Balance Sheet'!G18>0,'Profit & Loss'!G4/'Balance Sheet'!G18,0) -> 24.611344 | H21: =IF('Balance Sheet'!H18>0,'Profit & Loss'!H4/'Balance Sheet'!H18,0) -> 24.033262 | I21: =IF('Balance Sheet'!I18>0,'Profit & Loss'!I4/'Balance Sheet'!I18,0) -> 25.750392 | ... K21: =IF('Balance Sheet'!K18>0,'Profit & Loss'!K4/'Balance Sheet'!K18,0) -> 27.826087
A23: Return on Equity | B23: =IF(SUM('Balance Sheet'!B4:B5)>0,'Profit & Loss'!B12/SUM('Balance Sheet'!B4:B5),"") -> 0.27554535 | C23: =IF(SUM('Balance Sheet'!C4:C5)>0,'Profit & Loss'!C12/SUM('Balance Sheet'!C4:C5),"") -> 0.31457128 | D23: =IF(SUM('Balance Sheet'!D4:D5)>0,'Profit & Loss'!D12/SUM('Balance Sheet'!D4:D5),"") -> 0.25132607 | E23: =IF(SUM('Balance Sheet'!E4:E5)>0,'Profit & Loss'!E12/SUM('Balance Sheet'!E4:E5),"") -> 0.28706934 | F23: =IF(SUM('Balance Sheet'!F4:F5)>0,'Profit & Loss'!F12/SUM('Balance Sheet'!F4:F5),"") -> 0.24322827 | G23: =IF(SUM('Balance Sheet'!G4:G5)>0,'Profit & Loss'!G12/SUM('Balance Sheet'!G4:G5),"") -> 0.25912822 | H23: =IF(SUM('Balance Sheet'!H4:H5)>0,'Profit & Loss'!H12/SUM('Balance Sheet'!H4:H5),"") -> 0.24168632 | I23: =IF(SUM('Balance Sheet'!I4:I5)>0,'Profit & Loss'!I12/SUM('Balance Sheet'!I4:I5),"") -> 0.14458173 | ... K23: =IF(SUM('Balance Sheet'!K4:K5)>0,'Profit & Loss'!K12/SUM('Balance Sheet'!K4:K5),"") -> 0.10892056
A24: Return on Capital Emp | C24: =IF((B4+B5+B6+C4+C5+C6)>0,('Profit & Loss'!C10+'Profit & Loss'!C9)*2/(B4+B5+B6+C4+C5+C6),"") -> 0.53285489 | D24: =IF((C4+C5+C6+D4+D5+D6)>0,('Profit & Loss'!D10+'Profit & Loss'!D9)*2/(C4+C5+C6+D4+D5+D6),"") -> 0.45219649 | E24: =IF((D4+D5+D6+E4+E5+E6)>0,('Profit & Loss'!E10+'Profit & Loss'!E9)*2/(D4+D5+D6+E4+E5+E6),"") -> 0.44768199 | F24: =IF((E4+E5+E6+F4+F5+F6)>0,('Profit & Loss'!F10+'Profit & Loss'!F9)*2/(E4+E5+E6+F4+F5+F6),"") -> 0.35338815 | G24: =IF((F4+F5+F6+G4+G5+G6)>0,('Profit & Loss'!G10+'Profit & Loss'!G9)*2/(F4+F5+F6+G4+G5+G6),"") -> 0.3632041 | H24: =IF((G4+G5+G6+H4+H5+H6)>0,('Profit & Loss'!H10+'Profit & Loss'!H9)*2/(G4+G5+G6+H4+H5+H6),"") -> 0.30559315 | I24: =IF((H4+H5+H6+I4+I5+I6)>0,('Profit & Loss'!I10+'Profit & Loss'!I9)*2/(H4+H5+H6+I4+I5+I6),"") -> 0.17413153 | J24: =IF((I4+I5+I6+J4+J5+J6)>0,('Profit & Loss'!J10+'Profit & Loss'!J9)*2/(I4+I5+I6+J4+J5+J6),"") -> 0.1590216 | K24: =IF((J4+J5+J6+K4+K5+K6)>0,('Profit & Loss'!K10+'Profit & Loss'!K9)*2/(J4+J5+J6+K4+K5+K6),"") -> 0.14808791

Sheet Cash Flow
A1: ='Balance Sheet'!A1 -> METROPOLIS HEALTHCARE LTD | E1: =UPDATE | J1: SCREENER.IN
A3: Narration | B3: ='Data Sheet'!B81 -> 42460 | C3: ='Data Sheet'!C81 -> 42825 | D3: ='Data Sheet'!D81 -> 43190 | E3: ='Data Sheet'!E81 -> 43555 | F3: ='Data Sheet'!F81 -> 43921 | G3: ='Data Sheet'!G81 -> 44286 | H3: ='Data Sheet'!H81 -> 44651 | I3: ='Data Sheet'!I81 -> 45016 | ... K3: ='Data Sheet'!K81 -> 45747
A4: Cash from Operating Activity | B4: ='Data Sheet'!B82 -> 91.42 | C4: ='Data Sheet'!C82 -> 101.75 | D4: ='Data Sheet'!D82 -> 103.93 | E4: ='Data Sheet'!E82 -> 90.15 | F4: ='Data Sheet'!F82 -> 215 | G4: ='Data Sheet'!G82 -> 249.03 | H4: ='Data Sheet'!H82 -> 253.27 | I4: ='Data Sheet'!I82 -> 247.09 | ... K4: ='Data Sheet'!K82 -> 262.75
A5: Cash from Investing Activity | B5: ='Data Sheet'!B83 -> 96.29 | C5: ='Data Sheet'!C83 -> -85.78 | D5: ='Data Sheet'!D83 -> 1.33 | E5: ='Data Sheet'!E83 -> 35.9 | F5: ='Data Sheet'!F83 -> -103.87 | G5: ='Data Sheet'!G83 -> 63.08 | H5: ='Data Sheet'!H83 -> -736.41 | I5: ='Data Sheet'!I83 -> 48.09 | ... K5: ='Data Sheet'!K83 -> -201.06
A6: Cash from Financing Activity | B6: ='Data Sheet'!B84 -> -173.76 | C6: ='Data Sheet'!C84 -> -17.3 | D6: ='Data Sheet'!D84 -> -87.3 | E6: ='Data Sheet'!E84 -> -118.15 | F6: ='Data Sheet'!F84 -> -55.32 | G6: ='Data Sheet'!G84 -> -32.69 | H6: ='Data Sheet'!H84 -> 162.52 | I6: ='Data Sheet'!I84 -> -292.33 | ... K6: ='Data Sheet'!K84 -> -86.63
A7: Net Cash Flow | B7: ='Data Sheet'!B85 -> 13.94 | C7: ='Data Sheet'!C85 -> -1.32 | D7: ='Data Sheet'!D85 -> 17.96 | E7: ='Data Sheet'!E85 -> 7.9 | F7: ='Data Sheet'!F85 -> 55.8 | G7: ='Data Sheet'!G85 -> 279.42 | H7: ='Data Sheet'!H85 -> -320.61 | I7: ='Data Sheet'!I85 -> 2.85 | ... K7: ='Data Sheet'!K85 -> -24.94

Sheet Customization
A1: How to use it?
A3: You can customize this workbook as you want.
B4: You can add custom formating, add conditional formating, add your own formulas… do ANYTHING.
B5: Please don't edit the "Data Sheet" only.
A7: After customization, you can upload this back on Screener.
B8: Upload on: | C8: https://www.screener.in/excel/
A10: Download your customized workbooks now onwards.
B11: Now whenever you will "Export to excel" from Screener, it will export your customized file.
A14: TESTING:
B15: This is a testing feature currently.
B16: You can report any formula errors on the worksheet at: support@screener.in

Sheet Data>

Sheet Data Sheet
A1: COMPANY NAME | B1: METROPOLIS HEALTHCARE LTD | E1: =IF(B2<>B3, "A NEW VERSION OF THE WORKSHEET IS AVAILABLE", "")
A2: LATEST VERSION | B2: 2.1 | E2: PLEASE DO NOT MAKE ANY CHANGES TO THIS SHEET
A3: CURRENT VERSION | B3: 2.1
A5: META
A6: Number of shares | B6: =IF(B9>0, B9/B8, 0) -> 5.1917817
A7: Face Value | B7: 2
A8: Current Price | B8: 1702.3
A9: Market Capitalization | B9: 8837.97
A15: PROFIT & LOSS
A16: Report Date | B16: 42460 | C16: 42825 | D16: 43190 | E16: 43555 | F16: 43921 | G16: 44286 | H16: 44651 | I16: 45016 | J16: 45382 | K16: 45747
A17: Sales | B17: 475.47 | C17: 544.72 | D17: 647.16 | E17: 761.18 | F17: 856.41 | G17: 997.99 | H17: 1228.34 | I17: 1148.21 | J17: 1207.71 | K17: 1331.2
A18: Raw Material Cost | B18: 124.59 | C18: 135.1 | D18: 145.9 | E18: 173.51 | F18: 204.14 | G18: 252.16 | H18: 276.02 | I18: 253.26 | J18: 242.57 | K18: 268.68
A19: Change in Inventory
A20: Power and Fuel | B20: 8.06 | C20: 9.12 | D20: 9.99 | E20: 11 | F20: 12.49 | G20: 12 | H20: 14.73 | I20: 14.43 | J20: 16.2
A21: Other Mfr. Exp | B21: 10.95 | C21: 11.43 | D21: 58.73 | E21: 77.05 | F21: 22.51 | G21: 26.09 | H21: 33.09 | I21: 31.24 | J21: 45.46
A22: Employee Cost | B22: 108.26 | C22: 127.8 | D22: 147.56 | E22: 176.62 | F22: 190.72 | G22: 199.24 | H22: 233.65 | I22: 253.52 | J22: 276.39 | K22: 313.75
A23: Selling and admin | B23: 86.95 | C23: 101.19 | D23: 90.73 | E23: 106.46 | F23: 165.21 | G23: 184.68 | H23: 311.28 | I23: 288.98 | J23: 307.2
A24: Other Expenses | B24: 20.37 | C24: 19.88 | D24: 13.68 | E24: 13.97 | F24: 24.13 | G24: 34.03 | H24: 11.49 | I24: 13.43 | J24: 31.96 | K24: 445.78
A25: Other Income | B25: 29.47 | C25: 38.89 | D25: 5.67 | E25: 8.17 | F25: -16.56 | G25: 12.04 | H25: 33.51 | I25: 15.22 | J25: 9.12 | K25: 15.11
A26: Depreciation | B26: 16.64 | C26: 17.23 | D26: 19.02 | E26: 20.07 | F26: 39.27 | G26: 45.94 | H26: 63.22 | I26: 89.22 | J26: 94.47 | K26: 108.68
A27: Interest | B27: 1.6 | C27: 1.94 | D27: 3.54 | E27: 4.12 | F27: 12.65 | G27: 11.56 | H27: 25.02 | I27: 31.85 | J27: 27.89 | K27: 18.57
A28: Profit before tax | B28: 127.52 | C28: 159.92 | D28: 163.68 | E28: 186.55 | F28: 168.73 | G28: 244.33 | H28: 293.35 | I28: 187.5 | J28: 174.69 | K28: 190.85
A29: Tax | B29: 45.57 | C29: 52.66 | D29: 51.84 | E29: 62.94 | F29: 41.18 | G29: 60.97 | H29: 78.66 | I29: 44.11 | J29: 46.23 | K29: 45.34
A30: Net profit | B30: 76.8 | C30: 101.66 | D30: 104.24 | E30: 120.15 | F30: 127.33 | G30: 183.1 | H30: 214.18 | I30: 142.88 | J30: 127.82 | K30: 144.97
A31: Dividend Amount | B31: 76.71 | C31: 49.98 | E31: 66.57 | F31: 40.52 | G31: 40.88 | H31: 40.92 | I31: 40.96 | J31: 20.5
A40: Quarters
A41: Report Date | B41: 44926 | C41: 45016 | D41: 45107 | E41: 45199 | F41: 45291 | G41: 45382 | H41: 45473 | I41: 45565 | J41: 45657 | K41: 45747
A42: Sales | B42: 285.46 | C42: 282.55 | D42: 277.09 | E42: 308.5 | F42: 291.12 | G42: 331 | H42: 313.36 | I42: 349.79 | J42: 322.77 | K42: 345.29
A43: Expenses | B43: 214.97 | C43: 212.27 | D43: 214.15 | E43: 233.69 | F43: 226.27 | G43: 251.02 | H43: 234.55 | I43: 259.92 | J43: 250.77 | K43: 282.99
A44: Other Income | B44: 6.62 | C44: 1.23 | D44: 3.05 | E44: 1.22 | F44: 2.31 | G44: 2.54 | H44: 2.46 | I44: 3.13 | J44: 2.56 | K44: 6.97
A45: Depreciation | B45: 23.03 | C45: 23.43 | D45: 20.82 | E45: 22.24 | F45: 24.99 | G45: 26.42 | H45: 25.54 | I45: 26.82 | J45: 27.7 | K45: 28.62
A46: Interest | B46: 6.11 | C46: 6.17 | D46: 5.98 | E46: 5.68 | F46: 5.31 | G46: 5.57 | H46: 4.65 | I46: 4.79 | J46: 4.53 | K46: 4.6
A47: Profit before tax | B47: 47.97 | C47: 41.91 | D47: 39.19 | E47: 48.11 | F47: 36.86 | G47: 50.53 | H47: 51.08 | I47: 61.39 | J47: 42.33 | K47: 36.05
A48: Tax | B48: 12.11 | C48: 8.41 | D48: 10.21 | E48: 12.45 | F48: 9.57 | G48: 14.01 | H48: 12.96 | I48: 14.7 | J48: 10.86 | K48: 6.82
A49: Net profit | B49: 35.8 | C49: 33.36 | D49: 28.8 | E49: 35.45 | F49: 27.16 | G49: 36.41 | H49: 37.95 | I49: 46.52 | J49: 31.36 | K49: 29.14
A50: Operating Profit | B50: 70.49 | C50: 70.28 | D50: 62.94 | E50: 74.81 | F50: 64.85 | G50: 79.98 | H50: 78.81 | I50: 89.87 | J50: 72 | K50: 62.3
A55: BALANCE SHEET
A56: Report Date | B56: 42460 | C56: 42825 | D56: 43190 | E56: 43555 | F56: 43921 | G56: 44286 | H56: 44651 | I56: 45016 | J56: 45382 | K56: 45747
A57: Equity Share Capital | B57: 9.54 | C57: 9.54 | D57: 9.54 | E57: 10.04 | F57: 10.13 | G57: 10.22 | H57: 10.23 | I57: 10.24 | J57: 10.25 | K57: 10.36
A58: Reserves | B58: 269.18 | C58: 313.63 | D58: 405.22 | E58: 408.5 | F58: 513.37 | G58: 696.38 | H58: 875.96 | I58: 977.99 | J58: 1085.91 | K58: 1320.61
...

Sheet Financials>
A1: G

Sheet Historical FS
B2: ="Historical Financial Statement - "&'Data Sheet'!B1 -> Historical Financial Statement - METROPOLIS HEALTHCARE LTD
B3: Years | D3: ='Data Sheet'!B16 -> 42460 | E3: ='Data Sheet'!C16 -> 42825 | F3: ='Data Sheet'!D16 -> 43190 | G3: ='Data Sheet'!E16 -> 43555 | H3: ='Data Sheet'!F16 -> 43921 | I3: ='Data Sheet'!G16 -> 44286 | J3: ='Data Sheet'!H16 -> 44651 | K3: ='Data Sheet'!I16 -> 45016 | ... M3: ='Data Sheet'!K16 -> 45747 | N3: LTM
A4: # | B4: Income Statement
B5: Sales | D5: =IFERROR('Data Sheet'!B17,0) -> 475.47 | E5: =IFERROR('Data Sheet'!C17,0) -> 544.72 | F5: =IFERROR('Data Sheet'!D17,0) -> 647.16 | G5: =IFERROR('Data Sheet'!E17,0) -> 761.18 | H5: =IFERROR('Data Sheet'!F17,0) -> 856.41 | I5: =IFERROR('Data Sheet'!G17,0) -> 997.99 | J5: =IFERROR('Data Sheet'!H17,0) -> 1228.34 | K5: =IFERROR('Data Sheet'!I17,0) -> 1148.21 | ... M5: =IFERROR('Data Sheet'!K17,0) -> 1331.2 | N5: =IFERROR(SUM('Data Sheet'!H42:K42),0) -> 1331.21
B6: Sales Growth | D6: - | E6: =E5/D5 - 1 -> 0.14564536 | F6: =F5/E5 - 1 -> 0.18805992 | G6: =G5/F5 - 1 -> 0.17618518 | H6: =H5/G5 - 1 -> 0.12510838 | I6: =I5/H5 - 1 -> 0.16531801 | J6: =J5/I5 - 1 -> 0.23081394 | K6: =K5/J5 - 1 -> -0.065234381 | L6: =L5/K5 - 1 -> 0.051819789 | ... N6: =N5/M5 - 1 -> 7.5120192e-06
B8: COGS | D8: =IFERROR(SUM('Data Sheet'!B18,'Data Sheet'!B20:B22)-1*'Data Sheet'!B19,0) -> 251.86 | E8: =IFERROR(SUM('Data Sheet'!C18,'Data Sheet'!C20:C22)-1*'Data Sheet'!C19,0) -> 283.45 | F8: =IFERROR(SUM('Data Sheet'!D18,'Data Sheet'!D20:D22)-1*'Data Sheet'!D19,0) -> 362.18 | G8: =IFERROR(SUM('Data Sheet'!E18,'Data Sheet'!E20:E22)-1*'Data Sheet'!E19,0) -> 438.18 | H8: =IFERROR(SUM('Data Sheet'!F18,'Data Sheet'!F20:F22)-1*'Data Sheet'!F19,0) -> 429.86 | I8: =IFERROR(SUM('Data Sheet'!G18,'Data Sheet'!G20:G22)-1*'Data Sheet'!G19,0) -> 489.49 | J8: =IFERROR(SUM('Data Sheet'!H18,'Data Sheet'!H20:H22)-1*'Data Sheet'!H19,0) -> 557.49 | K8: =IFERROR(SUM('Data Sheet'!I18,'Data Sheet'!I20:I22)-1*'Data Sheet'!I19,0) -> 552.45 | ... M8: =IFERROR(SUM('Data Sheet'!K18,'Data Sheet'!K20:K22)-1*'Data Sheet'!K19,0) -> 582.43 | N8: =IFERROR(SUM('Data Sheet'!H43:K43),0) -> 1028.23
B9: COGS % Sales | D9: =D8/D5 -> 0.52970745 | E9: =E8/E5 -> 0.52035908 | F9: =F8/F5 -> 0.55964522 | G9: =G8/G5 -> 0.57565885 | H9: =H8/H5 -> 0.50193249 | I9: =I8/I5 -> 0.49047586 | J9: =J8/J5 -> 0.45385642 | K9: =K8/K5 -> 0.48114021 | ... N9: =N8/N5 -> 0.77240255
B11: Gross Profit | D11: =D5-D8 -> 223.61 | E11: =E5-E8 -> 261.27 | F11: =F5-F8 -> 284.98 | G11: =G5-G8 -> 323 | H11: =H5-H8 -> 426.55 | I11: =I5-I8 -> 508.5 | J11: =J5-J8 -> 670.85 | K11: =K5-K8 -> 595.76 | ... N11: =N5-N8 -> 302.98
B12: Gross Margin | D12: =(D5-D8)/D5 -> 0.47029255 | E12: =(E5-E8)/E5 -> 0.47964092 | F12: =(F5-F8)/F5 -> 0.44035478 | G12: =(G5-G8)/G5 -> 0.42434115 | H12: =(H5-H8)/H5 -> 0.49806751 | I12: =(I5-I8)/I5 -> 0.50952414 | J12: =(J5-J8)/J5 -> 0.54614358 | K12: =(K5-K8)/K5 -> 0.51885979 | ... N12: =(N5-N8)/N5 -> 0.22759745
B14: Selling & General Expenses | D14: =IFERROR(SUM('Data Sheet'!B23:B24),0) -> 107.32 | E14: =IFERROR(SUM('Data Sheet'!C23:C24),0) -> 121.07 | F14: =IFERROR(SUM('Data Sheet'!D23:D24),0) -> 104.41 | G14: =IFERROR(SUM('Data Sheet'!E23:E24),0) -> 120.43 | H14: =IFERROR(SUM('Data Sheet'!F23:F24),0) -> 189.34 | I14: =IFERROR(SUM('Data Sheet'!G23:G24),0) -> 218.71 | J14: =IFERROR(SUM('Data Sheet'!H23:H24),0) -> 322.77 | K14: =IFERROR(SUM('Data Sheet'!I23:I24),0) -> 302.41 | ... N14: =IFERROR(SUM('Data Sheet'!L23:L24),0) -> 0
B15: S&G Exp % Sales | D15: =D14/D5 -> 0.2257135 | E15: =E14/E5 -> 0.22226098 | F15: =F14/F5 -> 0.16133568 | G15: =G14/G5 -> 0.15821488 | H15: =H14/H5 -> 0.22108569 | I15: =I14/I5 -> 0.21915049 | J15: =J14/J5 -> 0.26276927 | K15: =K14/K5 -> 0.26337517 | ... N15: =N14/N5 -> 0
B17: EBITDA | D17: =D11-D14 -> 116.29 | E17: =E11-E14 -> 140.2 | F17: =F11-F14 -> 180.57 | G17: =G11-G14 -> 202.57 | H17: =H11-H14 -> 237.21 | I17: =I11-I14 -> 289.79 | J17: =J11-J14 -> 348.08 | K17: =K11-K14 -> 293.35 | ... N17: =N11-N14 -> 302.98
B18: EBITDA Margin | D18: =D17/D5 -> 0.24457905 | E18: =E17/E5 -> 0.25737994 | F18: =F17/F5 -> 0.2790191 | G18: =G17/G5 -> 0.26612628 | H18: =H17/H5 -> 0.27698182 | I18: =I17/I5 -> 0.29037365 | J18: =J17/J5 -> 0.28337431 | K18: =K17/K5 -> 0.25548462 | ... N18: =N17/N5 -> 0.22759745
B19: EBITDA % Sales | D19: =D17/D5 -> 0.24457905 | E19: =E17/E5 -> 0.25737994 | F19: =F17/F5 -> 0.2790191 | G19: =G17/G5 -> 0.26612628 | H19: =H17/H5 -> 0.27698182 | I19: =I17/I5 -> 0.29037365 | J19: =J17/J5 -> 0.28337431 | K19: =K17/K5 -> 0.25548462 | ... N19: =N17/N5 -> 0.22759745
B21: Interest | D21: =IFERROR('Data Sheet'!B27,0) -> 1.6 | E21: =IFERROR('Data Sheet'!C27,0) -> 1.94 | F21: =IFERROR('Data Sheet'!D27,0) -> 3.54 | G21: =IFERROR('Data Sheet'!E27,0) -> 4.12 | H21: =IFERROR('Data Sheet'!F27,0) -> 12.65 | I21: =IFERROR('Data Sheet'!G27,0) -> 11.56 | J21: =IFERROR('Data Sheet'!H27,0) -> 25.02 | K21: =IFERROR('Data Sheet'!I27,0) -> 31.85 | ... N21: =IFERROR('Data Sheet'!L27,0) -> 0
B22: Interest % Sales | D22: =D21/D5 -> 0.0033650914 | E22: =E21/E5 -> 0.0035614628 | F22: =F21/F5 -> 0.0054700538 | G22: =G21/G5 -> 0.0054126488 | H22: =H21/H5 -> 0.014770963 | I22: =I21/I5 -> 0.011583282 | J22: =J21/J5 -> 0.020368953 | K22: =K21/K5 -> 0.027738828 | ... N22: =N21/N5 -> 0
B24: Depreciation | D24: =IFERROR('Data Sheet'!B26,0) -> 16.64 | E24: =IFERROR('Data Sheet'!C26,0) -> 17.23 | F24: =IFERROR('Data Sheet'!D26,0) -> 19.02 | G24: =IFERROR('Data Sheet'!E26,0) -> 20.07 | H24: =IFERROR('Data Sheet'!F26,0) -> 39.27 | I24: =IFERROR('Data Sheet'!G26,0) -> 45.94 | J24: =IFERROR('Data Sheet'!H26,0) -> 63.22 | K24: =IFERROR('Data Sheet'!I26,0) -> 89.22 | ... M24: =IFERROR('Data Sheet'!K26,0) -> 108.68 | N24: =IFERROR(SUM('Data Sheet'!H45:K45),0) -> 108.68
B25: Depreciation % Sales | D25: =D24/D5 -> 0.03499695 | E25: =E24/E5 -> 0.03163093 | F25: =F24/F5 -> 0.02938995 | G25: =G24/G5 -> 0.026366957 | H25: =H24/H5 -> 0.045854205 | I25: =I24/I5 -> 0.046032525 | J25: =J24/J5 -> 0.051467835 | K25: =K24/K5 -> 0.077703556 | ... N25: =N24/N5 -> 0.081640012
B27: Earning before Taxes | D27: =IFERROR(D17-SUM(D21,D24),0) -> 98.05 | E27: =IFERROR(E17-SUM(E21,E24),0) -> 121.03 | F27: =IFERROR(F17-SUM(F21,F24),0) -> 158.01 | G27: =IFERROR(G17-SUM(G21,G24),0) -> 178.38 | H27: =IFERROR(H17-SUM(H21,H24),0) -> 185.29 | I27: =IFERROR(I17-SUM(I21,I24),0) -> 232.29 | J27: =IFERROR(J17-SUM(J21,J24),0) -> 259.84 | K27: =IFERROR(K17-SUM(K21,K24),0) -> 172.28 | ... N27: =IFERROR(N17-SUM(N21,N24),0) -> 194.3
B28: EBT % Sales | D28: =D27/D5 -> 0.20621701 | E28: =E27/E5 -> 0.22218755 | F28: =F27/F5 -> 0.2441591 | G28: =G27/G5 -> 0.23434667 | H28: =H27/H5 -> 0.21635665 | I28: =I27/I5 -> 0.23275784 | J28: =J27/J5 -> 0.21153752 | K28: =K27/K5 -> 0.15004224 | ... N28: =N27/N5 -> 0.14595744
B30: Tax | D30: =IFERROR('Data Sheet'!B29,0) -> 45.57 | E30: =IFERROR('Data Sheet'!C29,0) -> 52.66 | F30: =IFERROR('Data Sheet'!D29,0) -> 51.84 | G30: =IFERROR('Data Sheet'!E29,0) -> 62.94 | H30: =IFERROR('Data Sheet'!F29,0) -> 41.18 | I30: =IFERROR('Data Sheet'!G29,0) -> 60.97 | J30: =IFERROR('Data Sheet'!H29,0) -> 78.66 | K30: =IFERROR('Data Sheet'!I29,0) -> 44.11 | ... M30: =IFERROR('Data Sheet'!K29,0) -> 45.34 | N30: =IFERROR(SUM('Data Sheet'!H48:K48),0) -> 45.34
B31: Effective Tax Rate | D31: =D30/D27 -> 0.46476288 | E31: =E30/E27 -> 0.43509874 | F31: =F30/F27 -> 0.3280805 | G31: =G30/G27 -> 0.35284225 | H31: =H30/H27 -> 0.22224621 | I31: =I30/I27 -> 0.26247363 | J31: =J30/J27 -> 0.30272475 | K31: =K30/K27 -> 0.25603668 | ... N31: =N30/N27 -> 0.23335049
B33: Net Profit | D33: =IFERROR(D27-D30,0) -> 52.48 | E33: =IFERROR(E27-E30,0) -> 68.37 | F33: =IFERROR(F27-F30,0) -> 106.17 | G33: =IFERROR(G27-G30,0) -> 115.44 | H33: =IFERROR(H27-H30,0) -> 144.11 | I33: =IFERROR(I27-I30,0) -> 171.32 | J33: =IFERROR(J27-J30,0) -> 181.18 | K33: =IFERROR(K27-K30,0) -> 128.17 | ... N33: =IFERROR(N27-N30,0) -> 148.96
B34: Net Margins | D34: =D33/D5 -> 0.110375 | E34: =E33/E5 -> 0.12551403 | F34: =F33/F5 -> 0.16405526 | G34: =G33/G5 -> 0.15165927 | H34: =H33/H5 -> 0.16827221 | I34: =I33/I5 -> 0.17166505 | J34: =J33/J5 -> 0.14749988 | K34: =K33/K5 -> 0.11162592 | ... N34: =N33/N5 -> 0.1118982
B36: No. of Equity Shares | D36: =IFERROR('Data Sheet'!B93,0) -> 0.95 | E36: =IFERROR('Data Sheet'!C93,0) -> 0.95 | F36: =IFERROR('Data Sheet'!D93,0) -> 0.95 | G36: =IFERROR('Data Sheet'!E93,0) -> 5.02 | H36: =IFERROR('Data Sheet'!F93,0) -> 5.06 | I36: =IFERROR('Data Sheet'!G93,0) -> 5.11 | J36: =IFERROR('Data Sheet'!H93,0) -> 5.12 | K36: =IFERROR('Data Sheet'!I93,0) -> 5.12 | ... M36: =IFERROR('Data Sheet'!K93,0) -> 5.18
B38: EPS(Earning per share) | D38: =IFERROR(D33/D36,0) -> 55.242105 | E38: =IFERROR(E33/E36,0) -> 71.968421 | F38: =IFERROR(F33/F36,0) -> 111.75789 | G38: =IFERROR(G33/G36,0) -> 22.996016 | H38: =IFERROR(H33/H36,0) -> 28.480237 | I38: =IFERROR(I33/I36,0) -> 33.526419 | J38: =IFERROR(J33/J36,0) -> 35.386719 | K38: =IFERROR(K33/K36,0) -> 25.033203 | ... M38: =IFERROR(M33/M36,0) -> 25.173745
B39: EPS Growth%) | E39: =E38/D38-1 -> 0.30278201 | F39: =F38/E38-1 -> 0.55287407 | G39: =G38/F38-1 -> -0.79423363 | H39: =H38/G38-1 -> 0.23848571 | I39: =I38/H38-1 -> 0.17718187 | J39: =J38/I38-1 -> 0.055487584 | K39: =K38/J38-1 -> -0.29258196 | L39: =L38/K38-1 -> -0.068892877 | M39: =M38/L38-1 -> 0.080019904
B41: Dividend per share | D41: =IFERROR('Data Sheet'!B31/'Historical FS'!D36,0) -> 80.747368 | E41: =IFERROR('Data Sheet'!C31/'Historical FS'!E36,0) -> 52.610526 | F41: =IFERROR('Data Sheet'!D31/'Historical FS'!F36,0) -> 0 | G41: =IFERROR('Data Sheet'!E31/'Historical FS'!G36,0) -> 13.260956 | H41: =IFERROR('Data Sheet'!F31/'Historical FS'!H36,0) -> 8.0079051 | I41: =IFERROR('Data Sheet'!G31/'Historical FS'!I36,0) -> 8 | J41: =IFERROR('Data Sheet'!H31/'Historical FS'!J36,0) -> 7.9921875 | K41: =IFERROR('Data Sheet'!I31/'Historical FS'!K36,0) -> 8 | ... M41: =IFERROR('Data Sheet'!K31/'Historical FS'!M36,0) -> 0
B42: Dividend payout ratio | D42: =IFERROR(D41/D38,0) -> 1.4616997 | E42: =IFERROR(E41/E38,0) -> 0.73102238 | F42: =IFERROR(F41/F38,0) -> 0 | G42: =IFERROR(G41/G38,0) -> 0.5766632 | H42: =IFERROR(H41/H38,0) -> 0.2811741 | I42: =IFERROR(I41/I38,0) -> 0.23861779 | J42: =IFERROR(J41/J38,0) -> 0.22585274 | K42: =IFERROR(K41/K38,0) -> 0.31957556 | ... M42: =IFERROR(M41/M38,0) -> 0
B44: Retained Earnings | D44: =IFERROR(IF(D41<D38,1-D41/D38,0),0) -> 0 | E44: =IFERROR(IF(E41<E38,1-E41/E38,0),0) -> 0.26897762 | F44: =IFERROR(IF(F41<F38,1-F41/F38,0),0) -> 1 | G44: =IFERROR(IF(G41<G38,1-G41/G38,0),0) -> 0.4233368 | H44: =IFERROR(IF(H41<H38,1-H41/H38,0),0) -> 0.7188259 | I44: =IFERROR(IF(I41<I38,1-I41/I38,0),0) -> 0.76138221 | J44: =IFERROR(IF(J41<J38,1-J41/J38,0),0) -> 0.77414726 | K44: =IFERROR(IF(K41<K38,1-K41/K38,0),0) -> 0.68042444 | ... M44: =IFERROR(IF(M41<M38,1-M41/M38,0),0) -> 1
A47: # | B47: Balance Sheet
B48: Equity Share Capital | D48: =IFERROR('Data Sheet'!B57,0) -> 9.54 | E48: =IFERROR('Data Sheet'!C57,0) -> 9.54 | F48: =IFERROR('Data Sheet'!D57,0) -> 9.54 | G48: =IFERROR('Data Sheet'!E57,0) -> 10.04 | H48: =IFERROR('Data Sheet'!F57,0) -> 10.13 | I48: =IFERROR('Data Sheet'!G57,0) -> 10.22 | J48: =IFERROR('Data Sheet'!H57,0) -> 10.23 | K48: =IFERROR('Data Sheet'!I57,0) -> 10.24 | ... M48: =IFERROR('Data Sheet'!K57,0) -> 10.36
B49: Reserves | D49: =IFERROR('Data Sheet'!B58,0) -> 269.18 | E49: =IFERROR('Data Sheet'!C58,0) -> 313.63 | F49: =IFERROR('Data Sheet'!D58,0) -> 405.22 | G49: =IFERROR('Data Sheet'!E58,0) -> 408.5 | H49: =IFERROR('Data Sheet'!F58,0) -> 513.37 | I49: =IFERROR('Data Sheet'!G58,0) -> 696.38 | J49: =IFERROR('Data Sheet'!H58,0) -> 875.96 | K49: =IFERROR('Data Sheet'!I58,0) -> 977.99 | ... M49: =IFERROR('Data Sheet'!K58,0) -> 1320.61
B50: Borrowings | D50: =IFERROR('Data Sheet'!B59,0) -> 4.7 | E50: =IFERROR('Data Sheet'!C59,0) -> 0.93 | F50: =IFERROR('Data Sheet'!D59,0) -> 0.73 | G50: =IFERROR('Data Sheet'!E59,0) -> 17.78 | H50: =IFERROR('Data Sheet'!F59,0) -> 66.7 | I50: =IFERROR('Data Sheet'!G59,0) -> 112.27 | J50: =IFERROR('Data Sheet'!H59,0) -> 378.56 | K50: =IFERROR('Data Sheet'!I59,0) -> 266.38 | ... M50: =IFERROR('Data Sheet'!K59,0) -> 204.13
B51: Other Liabilities | D51: =IFERROR('Data Sheet'!B60,0) -> 107.24 | E51: =IFERROR('Data Sheet'!C60,0) -> 187.63 | F51: =IFERROR('Data Sheet'!D60,0) -> 110.4 | G51: =IFERROR('Data Sheet'!E60,0) -> 113.42 | H51: =IFERROR('Data Sheet'!F60,0) -> 160.3 | I51: =IFERROR('Data Sheet'!G60,0) -> 181.39 | J51: =IFERROR('Data Sheet'!H60,0) -> 255.76 | K51: =IFERROR('Data Sheet'!I60,0) -> 240.11 | ... M51: =IFERROR('Data Sheet'!K60,0) -> 332.24
B52: Total Liabilities | D52: =IFERROR('Data Sheet'!B61,0) -> 390.66 | E52: =IFERROR('Data Sheet'!C61,0) -> 511.73 | F52: =IFERROR('Data Sheet'!D61,0) -> 525.89 | G52: =IFERROR('Data Sheet'!E61,0) -> 549.74 | H52: =IFERROR('Data Sheet'!F61,0) -> 750.5 | I52: =IFERROR('Data Sheet'!G61,0) -> 1000.26 | J52: =IFERROR('Data Sheet'!H61,0) -> 1520.51 | K52: =IFERROR('Data Sheet'!I61,0) -> 1494.72 | ... M52: =IFERROR('Data Sheet'!K61,0) -> 1867.34
B54: Fixed Assets Net Block | D54: =IFERROR('Data Sheet'!B62,0) -> 141.66 | E54: =IFERROR('Data Sheet'!C62,0) -> 202.36 | F54: =IFERROR('Data Sheet'!D62,0) -> 207.44 | G54: =IFERROR('Data Sheet'!E62,0) -> 212.81 | H54: =IFERROR('Data Sheet'!F62,0) -> 296.37 | I54: =IFERROR('Data Sheet'!G62,0) -> 343.11 | J54: =IFERROR('Data Sheet'!H62,0) -> 1058.93 | K54: =IFERROR('Data Sheet'!I62,0) -> 1120.67 | ... M54: =IFERROR('Data Sheet'!K62,0) -> 1446.96
B55: Capital Work in Progress | D55: =IFERROR('Data Sheet'!B63,0) -> 0.56 | E55: =IFERROR('Data Sheet'!C63,0) -> 0.95 | F55: =IFERROR('Data Sheet'!D63,0) -> 0 | G55: =IFERROR('Data Sheet'!E63,0) -> 5.77 | H55: =IFERROR('Data Sheet'!F63,0) -> 2.99 | I55: =IFERROR('Data Sheet'!G63,0) -> 0 | J55: =IFERROR('Data Sheet'!H63,0) -> 5.78 | K55: =IFERROR('Data Sheet'!I63,0) -> 19.51 | ... M55: =IFERROR('Data Sheet'!K63,0) -> 0
B56: Investments | D56: =IFERROR('Data Sheet'!B64,0) -> 101.39 | E56: =IFERROR('Data Sheet'!C64,0) -> 141.84 | F56: =IFERROR('Data Sheet'!D64,0) -> 102.18 | G56: =IFERROR('Data Sheet'!E64,0) -> 33.29 | H56: =IFERROR('Data Sheet'!F64,0) -> 14.32 | I56: =IFERROR('Data Sheet'!G64,0) -> 10.08 | J56: =IFERROR('Data Sheet'!H64,0) -> 15.51 | K56: =IFERROR('Data Sheet'!I64,0) -> 14.81 | ... M56: =IFERROR('Data Sheet'!K64,0) -> 70.99
B57: Other Assets | D57: =IFERROR('Data Sheet'!B65-SUM('Data Sheet'!B67:B69),0) -> 27.68 | E57: =IFERROR('Data Sheet'!C65-SUM('Data Sheet'!C67:C69),0) -> 31.65 | F57: =IFERROR('Data Sheet'!D65-SUM('Data Sheet'!D67:D69),0) -> 34.26 | G57: =IFERROR('Data Sheet'!E65-SUM('Data Sheet'!E67:E69),0) -> 54.68 | H57: =IFERROR('Data Sheet'!F65-SUM('Data Sheet'!F67:F69),0) -> 73.7 | I57: =IFERROR('Data Sheet'!G65-SUM('Data Sheet'!G67:G69),0) -> 63.84 | J57: =IFERROR('Data Sheet'!H65-SUM('Data Sheet'!H67:H69),0) -> 86.75 | K57: =IFERROR('Data Sheet'!I65-SUM('Data Sheet'!I67:I69),0) -> 80.06 | ... M57: =IFERROR('Data Sheet'!K65-SUM('Data Sheet'!K67:K69),0) -> 104.58
...

Sheet Cash Flow Data
C2: 41334 | D2: 41699 | E2: 42064 | F2: 42430 | G2: 42795 | H2: 43160 | I2: 43525 | J2: 43891 | K2: 44256 | L2: 44621 | M2: 44986 | N2: 45352
B3: Cash from Operating Activity | C3: 22163 | D3: 36151 | E3: 35531 | F3: 37900 | G3: 30199 | H3: 23857 | I3: 18891 | J3: 26633 | K3: 29001 | L3: 14283 | M3: 35388 | N3: 67915
B4: Profit from operations | C4: 24406 | D4: 36303 | E4: 43397 | F4: 38626 | G4: 28840 | H4: 33312 | I4: 28771 | J4: 23352 | K4: 31198 | L4: 26943 | M4: 41694 | N4: 65106
B5: Receivables | C5: -5177 | D5: 445 | E5: -3179 | F5: -2223 | G5: -4152 | H5: -10688 | I5: -9109 | J5: 9950 | K5: -5505 | L5: 185 | M5: -2213 | N5: -1875
B6: Inventory | C6: -2656 | D6: -2853 | E6: -3692 | F6: -5743 | G6: -6621 | H6: -3560 | I6: 2069 | J6: 2326 | K6: 3814 | L6: 472 | M6: -5665 | N6: -7265
B7: Payables | C7: 8132 | D7: 4694 | E7: 3598 | F7: 3947 | G7: 9301 | H7: 7320 | I7: -4692 | J7: -8085 | K7: 5748 | L7: -7012 | M7: 6945 | N7: 13706
B8: Loans Advances | C8: 0 | D8: 0 | E8: 0 | F8: -520 | G8: 0 | H8: 0 | I8: 0 | J8: 0 | K8: 0 | L8: 0 | M8: 0 | N8: 0
B9: Other WC items | C9: -303 | D9: 1870 | E9: -398 | F9: 5852 | G9: 4727 | H9: 494 | I9: 4512 | J9: 875 | K9: -4150 | L9: -4396 | M9: -2194 | N9: 2760
B10: Working capital changes | C10: -3 | D10: 4157 | E10: -3672 | F10: 1313 | G10: 3254 | H10: -6434 | I10: -7221 | J10: 5065 | K10: -93 | L10: -10750 | M10: -3127 | N10: 7325
B11: Direct taxes | C11: -2240 | D11: -4308 | E11: -4194 | F11: -2040 | G11: -1895 | H11: -3021 | I11: -2659 | J11: -1785 | K11: -2105 | L11: -1910 | M11: -3179 | N11: -4516
B12: Cash from Investing Activity | C12: -22969 | D12: -27991 | E12: -36232 | F12: -36694 | G12: -39571 | H12: -25139 | I12: -20878 | J12: -33115 | K12: -25672 | L12: -4444 | M12: -15417 | N12: -22782
B13: Fixed assets purchased | C13: -18863 | D13: -26975 | E13: -31962 | F13: -31503 | G13: -16072 | H13: -35079 | I13: -35304 | J13: -29702 | K13: -20205 | L13: -15168 | M13: -19230 | N13: -31414
B14: Fixed assets sold | C14: 37 | D14: 50 | E14: 74 | F14: 59 | G14: 53 | H14: 30 | I14: 67 | J14: 171 | K14: 351 | L14: 230 | M14: 285 | N14: 231
... B33: Net Cash Flow | C33: -2499 | D33: 4277 | E33: 4500 | F33: -2589 | G33: -3167 | H33: 730 | I33: 6843 | J33: -3092 | K33: 13232 | L33: 6459 | M33: -6272 | N33: 8128

Sheet Ratio Analysis
B2: ="Ratio Analysis of - "&'Data Sheet'!B1 -> Ratio Analysis of - METROPOLIS HEALTHCARE LTD
B3: Years | D3: ='Data Sheet'!B16 -> 42460 | E3: ='Data Sheet'!C16 -> 42825 | F3: ='Data Sheet'!D16 -> 43190 | G3: ='Data Sheet'!E16 -> 43555 | H3: ='Data Sheet'!F16 -> 43921 | I3: ='Data Sheet'!G16 -> 44286 | J3: ='Data Sheet'!H16 -> 44651 | K3: ='Data Sheet'!I16 -> 45016 | ... M3: ='Data Sheet'!K16 -> 45747 | N3: Trend | O3: Mean | P3: Median
B5: Sales Growth | E5: =IFERROR('Historical FS'!E6,0) -> 0.14564536 | F5: =IFERROR('Historical FS'!F6,0) -> 0.18805992 | G5: =IFERROR('Historical FS'!G6,0) -> 0.17618518 | H5: =IFERROR('Historical FS'!H6,0) -> 0.12510838 | I5: =IFERROR('Historical FS'!I6,0) -> 0.16531801 | J5: =IFERROR('Historical FS'!J6,0) -> 0.23081394 | K5: =IFERROR('Historical FS'!K6,0) -> -0.065234381 | L5: =IFERROR('Historical FS'!L6,0) -> 0.051819789 | M5: =IFERROR('Historical FS'!M6,0) -> 0.10225137 | O5: =IFERROR(AVERAGE(E5:M5),0) -> 0.12444084 | P5: =IFERROR(MEDIAN(E5:M5),0) -> 0.14564536
B6: EBITDA Growth | E6: =IFERROR('Historical FS'!E17/'Historical FS'!D17-1,0) -> 0.20560667 | F6: =IFERROR('Historical FS'!F17/'Historical FS'!E17-1,0) -> 0.28794579 | G6: =IFERROR('Historical FS'!G17/'Historical FS'!F17-1,0) -> 0.12183641 | H6: =IFERROR('Historical FS'!H17/'Historical FS'!G17-1,0) -> 0.17100262 | I6: =IFERROR('Historical FS'!I17/'Historical FS'!H17-1,0) -> 0.22166013 | J6: =IFERROR('Historical FS'!J17/'Historical FS'!I17-1,0) -> 0.20114566 | K6: =IFERROR('Historical FS'!K17/'Historical FS'!J17-1,0) -> -0.15723397 | L6: =IFERROR('Historical FS'!L17/'Historical FS'!K17-1,0) -> -0.018476223 | M6: =IFERROR('Historical FS'!M17/'Historical FS'!L17-1,0) -> 0.05230438 | O6: =IFERROR(AVERAGE(E6:M6),0) -> 0.1206435 | P6: =IFERROR(MEDIAN(E6:M6),0) -> 0.17100262
B7: EBT Growth | E7: =IFERROR('Historical FS'!E27/'Historical FS'!D27-1,0) -> 0.23437022 | F7: =IFERROR('Historical FS'!F27/'Historical FS'!E27-1,0) -> 0.30554408 | G7: =IFERROR('Historical FS'!G27/'Historical FS'!F27-1,0) -> 0.12891589 | H7: =IFERROR('Historical FS'!H27/'Historical FS'!G27-1,0) -> 0.038737527 | I7: =IFERROR('Historical FS'!I27/'Historical FS'!H27-1,0) -> 0.25365643 | J7: =IFERROR('Historical FS'!J27/'Historical FS'!I27-1,0) -> 0.11860175 | K7: =IFERROR('Historical FS'!K27/'Historical FS'!J27-1,0) -> -0.3369766 | L7: =IFERROR('Historical FS'!L27/'Historical FS'!K27-1,0) -> -0.038948224 | M7: =IFERROR('Historical FS'!M27/'Historical FS'!L27-1,0) -> 0.061424171 | O7: =IFERROR(AVERAGE(E7:M7),0) -> 0.085036138 | P7: =IFERROR(MEDIAN(E7:M7),0) -> 0.11860175
B8: Net Profit Growth | E8: =IFERROR('Historical FS'!E33/'Historical FS'!D33-1,0) -> 0.30278201 | F8: =IFERROR('Historical FS'!F33/'Historical FS'!E33-1,0) -> 0.55287407 | G8: =IFERROR('Historical FS'!G33/'Historical FS'!F33-1,0) -> 0.0873128 | H8: =IFERROR('Historical FS'!H33/'Historical FS'!G33-1,0) -> 0.24835412 | I8: =IFERROR('Historical FS'!I33/'Historical FS'!H33-1,0) -> 0.1888141 | J8: =IFERROR('Historical FS'!J33/'Historical FS'!I33-1,0) -> 0.057553117 | K8: =IFERROR('Historical FS'!K33/'Historical FS'!J33-1,0) -> -0.29258196 | L8: =IFERROR('Historical FS'!L33/'Historical FS'!K33-1,0) -> -0.068892877 | M8: =IFERROR('Historical FS'!M33/'Historical FS'!L33-1,0) -> 0.092676387 | O8: =IFERROR(AVERAGE(E8:M8),0) -> 0.12987686 | P8: =IFERROR(MEDIAN(E8:M8),0) -> 0.092676387
B9: Dividend Growth | E9: =IFERROR('Historical FS'!E41/'Historical FS'!D41-1,0) -> -0.34845522 | F9: =IFERROR('Historical FS'!F41/'Historical FS'!E41-1,0) -> -1 | G9: =IFERROR('Historical FS'!G41/'Historical FS'!F41-1,0) -> 0 | H9: =IFERROR('Historical FS'!H41/'Historical FS'!G41-1,0) -> -0.39612913 | I9: =IFERROR('Historical FS'!I41/'Historical FS'!H41-1,0) -> -0.00098716683 | J9: =IFERROR('Historical FS'!J41/'Historical FS'!I41-1,0) -> -0.0009765625 | K9: =IFERROR('Historical FS'!K41/'Historical FS'!J41-1,0) -> 0.00097751711 | L9: =IFERROR('Historical FS'!L41/'Historical FS'!K41-1,0) -> -0.49951172 | M9: =IFERROR('Historical FS'!M41/'Historical FS'!L41-1,0) -> -1 | O9: =IFERROR(AVERAGE(E9:M9),0) -> -0.3605647 | P9: =IFERROR(MEDIAN(E9:M9),0) -> -0.34845522
B11: Gross Margin | D11: =IFERROR('Historical FS'!D12,0) -> 0.47029255 | E11: =IFERROR('Historical FS'!E12,0) -> 0.47964092 | F11: =IFERROR('Historical FS'!F12,0) -> 0.44035478 | G11: =IFERROR('Historical FS'!G12,0) -> 0.42434115 | H11: =IFERROR('Historical FS'!H12,0) -> 0.49806751 | I11: =IFERROR('Historical FS'!I12,0) -> 0.50952414 | J11: =IFERROR('Historical FS'!J12,0) -> 0.54614358 | K11: =IFERROR('Historical FS'!K12,0) -> 0.51885979 | ... M11: =IFERROR('Historical FS'!M12,0) -> 0.56247746 | O11: =IFERROR(AVERAGE(D11:M11),0) -> 0.49689408 | P11: =IFERROR(MEDIAN(D11:M11),0) -> 0.50379583
B12: EBITDA Margin | D12: =IFERROR('Historical FS'!D18,0) -> 0.24457905 | E12: =IFERROR('Historical FS'!E18,0) -> 0.25737994 | F12: =IFERROR('Historical FS'!F18,0) -> 0.2790191 | G12: =IFERROR('Historical FS'!G18,0) -> 0.26612628 | H12: =IFERROR('Historical FS'!H18,0) -> 0.27698182 | I12: =IFERROR('Historical FS'!I18,0) -> 0.29037365 | J12: =IFERROR('Historical FS'!J18,0) -> 0.28337431 | K12: =IFERROR('Historical FS'!K18,0) -> 0.25548462 | ... M12: =IFERROR('Historical FS'!M18,0) -> 0.22760667 | O12: =IFERROR(AVERAGE(D12:M12),0) -> 0.26193353 | P12: =IFERROR(MEDIAN(D12:M12),0) -> 0.26175311
B13: EBIT Margin | D13: =IFERROR(('Historical FS'!D17-'Historical FS'!D24)/'Historical FS'!D5,0) -> 0.2095821 | E13: =IFERROR(('Historical FS'!E17-'Historical FS'!E24)/'Historical FS'!E5,0) -> 0.22574901 | F13: =IFERROR(('Historical FS'!F17-'Historical FS'!F24)/'Historical FS'!F5,0) -> 0.24962915 | G13: =IFERROR(('Historical FS'!G17-'Historical FS'!G24)/'Historical FS'!G5,0) -> 0.23975932 | H13: =IFERROR(('Historical FS'!H17-'Historical FS'!H24)/'Historical FS'!H5,0) -> 0.23112761 | I13: =IFERROR(('Historical FS'!I17-'Historical FS'!I24)/'Historical FS'!I5,0) -> 0.24434113 | J13: =IFERROR(('Historical FS'!J17-'Historical FS'!J24)/'Historical FS'!J5,0) -> 0.23190648 | K13: =IFERROR(('Historical FS'!K17-'Historical FS'!K24)/'Historical FS'!K5,0) -> 0.17778107 | ... M13: =IFERROR(('Historical FS'!M17-'Historical FS'!M24)/'Historical FS'!M5,0) -> 0.14596605 | O13: =IFERROR(AVERAGE(D13:M13),0) -> 0.21160294 | P13: =IFERROR(MEDIAN(D13:M13),0) -> 0.22843831
B14: EBT Margin | D14: =IFERROR('Historical FS'!D28,0) -> 0.20621701 | E14: =IFERROR('Historical FS'!E28,0) -> 0.22218755 | F14: =IFERROR('Historical FS'!F28,0) -> 0.2441591 | G14: =IFERROR('Historical FS'!G28,0) -> 0.23434667 | H14: =IFERROR('Historical FS'!H28,0) -> 0.21635665 | I14: =IFERROR('Historical FS'!I28,0) -> 0.23275784 | J14: =IFERROR('Historical FS'!J28,0) -> 0.21153752 | K14: =IFERROR('Historical FS'!K28,0) -> 0.15004224 | ... M14: =IFERROR('Historical FS'!M28,0) -> 0.13201623 | O14: =IFERROR(AVERAGE(D14:M14),0) -> 0.1986715 | P14: =IFERROR(MEDIAN(D14:M14),0) -> 0.21394709
B15: Net Profit Margin | D15: =IFERROR('Historical FS'!D34,0) -> 0.110375 | E15: =IFERROR('Historical FS'!E34,0) -> 0.12551403 | F15: =IFERROR('Historical FS'!F34,0) -> 0.16405526 | G15: =IFERROR('Historical FS'!G34,0) -> 0.15165927 | H15: =IFERROR('Historical FS'!H34,0) -> 0.16827221 | I15: =IFERROR('Historical FS'!I34,0) -> 0.17166505 | J15: =IFERROR('Historical FS'!J34,0) -> 0.14749988 | K15: =IFERROR('Historical FS'!K34,0) -> 0.11162592 | ... M15: =IFERROR('Historical FS'!M34,0) -> 0.097956731 | O15: =IFERROR(AVERAGE(D15:M15),0) -> 0.13474384 | P15: =IFERROR(MEDIAN(D15:M15),0) -> 0.13650695
B17: SalesExpenses%Sales | D17: =IFERROR('Historical FS'!D15,0) -> 0.2257135 | E17: =IFERROR('Historical FS'!E15,0) -> 0.22226098 | F17: =IFERROR('Historical FS'!F15,0) -> 0.16133568 | G17: =IFERROR('Historical FS'!G15,0) -> 0.15821488 | H17: =IFERROR('Historical FS'!H15,0) -> 0.22108569 | I17: =IFERROR('Historical FS'!I15,0) -> 0.21915049 | J17: =IFERROR('Historical FS'!J15,0) -> 0.26276927 | K17: =IFERROR('Historical FS'!K15,0) -> 0.26337517 | ... M17: =IFERROR('Historical FS'!M15,0) -> 0.33487079 | O17: =IFERROR(AVERAGE(D17:M17),0) -> 0.23496055 | P17: =IFERROR(MEDIAN(D17:M17),0) -> 0.22398724
B18: Depreciation%Sales | D18: =IFERROR('Historical FS'!D25,0) -> 0.03499695 | E18: =IFERROR('Historical FS'!E25,0) -> 0.03163093 | F18: =IFERROR('Historical FS'!F25,0) -> 0.02938995 | G18: =IFERROR('Historical FS'!G25,0) -> 0.026366957 | H18: =IFERROR('Historical FS'!H25,0) -> 0.045854205 | I18: =IFERROR('Historical FS'!I25,0) -> 0.046032525 | J18: =IFERROR('Historical FS'!J25,0) -> 0.051467835 | K18: =IFERROR('Historical FS'!K25,0) -> 0.077703556 | ... M18: =IFERROR('Historical FS'!M25,0) -> 0.081640625 | O18: =IFERROR(AVERAGE(D18:M18),0) -> 0.050330595 | P18: =IFERROR(MEDIAN(D18:M18),0) -> 0.045943365
B19: OperatingIncome%Sales | D19: =D13 -> 0.2095821 | E19: =E13 -> 0.22574901 | F19: =F13 -> 0.24962915 | G19: =G13 -> 0.23975932 | H19: =H13 -> 0.23112761 | I19: =I13 -> 0.24434113 | J19: =J13 -> 0.23190648 | K19: =K13 -> 0.17778107 | ... M19: =M13 -> 0.14596605 | O19: =IFERROR(AVERAGE(D19:M19),0) -> 0.21160294 | P19: =IFERROR(MEDIAN(D19:M19),0) -> 0.22843831
B21: Return on Capital Employed | D21: =IFERROR(('Historical FS'!D17-'Historical FS'!D24)/SUM('Historical FS'!D48:D50),0) -> 0.35159833 | E21: =IFERROR(('Historical FS'!E17-'Historical FS'!E24)/SUM('Historical FS'!E48:E50),0) -> 0.37941993 | F21: =IFERROR(('Historical FS'!F17-'Historical FS'!F24)/SUM('Historical FS'!F48:F50),0) -> 0.38881802 | G21: =IFERROR(('Historical FS'!G17-'Historical FS'!G24)/SUM('Historical FS'!G48:G50),0) -> 0.41827099 | H21: =IFERROR(('Historical FS'!H17-'Historical FS'!H24)/SUM('Historical FS'!H48:H50),0) -> 0.33537784 | I21: =IFERROR(('Historical FS'!I17-'Historical FS'!I24)/SUM('Historical FS'!I48:I50),0) -> 0.29778842 | J21: =IFERROR(('Historical FS'!J17-'Historical FS'!J24)/SUM('Historical FS'!J48:J50),0) -> 0.22523028 | K21: =IFERROR(('Historical FS'!K17-'Historical FS'!K24)/SUM('Historical FS'!K48:K50),0) -> 0.16270395 | ... M21: =IFERROR(('Historical FS'!M17-'Historical FS'!M24)/SUM('Historical FS'!M48:M50),0) -> 0.12657807 | O21: =IFERROR(AVERAGE(D21:M21),0) -> 0.28353814 | P21: =IFERROR(MEDIAN(D21:M21),0) -> 0.31658313
B22: Retained Earnings% | D22: =IFERROR('Historical FS'!D44,0) -> 0 | E22: =IFERROR('Historical FS'!E44,0) -> 0.26897762 | F22: =IFERROR('Historical FS'!F44,0) -> 1 | G22: =IFERROR('Historical FS'!G44,0) -> 0.4233368 | H22: =IFERROR('Historical FS'!H44,0) -> 0.7188259 | I22: =IFERROR('Historical FS'!I44,0) -> 0.76138221 | J22: =IFERROR('Historical FS'!J44,0) -> 0.77414726 | K22: =IFERROR('Historical FS'!K44,0) -> 0.68042444 | ... M22: =IFERROR('Historical FS'!M44,0) -> 1 | O22: =IFERROR(AVERAGE(D22:M22),0) -> 0.64553161 | P22: =IFERROR(MEDIAN(D22:M22),0) -> 0.74010405
B23: Return on Equity% | D23: =IFERROR('Historical FS'!D33/SUM('Historical FS'!D48:D49),0) -> 0.18828932 | E23: =IFERROR('Historical FS'!E33/SUM('Historical FS'!E48:E49),0) -> 0.21156048 | F23: =IFERROR('Historical FS'!F33/SUM('Historical FS'!F48:F49),0) -> 0.25597936 | G23: =IFERROR('Historical FS'!G33/SUM('Historical FS'!G48:G49),0) -> 0.27581593 | H23: =IFERROR('Historical FS'!H33/SUM('Historical FS'!H48:H49),0) -> 0.27528176 | I23: =IFERROR('Historical FS'!I33/SUM('Historical FS'!I48:I49),0) -> 0.24245684 | J23: =IFERROR('Historical FS'!J33/SUM('Historical FS'!J48:J49),0) -> 0.20444826 | K23: =IFERROR('Historical FS'!K33/SUM('Historical FS'!K48:K49),0) -> 0.12969653 | ... M23: =IFERROR('Historical FS'!M33/SUM('Historical FS'!M48:M49),0) -> 0.097973658 | O23: =IFERROR(AVERAGE(D23:M23),0) -> 0.19903731 | P23: =IFERROR(MEDIAN(D23:M23),0) -> 0.20800437
B24: Self Sustained Growth Rate | D24: =IFERROR(D22*D23,0) -> 0 | E24: =IFERROR(E22*E23,0) -> 0.056905035 | F24: =IFERROR(F22*F23,0) -> 0.25597936 | G24: =IFERROR(G22*G23,0) -> 0.11676303 | H24: =IFERROR(H22*H23,0) -> 0.19787966 | I24: =IFERROR(I22*I23,0) -> 0.18460232 | J24: =IFERROR(J22*J23,0) -> 0.15827306 | K24: =IFERROR(K22*K23,0) -> 0.088248687 | ... M24: =IFERROR(M22*M23,0) -> 0.097973658 | O24: =IFERROR(AVERAGE(D24:M24),0) -> 0.12467941 | P24: =IFERROR(MEDIAN(D24:M24),0) -> 0.10736835
B25: Interest Coverage Ratio | D25: =IFERROR(('Historical FS'!D17-'Historical FS'!D24)/'Historical FS'!D21,0) -> 62.28125 | E25: =IFERROR(('Historical FS'!E17-'Historical FS'!E24)/'Historical FS'!E21,0) -> 63.386598 | F25: =IFERROR(('Historical FS'!F17-'Historical FS'!F24)/'Historical FS'!F21,0) -> 45.635593 | G25: =IFERROR(('Historical FS'!G17-'Historical FS'!G24)/'Historical FS'!G21,0) -> 44.296117 | H25: =IFERROR(('Historical FS'!H17-'Historical FS'!H24)/'Historical FS'!H21,0) -> 15.647431 | I25: =IFERROR(('Historical FS'!I17-'Historical FS'!I24)/'Historical FS'!I21,0) -> 21.094291 | J25: =IFERROR(('Historical FS'!J17-'Historical FS'!J24)/'Historical FS'!J21,0) -> 11.385292 | K25: =IFERROR(('Historical FS'!K17-'Historical FS'!K24)/'Historical FS'!K21,0) -> 6.4091052 | ... M25: =IFERROR(('Historical FS'!M17-'Historical FS'!M24)/'Historical FS'!M21,0) -> 10.463651 | O25: =IFERROR(AVERAGE(D25:M25),0) -> 28.753586 | P25: =IFERROR(MEDIAN(D25:M25),0) -> 18.370861
B27: Debtor Turnover Ratio | D27: =IFERROR('Historical FS'!D5/'Historical FS'!D60,0) -> 6.7730769 | E27: =IFERROR('Historical FS'!E5/'Historical FS'!E60,0) -> 6.7844065 | F27: =IFERROR('Historical FS'!F5/'Historical FS'!F60,0) -> 6.4278903 | G27: =IFERROR('Historical FS'!G5/'Historical FS'!G60,0) -> 5.5621483 | H27: =IFERROR('Historical FS'!H5/'Historical FS'!H60,0) -> 6.6776608 | I27: =IFERROR('Historical FS'!I5/'Historical FS'!I60,0) -> 8.1150594 | J27: =IFERROR('Historical FS'!J5/'Historical FS'!J60,0) -> 9.0659089 | K27: =IFERROR('Historical FS'!K5/'Historical FS'!K60,0) -> 9.4200509 | ... M27: =IFERROR('Historical FS'!M5/'Historical FS'!M60,0) -> 8.9976343 | O27: =IFERROR(AVERAGE(D27:M27),0) -> 7.7387584 | P27: =IFERROR(MEDIAN(D27:M27),0) -> 7.4497329
B28: Creditor Turnover Ratio | D28: =IFERROR('Historical FS'!D5/'Historical FS'!D51,0) -> 4.4337001 | E28: =IFERROR('Historical FS'!E5/'Historical FS'!E51,0) -> 2.9031605 | F28: =IFERROR('Historical FS'!F5/'Historical FS'!F51,0) -> 5.8619565 | G28: =IFERROR('Historical FS'!G5/'Historical FS'!G51,0) -> 6.7111621 | H28: =IFERROR('Historical FS'!H5/'Historical FS'!H51,0) -> 5.3425452 | I28: =IFERROR('Historical FS'!I5/'Historical FS'!I51,0) -> 5.501902 | J28: =IFERROR('Historical FS'!J5/'Historical FS'!J51,0) -> 4.8027057 | K28: =IFERROR('Historical FS'!K5/'Historical FS'!K51,0) -> 4.7820166 | ... M28: =IFERROR('Historical FS'!M5/'Historical FS'!M51,0) -> 4.0067421 | O28: =IFERROR(AVERAGE(D28:M28),0) -> 4.9096727 | P28: =IFERROR(MEDIAN(D28:M28),0) -> 4.7923611
