Workbook
Name UPDATE: 'Data Sheet'!$E$1

Sheet Profit & Loss
A1: ='Data Sheet'!B1 -> SUN PHARMACEUTICAL INDUSTRIES LTD | H1: =UPDATE
A3: Narration | B3: ='Data Sheet'!B16 -> 42460 | C3: ='Data Sheet'!C16 -> 42825 | D3: ='Data Sheet'!D16 -> 43190 | E3: ='Data Sheet'!E16 -> 43555 | F3: ='Data Sheet'!F16 -> 43921 | G3: ='Data Sheet'!G16 -> 44286 | H3: ='Data Sheet'!H16 -> 44651 | I3: ='Data Sheet'!I16 -> 45016 | ... K3: ='Data Sheet'!K16 -> 45747 | L3: Trailing | M3: Best Case | N3: Worst Case
A4: Sales | B4: ='Data Sheet'!B17 -> 28487.03 | C4: ='Data Sheet'!C17 -> 31578.44 | D4: ='Data Sheet'!D17 -> 26489.46 | E4: ='Data Sheet'!E17 -> 29065.91 | F4: ='Data Sheet'!F17 -> 32837.5 | G4: ='Data Sheet'!G17 -> 33498.14 | H4: ='Data Sheet'!H17 -> 38654.49 | I4: ='Data Sheet'!I17 -> 43885.68 | ... K4: ='Data Sheet'!K17 -> 52578.44 | L4: =SUM(Quarters!H4:K4) -> 52578.44 | M4: =$K4+M23*K4 -> 58256.396 | N4: =$K4+N23*L4 -> 56283.499
A5: Expenses | B5: =SUM('Data Sheet'!B18,'Data Sheet'!B20:B24, -1*'Data Sheet'!B19) -> 20313.13 | C5: =SUM('Data Sheet'!C18,'Data Sheet'!C20:C24, -1*'Data Sheet'!C19) -> 21476.42 | D5: =SUM('Data Sheet'!D18,'Data Sheet'!D20:D24, -1*'Data Sheet'!D19) -> 20858.04 | E5: =SUM('Data Sheet'!E18,'Data Sheet'!E20:E24, -1*'Data Sheet'!E19) -> 22688.93 | F5: =SUM('Data Sheet'!F18,'Data Sheet'!F20:F24, -1*'Data Sheet'!F19) -> 25854.66 | G5: =SUM('Data Sheet'!G18,'Data Sheet'!G20:G24, -1*'Data Sheet'!G19) -> 25028.18 | H5: =SUM('Data Sheet'!H18,'Data Sheet'!H20:H24, -1*'Data Sheet'!H19) -> 28396.92 | I5: =SUM('Data Sheet'!I18,'Data Sheet'!I20:I24, -1*'Data Sheet'!I19) -> 32235.24 | ... K5: =SUM('Data Sheet'!K18,'Data Sheet'!K20:K24, -1*'Data Sheet'!K19) -> 37306.75 | L5: =SUM(Quarters!H5:K5) -> 37306.75 | M5: =M4-M6 -> 41335.513 | N5: =N4-N6 -> 41754.114
A6: Operating Profit | B6: =B4-B5 -> 8173.9 | C6: =C4-C5 -> 10102.02 | D6: =D4-D5 -> 5631.42 | E6: =E4-E5 -> 6376.98 | F6: =F4-F5 -> 6982.84 | G6: =G4-G5 -> 8469.96 | H6: =H4-H5 -> 10257.57 | I6: =I4-I5 -> 11650.44 | ... K6: =K4-K5 -> 15271.69 | L6: =SUM(Quarters!H6:K6) -> 15271.69 | M6: =M4*M24 -> 16920.883 | N6: =N4*N24 -> 14529.385
A7: Other Income | B7: ='Data Sheet'!B25 -> -42.5 | C7: ='Data Sheet'!C25 -> 610.4 | D7: ='Data Sheet'!D25 -> -135.03 | E7: ='Data Sheet'!E25 -> -258.28 | F7: ='Data Sheet'!F25 -> 382.26 | G7: ='Data Sheet'!G25 -> -3449.21 | H7: ='Data Sheet'!H25 -> -3505.16 | I7: ='Data Sheet'!I25 -> 459.42 | ... K7: ='Data Sheet'!K25 -> 1287.19 | L7: =SUM(Quarters!H7:K7) -> 1287.19 | M7: 0 | N7: 0
A8: Depreciation | B8: ='Data Sheet'!B26 -> 1037.53 | C8: ='Data Sheet'!C26 -> 1264.75 | D8: ='Data Sheet'!D26 -> 1499.84 | E8: ='Data Sheet'!E26 -> 1753.25 | F8: ='Data Sheet'!F26 -> 2052.78 | G8: ='Data Sheet'!G26 -> 2079.95 | H8: ='Data Sheet'!H26 -> 2143.74 | I8: ='Data Sheet'!I26 -> 2529.43 | ... K8: ='Data Sheet'!K26 -> 2575.39 | L8: =SUM(Quarters!H8:K8) -> 2575.39 | M8: =+$L8 -> 2575.39 | N8: =+$L8 -> 2575.39
A9: Interest | B9: ='Data Sheet'!B27 -> 523.24 | C9: ='Data Sheet'!C27 -> 399.8 | D9: ='Data Sheet'!D27 -> 517.57 | E9: ='Data Sheet'!E27 -> 555.25 | F9: ='Data Sheet'!F27 -> 302.73 | G9: ='Data Sheet'!G27 -> 141.43 | H9: ='Data Sheet'!H27 -> 127.35 | I9: ='Data Sheet'!I27 -> 172 | ... K9: ='Data Sheet'!K27 -> 231.36 | L9: =SUM(Quarters!H9:K9) -> 231.36 | M9: =+$L9 -> 231.36 | N9: =+$L9 -> 231.36
A10: Profit before tax | B10: ='Data Sheet'!B28 -> 6570.63 | C10: ='Data Sheet'!C28 -> 9047.87 | D10: ='Data Sheet'!D28 -> 3478.98 | E10: ='Data Sheet'!E28 -> 3810.2 | F10: ='Data Sheet'!F28 -> 5009.59 | G10: ='Data Sheet'!G28 -> 2799.37 | H10: ='Data Sheet'!H28 -> 4481.32 | I10: ='Data Sheet'!I28 -> 9408.43 | ... K10: ='Data Sheet'!K28 -> 13752.13 | L10: =SUM(Quarters!H10:K10) -> 13752.13 | M10: =M6+M7-SUM(M8:M9) -> 14114.133 | N10: =N6+N7-SUM(N8:N9) -> 11722.635
A11: Tax | B11: ='Data Sheet'!B29 -> 913.77 | C11: ='Data Sheet'!C29 -> 1211.57 | D11: ='Data Sheet'!D29 -> 911.04 | E11: ='Data Sheet'!E29 -> 600.88 | F11: ='Data Sheet'!F29 -> 822.8 | G11: ='Data Sheet'!G29 -> 514.69 | H11: ='Data Sheet'!H29 -> 1075.5 | I11: ='Data Sheet'!I29 -> 847.59 | ... K11: ='Data Sheet'!K29 -> 2772.03 | L11: =SUM(Quarters!H11:K11) -> 2772.03 | M11: =IF($L10>0,$L11/$L10,0) -> 0.20157096 | N11: =IF($L10>0,$L11/$L10,0) -> 0.20157096
A12: Net profit | B12: ='Data Sheet'!B30 -> 4545.71 | C12: ='Data Sheet'!C30 -> 6964.37 | D12: ='Data Sheet'!D30 -> 2095.7 | E12: ='Data Sheet'!E30 -> 2665.42 | F12: ='Data Sheet'!F30 -> 3764.93 | G12: ='Data Sheet'!G30 -> 2903.82 | H12: ='Data Sheet'!H30 -> 3272.73 | I12: ='Data Sheet'!I30 -> 8473.58 | ... K12: ='Data Sheet'!K30 -> 10929.04 | L12: =SUM(Quarters!H12:K12) -> 10929.04 | M12: =M10-M11*M10 -> 11269.134 | N12: =N10-N11*N10 -> 9359.6925
A13: EPS | B13: =IF('Data Sheet'!B93>0,B12/'Data Sheet'!B93,0) -> 18.88773 | C13: =IF('Data Sheet'!C93>0,C12/'Data Sheet'!C93,0) -> 29.026674 | D13: =IF('Data Sheet'!D93>0,D12/'Data Sheet'!D93,0) -> 8.7346309 | E13: =IF('Data Sheet'!E93>0,E12/'Data Sheet'!E93,0) -> 11.109157 | F13: =IF('Data Sheet'!F93>0,F12/'Data Sheet'!F93,0) -> 15.691785 | G13: =IF('Data Sheet'!G93>0,G12/'Data Sheet'!G93,0) -> 12.10278 | H13: =IF('Data Sheet'!H93>0,H12/'Data Sheet'!H93,0) -> 13.640353 | I13: =IF('Data Sheet'!I93>0,I12/'Data Sheet'!I93,0) -> 35.316884 | ... K13: =IF('Data Sheet'!K93>0,K12/'Data Sheet'!K93,0) -> 45.550952 | L13: =IF('Data Sheet'!$B6>0,'Profit & Loss'!L12/'Data Sheet'!$B6,0) -> 45.557046 | M13: =IF('Data Sheet'!$B6>0,'Profit & Loss'!M12/'Data Sheet'!$B6,0) -> 46.974705 | N13: =IF('Data Sheet'!$B6>0,'Profit & Loss'!N12/'Data Sheet'!$B6,0) -> 39.015315
A14: Price to earning | B14: =IF(B15>0,B15/B13,"") -> 43.414428 | C14: =IF(C15>0,C15/C13,"") -> 23.707504 | D14: =IF(D15>0,D15/D13,"") -> 56.682418 | E14: =IF(E15>0,E15/E13,"") -> 43.104081 | F14: =IF(F15>0,F15/F13,"") -> 22.451238 | G14: =IF(G15>0,G15/G13,"") -> 49.39361 | H14: =IF(H15>0,H15/H13,"") -> 67.062045 | I14: =IF(I15>0,I15/I13,"") -> 27.836544 | ... K14: =IF(K15>0,K15/K13,"") -> 38.082629 | L14: =IF(L13>0,L15/L13,0) -> 36.222718 | M14: =M25 -> 36.222718 | N14: =N25 -> 35.68593
A15: Price | B15: ='Data Sheet'!B90 -> 820 | C15: ='Data Sheet'!C90 -> 688.15 | D15: ='Data Sheet'!D90 -> 495.1 | E15: ='Data Sheet'!E90 -> 478.85 | F15: ='Data Sheet'!F90 -> 352.3 | G15: ='Data Sheet'!G90 -> 597.8 | H15: ='Data Sheet'!H90 -> 914.75 | I15: ='Data Sheet'!I90 -> 983.1 | ... K15: ='Data Sheet'!K90 -> 1734.7 | L15: ='Data Sheet'!B8 -> 1650.2 | M15: =M13*M14 -> 1701.5515 | N15: =N13*N14 -> 1392.2978
A17: RATIOS:
A18: Dividend Payout | B18: =IF('Data Sheet'!B30>0, 'Data Sheet'!B31/'Data Sheet'!B30, 0) -> 0.052942225 | C18: =IF('Data Sheet'!C30>0, 'Data Sheet'!C31/'Data Sheet'!C30, 0) -> 0.12057946 | D18: =IF('Data Sheet'!D30>0, 'Data Sheet'!D31/'Data Sheet'!D30, 0) -> 0.22897361 | E18: =IF('Data Sheet'!E30>0, 'Data Sheet'!E31/'Data Sheet'!E30, 0) -> 0.24754448 | F18: =IF('Data Sheet'!F30>0, 'Data Sheet'!F31/'Data Sheet'!F30, 0) -> 0.25491045 | G18: =IF('Data Sheet'!G30>0, 'Data Sheet'!G31/'Data Sheet'!G30, 0) -> 0.61969406 | H18: =IF('Data Sheet'!H30>0, 'Data Sheet'!H31/'Data Sheet'!H30, 0) -> 0.73311883 | I18: =IF('Data Sheet'!I30>0, 'Data Sheet'!I31/'Data Sheet'!I30, 0) -> 0.32562388 | ... K18: =IF('Data Sheet'!K30>0, 'Data Sheet'!K31/'Data Sheet'!K30, 0) -> 0.35125501
A19: Operating Profit Margin (OPM) | B19: =IF(B6>0,B6/B4,0) -> 0.28693409 | C19: =IF(C6>0,C6/C4,0) -> 0.31990244 | D19: =IF(D6>0,D6/D4,0) -> 0.21259097 | E19: =IF(E6>0,E6/E4,0) -> 0.21939723 | F19: =IF(F6>0,F6/F4,0) -> 0.21264834 | G19: =IF(G6>0,G6/G4,0) -> 0.25284867 | H19: =IF(H6>0,H6/H4,0) -> 0.26536555 | I19: =IF(I6>0,I6/I4,0) -> 0.26547247 | ... L19: =IF(L6>0,L6/L4,0) -> 0.29045537
G22: TRENDS: | H22: 10 YEARS | I22: 7 YEARS | J22: 5 YEARS | K22: 3 YEARS | L22: RECENT | M22: BEST | N22: WORST
G23: Sales Growth | H23: =IF(B4=0,"",POWER($K4/B4,1/9)-1) -> 0.070467266 | I23: =IF(D4=0,"",POWER($K4/D4,1/7)-1) -> 0.10289334 | J23: =IF(F4=0,"",POWER($K4/F4,1/5)-1) -> 0.098721245 | K23: =IF(H4=0,"",POWER($K4/H4, 1/3)-1) -> 0.10799019 | L23: =IF(ISERROR(MAX(IF(J4=0,"",(K4-J4)/J4),IF(K4=0,"",(L4-K4)/K4))),"",MAX(IF(J4=0,"",(K4-J4)/J4),IF(K4=0,"",(L4-K4)/K4))) -> 0.084161961 | M23: =MAX(K23:L23) -> 0.10799019 | N23: =MIN(H23:L23) -> 0.070467266
G24: OPM | H24: =IF(SUM(B4:$K$4)=0,"",SUMPRODUCT(B19:$K$19,B4:$K$4)/SUM(B4:$K$4)) -> 0.26242329 | I24: =IF(SUM(E4:$K$4)=0,"",SUMPRODUCT(E19:$K$19,E4:$K$4)/SUM(E4:$K$4)) -> 0.25814645 | J24: =IF(SUM(G4:$K$4)=0,"",SUMPRODUCT(G19:$K$19,G4:$K$4)/SUM(G4:$K$4)) -> 0.27021536 | K24: =IF(SUM(I4:$K$4)=0, "", SUMPRODUCT(I19:$K$19,I4:$K$4)/SUM(I4:$K$4)) -> 0.27552175 | L24: =L19 -> 0.29045537 | M24: =MAX(K24:L24) -> 0.29045537 | N24: =MIN(H24:L24) -> 0.25814645
G25: Price to Earning | H25: =IF(ISERROR(AVERAGEIF(B14:$L14,">0")),"",AVERAGEIF(B14:$L14,">0")) -> 40.778095 | I25: =IF(ISERROR(AVERAGEIF(E14:$L14,">0")),"",AVERAGEIF(E14:$L14,">0")) -> 40.594337 | J25: =IF(ISERROR(AVERAGEIF(G14:$L14,">0")),"",AVERAGEIF(G14:$L14,">0")) -> 43.199896 | K25: =IF(ISERROR(AVERAGEIF(I14:$L14,">0")),"",AVERAGEIF(I14:$L14,">0")) -> 35.68593 | L25: =L14 -> 36.222718 | M25: =MAX(K25:L25) -> 36.222718 | N25: =MIN(H25:L25) -> 35.68593

Sheet Quarters
A1: ='Profit & Loss'!A1 -> SUN PHARMACEUTICAL INDUSTRIES LTD | E1: =UPDATE
A3: Narration | B3: ='Data Sheet'!B41 -> 44926 | C3: ='Data Sheet'!C41 -> 45016 | D3: ='Data Sheet'!D41 -> 45107 | E3: ='Data Sheet'!E41 -> 45199 | F3: ='Data Sheet'!F41 -> 45291 | G3: ='Data Sheet'!G41 -> 45382 | H3: ='Data Sheet'!H41 -> 45473 | I3: ='Data Sheet'!I41 -> 45565 | ... K3: ='Data Sheet'!K41 -> 45747
A4: Sales | B4: ='Data Sheet'!B42 -> 11240.97 | C4: ='Data Sheet'!C42 -> 10930.67 | D4: ='Data Sheet'!D42 -> 11940.84 | E4: ='Data Sheet'!E42 -> 12192.41 | F4: ='Data Sheet'!F42 -> 12380.7 | G4: ='Data Sheet'!G42 -> 11982.9 | H4: ='Data Sheet'!H42 -> 12652.75 | I4: ='Data Sheet'!I42 -> 13291.39 | ... K4: ='Data Sheet'!K42 -> 12958.84
A5: Expenses | B5: ='Data Sheet'!B43 -> 8237.25 | C5: ='Data Sheet'!C43 -> 8128.54 | D5: ='Data Sheet'!D43 -> 8609.07 | E5: ='Data Sheet'!E43 -> 9013.03 | F5: ='Data Sheet'!F43 -> 8903.87 | G5: ='Data Sheet'!G43 -> 8947.75 | H5: ='Data Sheet'!H43 -> 9045.13 | I5: ='Data Sheet'!I43 -> 9352.43 | ... K5: ='Data Sheet'!K43 -> 9242.75
A6: Operating Profit | B6: ='Data Sheet'!B50 -> 3003.72 | C6: ='Data Sheet'!C50 -> 2802.13 | D6: ='Data Sheet'!D50 -> 3331.77 | E6: ='Data Sheet'!E50 -> 3179.38 | F6: ='Data Sheet'!F50 -> 3476.83 | G6: ='Data Sheet'!G50 -> 3035.15 | H6: ='Data Sheet'!H50 -> 3607.62 | I6: ='Data Sheet'!I50 -> 3938.96 | ... K6: ='Data Sheet'!K50 -> 3716.09
A7: Other Income | B7: ='Data Sheet'!B44 -> 173.88 | C7: ='Data Sheet'!C44 -> 201.83 | D7: ='Data Sheet'!D44 -> -118.43 | E7: ='Data Sheet'!E44 -> 293.61 | F7: ='Data Sheet'!F44 -> 180.39 | G7: ='Data Sheet'!G44 -> 504.3 | H7: ='Data Sheet'!H44 -> 532.55 | I7: ='Data Sheet'!I44 -> 354 | ... K7: ='Data Sheet'!K44 -> 251.19
A8: Depreciation | B8: ='Data Sheet'!B45 -> 659.95 | C8: ='Data Sheet'!C45 -> 671.53 | D8: ='Data Sheet'!D45 -> 651.32 | E8: ='Data Sheet'!E45 -> 632.82 | F8: ='Data Sheet'!F45 -> 622.14 | G8: ='Data Sheet'!G45 -> 650.36 | H8: ='Data Sheet'!H45 -> 655.13 | I8: ='Data Sheet'!I45 -> 625.91 | ... K8: ='Data Sheet'!K45 -> 663.79
A9: Interest | B9: ='Data Sheet'!B46 -> 46.18 | C9: ='Data Sheet'!C46 -> 92.74 | D9: ='Data Sheet'!D46 -> 80.88 | E9: ='Data Sheet'!E46 -> 49.29 | F9: ='Data Sheet'!F46 -> 34.73 | G9: ='Data Sheet'!G46 -> 73.57 | H9: ='Data Sheet'!H46 -> 61.54 | I9: ='Data Sheet'!I46 -> 69.17 | ... K9: ='Data Sheet'!K46 -> 49.14
A10: Profit before tax | B10: ='Data Sheet'!B47 -> 2471.47 | C10: ='Data Sheet'!C47 -> 2239.69 | D10: ='Data Sheet'!D47 -> 2481.14 | E10: ='Data Sheet'!E47 -> 2790.88 | F10: ='Data Sheet'!F47 -> 3000.35 | G10: ='Data Sheet'!G47 -> 2815.52 | H10: ='Data Sheet'!H47 -> 3423.5 | I10: ='Data Sheet'!I47 -> 3597.88 | ... K10: ='Data Sheet'!K47 -> 3254.35
A11: Tax | B11: ='Data Sheet'!B48 -> 283.43 | C11: ='Data Sheet'!C48 -> 222.91 | D11: ='Data Sheet'!D48 -> 468.1 | E11: ='Data Sheet'!E48 -> 390.1 | F11: ='Data Sheet'!F48 -> 432.32 | G11: ='Data Sheet'!G48 -> 148.93 | H11: ='Data Sheet'!H48 -> 552.25 | I11: ='Data Sheet'!I48 -> 567.21 | ... K11: ='Data Sheet'!K48 -> 1093.71
A12: Net profit | B12: ='Data Sheet'!B49 -> 2166.01 | C12: ='Data Sheet'!C49 -> 1984.47 | D12: ='Data Sheet'!D49 -> 2022.54 | E12: ='Data Sheet'!E49 -> 2375.51 | F12: ='Data Sheet'!F49 -> 2523.75 | G12: ='Data Sheet'!G49 -> 2654.58 | H12: ='Data Sheet'!H49 -> 2835.62 | I12: ='Data Sheet'!I49 -> 3040.16 | ... K12: ='Data Sheet'!K49 -> 2149.88
A14: Operating Profit Margin | B14: =IF(B4>0,B6/B4,"") -> 0.26721182 | C14: =IF(C4>0,C6/C4,"") -> 0.25635483 | D14: =IF(D4>0,D6/D4,"") -> 0.27902308 | E14: =IF(E4>0,E6/E4,"") -> 0.26076715 | F14: =IF(F4>0,F6/F4,"") -> 0.28082661 | G14: =IF(G4>0,G6/G4,"") -> 0.25329011 | H14: =IF(H4>0,H6/H4,"") -> 0.28512537 | I14: =IF(I4>0,I6/I4,"") -> 0.29635426 | ... K14: =IF(K4>0,K6/K4,"") -> 0.28676101

Sheet Balance Sheet
A1: ='Profit & Loss'!A1 -> SUN PHARMACEUTICAL INDUSTRIES LTD | E1: =UPDATE
A3: Narration | B3: ='Data Sheet'!B56 -> 42460 | C3: ='Data Sheet'!C56 -> 42825 | D3: ='Data Sheet'!D56 -> 43190 | E3: ='Data Sheet'!E56 -> 43555 | F3: ='Data Sheet'!F56 -> 43921 | G3: ='Data Sheet'!G56 -> 44286 | H3: ='Data Sheet'!H56 -> 44651 | I3: ='Data Sheet'!I56 -> 45016 | ... K3: ='Data Sheet'!K56 -> 45747
A4: Equity Share Capital | B4: ='Data Sheet'!B57 -> 240.66 | C4: ='Data Sheet'!C57 -> 239.93 | D4: ='Data Sheet'!D57 -> 239.93 | E4: ='Data Sheet'!E57 -> 239.93 | F4: ='Data Sheet'!F57 -> 239.93 | G4: ='Data Sheet'!G57 -> 239.93 | H4: ='Data Sheet'!H57 -> 239.93 | I4: ='Data Sheet'!I57 -> 239.93 | ... K4: ='Data Sheet'!K57 -> 239.93
A5: Reserves | B5: ='Data Sheet'!B58 -> 32741.82 | C5: ='Data Sheet'!C58 -> 36399.74 | D5: ='Data Sheet'!D58 -> 38074.18 | E5: ='Data Sheet'!E58 -> 41169.13 | F5: ='Data Sheet'!F58 -> 45024.52 | G5: ='Data Sheet'!G58 -> 46222.85 | H5: ='Data Sheet'!H58 -> 47771.29 | I5: ='Data Sheet'!I58 -> 55755.45 | ... K5: ='Data Sheet'!K58 -> 71978.09
A6: Borrowings | B6: ='Data Sheet'!B59 -> 8496.76 | C6: ='Data Sheet'!C59 -> 9831.77 | D6: ='Data Sheet'!D59 -> 10385.27 | E6: ='Data Sheet'!E59 -> 10514.36 | F6: ='Data Sheet'!F59 -> 8314.88 | G6: ='Data Sheet'!G59 -> 3868.58 | H6: ='Data Sheet'!H59 -> 1290.3 | I6: ='Data Sheet'!I59 -> 6885.87 | ... K6: ='Data Sheet'!K59 -> 2362.19
A7: Other Liabilities | B7: ='Data Sheet'!B60 -> 13948.26 | C7: ='Data Sheet'!C60 -> 14624.01 | D7: ='Data Sheet'!D60 -> 15598.01 | E7: ='Data Sheet'!E60 -> 12666.11 | F7: ='Data Sheet'!F60 -> 14614.99 | G7: ='Data Sheet'!G60 -> 17290.86 | H7: ='Data Sheet'!H60 -> 20474.39 | I7: ='Data Sheet'!I60 -> 17830.65 | ... K7: ='Data Sheet'!K60 -> 17520.37
A8: Total | B8: ='Data Sheet'!B61 -> 55427.5 | C8: ='Data Sheet'!C61 -> 61095.45 | D8: ='Data Sheet'!D61 -> 64297.39 | E8: ='Data Sheet'!E61 -> 64589.53 | F8: ='Data Sheet'!F61 -> 68194.32 | G8: ='Data Sheet'!G61 -> 67622.22 | H8: ='Data Sheet'!H61 -> 69775.91 | I8: ='Data Sheet'!I61 -> 80711.9 | ... K8: ='Data Sheet'!K61 -> 92100.58
A10: Net Block | B10: ='Data Sheet'!B62 -> 15872.25 | C10: ='Data Sheet'!C62 -> 17675.17 | D10: ='Data Sheet'!D62 -> 18852.65 | E10: ='Data Sheet'!E62 -> 21836.54 | F10: ='Data Sheet'!F62 -> 22846.91 | G10: ='Data Sheet'!G62 -> 21552.98 | H10: ='Data Sheet'!H62 -> 22665.16 | I10: ='Data Sheet'!I62 -> 24065.44 | ... K10: ='Data Sheet'!K62 -> 27995.9
A11: Capital Work in Progress | B11: ='Data Sheet'!B63 -> 2175.45 | C11: ='Data Sheet'!C63 -> 2801.38 | D11: ='Data Sheet'!D63 -> 2465.16 | E11: ='Data Sheet'!E63 -> 1411.15 | F11: ='Data Sheet'!F63 -> 1220.34 | G11: ='Data Sheet'!G63 -> 1566.83 | H11: ='Data Sheet'!H63 -> 1286.8 | I11: ='Data Sheet'!I63 -> 4973.16 | ... K11: ='Data Sheet'!K63 -> 1234.34
A12: Investments | B12: ='Data Sheet'!B64 -> 1829.88 | C12: ='Data Sheet'!C64 -> 1191.88 | D12: ='Data Sheet'!D64 -> 7142.87 | E12: ='Data Sheet'!E64 -> 7902.53 | F12: ='Data Sheet'!F64 -> 10143.11 | G12: ='Data Sheet'!G64 -> 9612.45 | H12: ='Data Sheet'!H64 -> 12848.59 | I12: ='Data Sheet'!I64 -> 14824.34 | ... K12: ='Data Sheet'!K64 -> 18353.8
A13: Other Assets | B13: ='Data Sheet'!B65 -> 35549.92 | C13: ='Data Sheet'!C65 -> 39427.02 | D13: ='Data Sheet'!D65 -> 35836.71 | E13: ='Data Sheet'!E65 -> 33439.31 | F13: ='Data Sheet'!F65 -> 33983.96 | G13: ='Data Sheet'!G65 -> 34889.96 | H13: ='Data Sheet'!H65 -> 32975.36 | I13: ='Data Sheet'!I65 -> 36848.96 | ... K13: ='Data Sheet'!K65 -> 44516.54
A14: Total | B14: ='Data Sheet'!B66 -> 55427.5 | C14: ='Data Sheet'!C66 -> 61095.45 | D14: ='Data Sheet'!D66 -> 64297.39 | E14: ='Data Sheet'!E66 -> 64589.53 | F14: ='Data Sheet'!F66 -> 68194.32 | G14: ='Data Sheet'!G66 -> 67622.22 | H14: ='Data Sheet'!H66 -> 69775.91 | I14: ='Data Sheet'!I66 -> 80711.9 | ... K14: ='Data Sheet'!K66 -> 92100.58
A16: Working Capital | B16: =B13-B7 -> 21601.66 | C16: =C13-C7 -> 24803.01 | D16: =D13-D7 -> 20238.7 | E16: =E13-E7 -> 20773.2 | F16: =F13-F7 -> 19368.97 | G16: =G13-G7 -> 17599.1 | H16: =H13-H7 -> 12500.97 | I16: =I13-I7 -> 19018.31 | ... K16: =K13-K7 -> 26996.17
A17: Debtors | B17: ='Data Sheet'!B67 -> 6775.66 | C17: ='Data Sheet'!C67 -> 7202.61 | D17: ='Data Sheet'!D67 -> 7815.28 | E17: ='Data Sheet'!E67 -> 8884.2 | F17: ='Data Sheet'!F67 -> 9421.24 | G17: ='Data Sheet'!G67 -> 9061.4 | H17: ='Data Sheet'!H67 -> 10484.59 | I17: ='Data Sheet'!I67 -> 11438.51 | ... K17: ='Data Sheet'!K67 -> 13046.11
A18: Inventory | B18: ='Data Sheet'!B68 -> 6422.54 | C18: ='Data Sheet'!C68 -> 6832.81 | D18: ='Data Sheet'!D68 -> 6880.69 | E18: ='Data Sheet'!E68 -> 7885.98 | F18: ='Data Sheet'!F68 -> 7874.99 | G18: ='Data Sheet'!G68 -> 8997.02 | H18: ='Data Sheet'!H68 -> 8925.13 | I18: ='Data Sheet'!I68 -> 10513.05 | ... K18: ='Data Sheet'!K68 -> 10243.33
A20: Debtor Days | B20: =IF('Profit & Loss'!B4>0,'Balance Sheet'!B17/('Profit & Loss'!B4/365),0) -> 86.815505 | C20: =IF('Profit & Loss'!C4>0,'Balance Sheet'!C17/('Profit & Loss'!C4/365),0) -> 83.251505 | D20: =IF('Profit & Loss'!D4>0,'Balance Sheet'!D17/('Profit & Loss'!D4/365),0) -> 107.68725 | E20: =IF('Profit & Loss'!E4>0,'Balance Sheet'!E17/('Profit & Loss'!E4/365),0) -> 111.56482 | F20: =IF('Profit & Loss'!F4>0,'Balance Sheet'!F17/('Profit & Loss'!F4/365),0) -> 104.72029 | G20: =IF('Profit & Loss'!G4>0,'Balance Sheet'!G17/('Profit & Loss'!G4/365),0) -> 98.734169 | H20: =IF('Profit & Loss'!H4>0,'Balance Sheet'!H17/('Profit & Loss'!H4/365),0) -> 99.002091 | I20: =IF('Profit & Loss'!I4>0,'Balance Sheet'!I17/('Profit & Loss'!I4/365),0) -> 95.134817 | ... K20: =IF('Profit & Loss'!K4>0,'Balance Sheet'!K17/('Profit & Loss'!K4/365),0) -> 90.566212
A21: Inventory Turnover | B21: =IF('Balance Sheet'!B18>0,'Profit & Loss'!B4/'Balance Sheet'!B18,0) -> 4.4354772 | C21: =IF('Balance Sheet'!C18>0,'Profit & Loss'!C4/'Balance Sheet'!C18,0) -> 4.6215891 | D21: =IF('Balance Sheet'!D18>0,'Profit & Loss'!D4/'Balance Sheet'!D18,0) -> 3.8498261 | E21: =IF('Balance Sheet'!E18>0,'Profit & Loss'!E4/'Balance Sheet'!E18,0) -> 3.6857702 | F21: =IF('Balance Sheet'!F18>0,'Profit & Loss'!F4/'Balance Sheet'!F18,0) -> 4.1698466 | G21: =IF('Balance Sheet'!G18>0,'Profit & Loss'!G4/'Balance Sheet'!G18,0) -> 3.7232484 | H21: =IF('Balance Sheet'!H18>0,'Profit & Loss'!H4/'Balance Sheet'!H18,0) -> 4.3309722 | I21: =IF('Balance Sheet'!I18>0,'Profit & Loss'!I4/'Balance Sheet'!I18,0) -> 4.1744004 | ... K21: =IF('Balance Sheet'!K18>0,'Profit & Loss'!K4/'Balance Sheet'!K18,0) -> 5.1329441
A23: Return on Equity | B23: =IF(SUM('Balance Sheet'!B4:B5)>0,'Profit & Loss'!B12/SUM('Balance Sheet'!B4:B5),"") -> 0.13782196 | C23: =IF(SUM('Balance Sheet'!C4:C5)>0,'Profit & Loss'!C12/SUM('Balance Sheet'!C4:C5),"") -> 0.19007731 | D23: =IF(SUM('Balance Sheet'!D4:D5)>0,'Profit & Loss'!D12/SUM('Balance Sheet'!D4:D5),"") -> 0.054697865 | E23: =IF(SUM('Balance Sheet'!E4:E5)>0,'Profit & Loss'!E12/SUM('Balance Sheet'!E4:E5),"") -> 0.064368039 | F23: =IF(SUM('Balance Sheet'!F4:F5)>0,'Profit & Loss'!F12/SUM('Balance Sheet'!F4:F5),"") -> 0.083176312 | G23: =IF(SUM('Balance Sheet'!G4:G5)>0,'Profit & Loss'!G12/SUM('Balance Sheet'!G4:G5),"") -> 0.062497767 | H23: =IF(SUM('Balance Sheet'!H4:H5)>0,'Profit & Loss'!H12/SUM('Balance Sheet'!H4:H5),"") -> 0.068165941 | I23: =IF(SUM('Balance Sheet'!I4:I5)>0,'Profit & Loss'!I12/SUM('Balance Sheet'!I4:I5),"") -> 0.15132641 | ... K23: =IF(SUM('Balance Sheet'!K4:K5)>0,'Profit & Loss'!K12/SUM('Balance Sheet'!K4:K5),"") -> 0.15133397
A24: Return on Capital Emp | C24: =IF((B4+B5+B6+C4+C5+C6)>0,('Profit & Loss'!C10+'Profit & Loss'!C9)*2/(B4+B5+B6+C4+C5+C6),"") -> 0.21484018 | D24: =IF((C4+C5+C6+D4+D5+D6)>0,('Profit & Loss'!D10+'Profit & Loss'!D9)*2/(C4+C5+C6+D4+D5+D6),"") -> 0.083986877 | E24: =IF((D4+D5+D6+E4+E5+E6)>0,('Profit & Loss'!E10+'Profit & Loss'!E9)*2/(D4+D5+D6+E4+E5+E6),"") -> 0.086768605 | F24: =IF((E4+E5+E6+F4+F5+F6)>0,('Profit & Loss'!F10+'Profit & Loss'!F9)*2/(E4+E5+E6+F4+F5+F6),"") -> 0.10070486 | G24: =IF((F4+F5+F6+G4+G5+G6)>0,('Profit & Loss'!G10+'Profit & Loss'!G9)*2/(F4+F5+F6+G4+G5+G6),"") -> 0.056602454 | H24: =IF((G4+G5+G6+H4+H5+H6)>0,('Profit & Loss'!H10+'Profit & Loss'!H9)*2/(G4+G5+G6+H4+H5+H6),"") -> 0.092513034 | I24: =IF((H4+H5+H6+I4+I5+I6)>0,('Profit & Loss'!I10+'Profit & Loss'!I9)*2/(H4+H5+H6+I4+I5+I6),"") -> 0.17080038 | J24: =IF((I4+I5+I6+J4+J5+J6)>0,('Profit & Loss'!J10+'Profit & Loss'!J9)*2/(I4+I5+I6+J4+J5+J6),"") -> 0.17449105 | K24: =IF((J4+J5+J6+K4+K5+K6)>0,('Profit & Loss'!K10+'Profit & Loss'!K9)*2/(J4+J5+J6+K4+K5+K6),"") -> 0.19761769

Sheet Cash Flow
A1: ='Balance Sheet'!A1 -> SUN PHARMACEUTICAL INDUSTRIES LTD | E1: =UPDATE
A3: Narration | B3: ='Data Sheet'!B81 -> 42460 | C3: ='Data Sheet'!C81 -> 42825 | D3: ='Data Sheet'!D81 -> 43190 | E3: ='Data Sheet'!E81 -> 43555 | F3: ='Data Sheet'!F81 -> 43921 | G3: ='Data Sheet'!G81 -> 44286 | H3: ='Data Sheet'!H81 -> 44651 | I3: ='Data Sheet'!I81 -> 45016 | ... K3: ='Data Sheet'!K81 -> 45747
A4: Cash from Operating Activity | B4: ='Data Sheet'!B82 -> 6685.86 | C4: ='Data Sheet'!C82 -> 7082.21 | D4: ='Data Sheet'!D82 -> 3907.15 | E4: ='Data Sheet'!E82 -> 2196.45 | F4: ='Data Sheet'!F82 -> 6554.77 | G4: ='Data Sheet'!G82 -> 6170.37 | H4: ='Data Sheet'!H82 -> 8984.54 | I4: ='Data Sheet'!I82 -> 4959.33 | ... K4: ='Data Sheet'!K82 -> 14072.09
A5: Cash from Investing Activity | B5: ='Data Sheet'!B83 -> -3949.13 | C5: ='Data Sheet'!C83 -> -4186.15 | D5: ='Data Sheet'!D83 -> -3103.8 | E5: ='Data Sheet'!E83 -> -310.08 | F5: ='Data Sheet'!F83 -> -2225.32 | G5: ='Data Sheet'!G83 -> 406.53 | H5: ='Data Sheet'!H83 -> -5555.86 | I5: ='Data Sheet'!I83 -> -7219.92 | ... K5: ='Data Sheet'!K83 -> -5306.16
A6: Cash from Financing Activity | B6: ='Data Sheet'!B84 -> -1888.53 | C6: ='Data Sheet'!C84 -> -2285.39 | D6: ='Data Sheet'!D84 -> -1539.26 | E6: ='Data Sheet'!E84 -> -2730.52 | F6: ='Data Sheet'!F84 -> -5715.14 | G6: ='Data Sheet'!G84 -> -5980.48 | H6: ='Data Sheet'!H84 -> -5193.46 | I6: ='Data Sheet'!I84 -> 2376.07 | ... K6: ='Data Sheet'!K84 -> -7905.82
A7: Net Cash Flow | B7: ='Data Sheet'!B85 -> 848.2 | C7: ='Data Sheet'!C85 -> 610.67 | D7: ='Data Sheet'!D85 -> -735.91 | E7: ='Data Sheet'!E85 -> -844.15 | F7: ='Data Sheet'!F85 -> -1385.69 | G7: ='Data Sheet'!G85 -> 596.42 | H7: ='Data Sheet'!H85 -> -1764.78 | I7: ='Data Sheet'!I85 -> 115.48 | ... K7: ='Data Sheet'!K85 -> 860.11

Sheet Data>

Sheet Data Sheet
A1: COMPANY NAME | B1: SUN PHARMACEUTICAL INDUSTRIES LTD | E1: =IF(B2<>B3, "A NEW VERSION OF THE WORKSHEET IS AVAILABLE", "")
A2: LATEST VERSION | B2: 2.1
A3: CURRENT VERSION | B3: 2.1
A5: META
A6: Number of shares | B6: =IF(B9>0, B9/B8, 0) -> 239.89791
A7: Face Value | B7: 1
A8: Current Price | B8: 1650.2
A9: Market Capitalization | B9: 395879.53
A15: PROFIT & LOSS
A16: Report Date | B16: 42460 | C16: 42825 | D16: 43190 | E16: 43555 | F16: 43921 | G16: 44286 | H16: 44651 | I16: 45016 | J16: 45382 | K16: 45747
A17: Sales | B17: 28487.03 | C17: 31578.44 | D17: 26489.46 | E17: 29065.91 | F17: 32837.5 | G17: 33498.14 | H17: 38654.49 | I17: 43885.68 | J17: 48496.85 | K17: 52578.44
A18: Raw Material Cost | B18: 6724.15 | C18: 8402.37 | D18: 7193.98 | E18: 8302.08 | F18: 8929.6 | G18: 9328.3 | H18: 10459.15 | I18: 11349.07 | J18: 10370.48 | K18: 10597.05
A19: Change in Inventory | B19: 393.77 | C19: 271.63 | D19: -230.7 | E19: 433.11 | F19: -300.85 | G19: 638.22 | H19: 107.61 | I19: 686.91 | J19: -292.13 | K19: -150.31
A20: Power and Fuel | B20: 545.44 | C20: 525.09 | D20: 559.97 | E20: 613.6 | F20: 621.89 | G20: 627.09 | H20: 702.78 | I20: 830.05 | J20: 760.78
A21: Other Mfr. Exp | B21: 1808.55 | C21: 1973.46 | D21: 1828.35 | E21: 1884.71 | F21: 1690 | G21: 1723.78 | H21: 1880.71 | I21: 1936.77 | J21: 2186.62
A22: Employee Cost | B22: 4772.31 | C22: 4902.3 | D22: 5367.05 | E22: 5967.09 | F22: 6362.35 | G22: 6862.23 | H22: 7300.83 | I22: 8296.03 | J22: 9429.06 | K22: 9973.12
A23: Selling and admin | B23: 5219.2 | C23: 5224.61 | D23: 4727 | E23: 5350.33 | F23: 6995.37 | G23: 6283.41 | H23: 7366.88 | I23: 9482.36 | J23: 11033.19
A24: Other Expenses | B24: 1637.25 | C24: 720.22 | D24: 950.99 | E24: 1004.23 | F24: 954.6 | G24: 841.59 | H24: 794.18 | I24: 1027.87 | J24: 1406.82 | K24: 16586.27
A25: Other Income | B25: -42.5 | C25: 610.4 | D25: -135.03 | E25: -258.28 | F25: 382.26 | G25: -3449.21 | H25: -3505.16 | I25: 459.42 | J25: 865.23 | K25: 1287.19
A26: Depreciation | B26: 1037.53 | C26: 1264.75 | D26: 1499.84 | E26: 1753.25 | F26: 2052.78 | G26: 2079.95 | H26: 2143.74 | I26: 2529.43 | J26: 2556.64 | K26: 2575.39
A27: Interest | B27: 523.24 | C27: 399.8 | D27: 517.57 | E27: 555.25 | F27: 302.73 | G27: 141.43 | H27: 127.35 | I27: 172 | J27: 238.47 | K27: 231.36
A28: Profit before tax | B28: 6570.63 | C28: 9047.87 | D28: 3478.98 | E28: 3810.2 | F28: 5009.59 | G28: 2799.37 | H28: 4481.32 | I28: 9408.43 | J28: 11087.89 | K28: 13752.13
A29: Tax | B29: 913.77 | C29: 1211.57 | D29: 911.04 | E29: 600.88 | F29: 822.8 | G29: 514.69 | H29: 1075.5 | I29: 847.59 | J29: 1439.45 | K29: 2772.03
A30: Net profit | B30: 4545.71 | C30: 6964.37 | D30: 2095.7 | E30: 2665.42 | F30: 3764.93 | G30: 2903.82 | H30: 3272.73 | I30: 8473.58 | J30: 9576.38 | K30: 10929.04
A31: Dividend Amount | B31: 240.66 | C31: 839.76 | D31: 479.86 | E31: 659.81 | F31: 959.72 | G31: 1799.48 | H31: 2399.3 | I31: 2759.2 | J31: 3239.06 | K31: 3838.88
A40: Quarters
A41: Report Date | B41: 44926 | C41: 45016 | D41: 45107 | E41: 45199 | F41: 45291 | G41: 45382 | H41: 45473 | I41: 45565 | J41: 45657 | K41: 45747
A42: Sales | B42: 11240.97 | C42: 10930.67 | D42: 11940.84 | E42: 12192.41 | F42: 12380.7 | G42: 11982.9 | H42: 12652.75 | I42: 13291.39 | J42: 13675.46 | K42: 12958.84
A43: Expenses | B43: 8237.25 | C43: 8128.54 | D43: 8609.07 | E43: 9013.03 | F43: 8903.87 | G43: 8947.75 | H43: 9045.13 | I43: 9352.43 | J43: 9666.44 | K43: 9242.75
A44: Other Income | B44: 173.88 | C44: 201.83 | D44: -118.43 | E44: 293.61 | F44: 180.39 | G44: 504.3 | H44: 532.55 | I44: 354 | J44: 149.45 | K44: 251.19
A45: Depreciation | B45: 659.95 | C45: 671.53 | D45: 651.32 | E45: 632.82 | F45: 622.14 | G45: 650.36 | H45: 655.13 | I45: 625.91 | J45: 630.56 | K45: 663.79
A46: Interest | B46: 46.18 | C46: 92.74 | D46: 80.88 | E46: 49.29 | F46: 34.73 | G46: 73.57 | H46: 61.54 | I46: 69.17 | J46: 51.51 | K46: 49.14
A47: Profit before tax | B47: 2471.47 | C47: 2239.69 | D47: 2481.14 | E47: 2790.88 | F47: 3000.35 | G47: 2815.52 | H47: 3423.5 | I47: 3597.88 | J47: 3476.4 | K47: 3254.35
A48: Tax | B48: 283.43 | C48: 222.91 | D48: 468.1 | E48: 390.1 | F48: 432.32 | G48: 148.93 | H48: 552.25 | I48: 567.21 | J48: 558.86 | K48: 1093.71
A49: Net profit | B49: 2166.01 | C49: 1984.47 | D49: 2022.54 | E49: 2375.51 | F49: 2523.75 | G49: 2654.58 | H49: 2835.62 | I49: 3040.16 | J49: 2903.38 | K49: 2149.88
A50: Operating Profit | B50: 3003.72 | C50: 2802.13 | D50: 3331.77 | E50: 3179.38 | F50: 3476.83 | G50: 3035.15 | H50: 3607.62 | I50: 3938.96 | J50: 4009.02 | K50: 3716.09
A55: BALANCE SHEET
A56: Report Date | B56: 42460 | C56: 42825 | D56: 43190 | E56: 43555 | F56: 43921 | G56: 44286 | H56: 44651 | I56: 45016 | J56: 45382 | K56: 45747
A57: Equity Share Capital | B57: 240.66 | C57: 239.93 | D57: 239.93 | E57: 239.93 | F57: 239.93 | G57: 239.93 | H57: 239.93 | I57: 239.93 | J57: 239.93 | K57: 239.93
A58: Reserves | B58: 32741.82 | C58: 36399.74 | D58: 38074.18 | E58: 41169.13 | F58: 45024.52 | G58: 46222.85 | H58: 47771.29 | I58: 55755.45 | J58: 63426.82 | K58: 71978.09
...

Sheet Financials>
A1: G

Sheet Historical FS
B2: ="Historical Financial Statement - "&'Data Sheet'!B1 -> Historical Financial Statement - SUN PHARMACEUTICAL INDUSTRIES LTD
B3: Years | D3: ='Data Sheet'!B16 -> 42460 | E3: ='Data Sheet'!C16 -> 42825 | F3: ='Data Sheet'!D16 -> 43190 | G3: ='Data Sheet'!E16 -> 43555 | H3: ='Data Sheet'!F16 -> 43921 | I3: ='Data Sheet'!G16 -> 44286 | J3: ='Data Sheet'!H16 -> 44651 | K3: ='Data Sheet'!I16 -> 45016 | ... M3: ='Data Sheet'!K16 -> 45747 | N3: LTM
A4: # | B4: Income Statement
B5: Sales | D5: =IFERROR('Data Sheet'!B17,0) -> 28487.03 | E5: =IFERROR('Data Sheet'!C17,0) -> 31578.44 | F5: =IFERROR('Data Sheet'!D17,0) -> 26489.46 | G5: =IFERROR('Data Sheet'!E17,0) -> 29065.91 | H5: =IFERROR('Data Sheet'!F17,0) -> 32837.5 | I5: =IFERROR('Data Sheet'!G17,0) -> 33498.14 | J5: =IFERROR('Data Sheet'!H17,0) -> 38654.49 | K5: =IFERROR('Data Sheet'!I17,0) -> 43885.68 | ... M5: =IFERROR('Data Sheet'!K17,0) -> 52578.44 | N5: =IFERROR(SUM('Data Sheet'!H42:K42),0) -> 52578.44
B6: Sales Growth | D6: - | E6: =E5/D5 - 1 -> 0.10851991 | F6: =F5/E5 - 1 -> -0.16115362 | G6: =G5/F5 - 1 -> 0.097263213 | H6: =H5/G5 - 1 -> 0.12975991 | I6: =I5/H5 - 1 -> 0.020118462 | J6: =J5/I5 - 1 -> 0.15392944 | K6: =K5/J5 - 1 -> 0.13533201 | L6: =L5/K5 - 1 -> 0.10507232 | ... N6: =N5/M5 - 1 -> 0
B8: COGS | D8: =IFERROR(SUM('Data Sheet'!B18,'Data Sheet'!B20:B22)-1*'Data Sheet'!B19,0) -> 13456.68 | E8: =IFERROR(SUM('Data Sheet'!C18,'Data Sheet'!C20:C22)-1*'Data Sheet'!C19,0) -> 15531.59 | F8: =IFERROR(SUM('Data Sheet'!D18,'Data Sheet'!D20:D22)-1*'Data Sheet'!D19,0) -> 15180.05 | G8: =IFERROR(SUM('Data Sheet'!E18,'Data Sheet'!E20:E22)-1*'Data Sheet'!E19,0) -> 16334.37 | H8: =IFERROR(SUM('Data Sheet'!F18,'Data Sheet'!F20:F22)-1*'Data Sheet'!F19,0) -> 17904.69 | I8: =IFERROR(SUM('Data Sheet'!G18,'Data Sheet'!G20:G22)-1*'Data Sheet'!G19,0) -> 17903.18 | J8: =IFERROR(SUM('Data Sheet'!H18,'Data Sheet'!H20:H22)-1*'Data Sheet'!H19,0) -> 20235.86 | K8: =IFERROR(SUM('Data Sheet'!I18,'Data Sheet'!I20:I22)-1*'Data Sheet'!I19,0) -> 21725.01 | ... M8: =IFERROR(SUM('Data Sheet'!K18,'Data Sheet'!K20:K22)-1*'Data Sheet'!K19,0) -> 20720.48 | N8: =IFERROR(SUM('Data Sheet'!H43:K43),0) -> 37306.75
B9: COGS % Sales | D9: =D8/D5 -> 0.47237918 | E9: =E8/E5 -> 0.49184159 | F9: =F8/F5 -> 0.57306 | G9: =G8/G5 -> 0.5619769 | H9: =H8/H5 -> 0.54525131 | I9: =I8/I5 -> 0.53445296 | J9: =J8/J5 -> 0.52350607 | K9: =K8/K5 -> 0.49503642 | ... N9: =N8/N5 -> 0.70954463
B11: Gross Profit | D11: =D5-D8 -> 15030.35 | E11: =E5-E8 -> 16046.85 | F11: =F5-F8 -> 11309.41 | G11: =G5-G8 -> 12731.54 | H11: =H5-H8 -> 14932.81 | I11: =I5-I8 -> 15594.96 | J11: =J5-J8 -> 18418.63 | K11: =K5-K8 -> 22160.67 | ... N11: =N5-N8 -> 15271.69
B12: Gross Margin | D12: =(D5-D8)/D5 -> 0.52762082 | E12: =(E5-E8)/E5 -> 0.50815841 | F12: =(F5-F8)/F5 -> 0.42694 | G12: =(G5-G8)/G5 -> 0.4380231 | H12: =(H5-H8)/H5 -> 0.45474869 | I12: =(I5-I8)/I5 -> 0.46554704 | J12: =(J5-J8)/J5 -> 0.47649393 | K12: =(K5-K8)/K5 -> 0.50496358 | ... N12: =(N5-N8)/N5 -> 0.29045537
B14: Selling & General Expenses | D14: =IFERROR(SUM('Data Sheet'!B23:B24),0) -> 6856.45 | E14: =IFERROR(SUM('Data Sheet'!C23:C24),0) -> 5944.83 | F14: =IFERROR(SUM('Data Sheet'!D23:D24),0) -> 5677.99 | G14: =IFERROR(SUM('Data Sheet'!E23:E24),0) -> 6354.56 | H14: =IFERROR(SUM('Data Sheet'!F23:F24),0) -> 7949.97 | I14: =IFERROR(SUM('Data Sheet'!G23:G24),0) -> 7125 | J14: =IFERROR(SUM('Data Sheet'!H23:H24),0) -> 8161.06 | K14: =IFERROR(SUM('Data Sheet'!I23:I24),0) -> 10510.23 | ... N14: =IFERROR(SUM('Data Sheet'!L23:L24),0) -> 0
B15: S&G Exp % Sales | D15: =D14/D5 -> 0.24068673 | E15: =E14/E5 -> 0.18825597 | F15: =F14/F5 -> 0.21434903 | G15: =G14/G5 -> 0.21862587 | H15: =H14/H5 -> 0.24210034 | I15: =I14/I5 -> 0.21269838 | J15: =J14/J5 -> 0.21112838 | K15: =K14/K5 -> 0.23949111 | ... N15: =N14/N5 -> 0
B17: EBITDA | D17: =D11-D14 -> 8173.9 | E17: =E11-E14 -> 10102.02 | F17: =F11-F14 -> 5631.42 | G17: =G11-G14 -> 6376.98 | H17: =H11-H14 -> 6982.84 | I17: =I11-I14 -> 8469.96 | J17: =J11-J14 -> 10257.57 | K17: =K11-K14 -> 11650.44 | ... N17: =N11-N14 -> 15271.69
B18: EBITDA Margin | D18: =D17/D5 -> 0.28693409 | E18: =E17/E5 -> 0.31990244 | F18: =F17/F5 -> 0.21259097 | G18: =G17/G5 -> 0.21939723 | H18: =H17/H5 -> 0.21264834 | I18: =I17/I5 -> 0.25284867 | J18: =J17/J5 -> 0.26536555 | K18: =K17/K5 -> 0.26547247 | ... N18: =N17/N5 -> 0.29045537
B19: EBITDA % Sales | D19: =D17/D5 -> 0.28693409 | E19: =E17/E5 -> 0.31990244 | F19: =F17/F5 -> 0.21259097 | G19: =G17/G5 -> 0.21939723 | H19: =H17/H5 -> 0.21264834 | I19: =I17/I5 -> 0.25284867 | J19: =J17/J5 -> 0.26536555 | K19: =K17/K5 -> 0.26547247 | ... N19: =N17/N5 -> 0.29045537
B21: Interest | D21: =IFERROR('Data Sheet'!B27,0) -> 523.24 | E21: =IFERROR('Data Sheet'!C27,0) -> 399.8 | F21: =IFERROR('Data Sheet'!D27,0) -> 517.57 | G21: =IFERROR('Data Sheet'!E27,0) -> 555.25 | H21: =IFERROR('Data Sheet'!F27,0) -> 302.73 | I21: =IFERROR('Data Sheet'!G27,0) -> 141.43 | J21: =IFERROR('Data Sheet'!H27,0) -> 127.35 | K21: =IFERROR('Data Sheet'!I27,0) -> 172 | ... N21: =IFERROR('Data Sheet'!L27,0) -> 0
B22: Interest % Sales | D22: =D21/D5 -> 0.018367657 | E22: =E21/E5 -> 0.012660537 | F22: =F21/F5 -> 0.019538715 | G22: =G21/G5 -> 0.019103135 | H22: =H21/H5 -> 0.0092190331 | I22: =I21/I5 -> 0.0042220255 | J22: =J21/J5 -> 0.003294572 | K22: =K21/K5 -> 0.0039192739 | ... N22: =N21/N5 -> 0
B24: Depreciation | D24: =IFERROR('Data Sheet'!B26,0) -> 1037.53 | E24: =IFERROR('Data Sheet'!C26,0) -> 1264.75 | F24: =IFERROR('Data Sheet'!D26,0) -> 1499.84 | G24: =IFERROR('Data Sheet'!E26,0) -> 1753.25 | H24: =IFERROR('Data Sheet'!F26,0) -> 2052.78 | I24: =IFERROR('Data Sheet'!G26,0) -> 2079.95 | J24: =IFERROR('Data Sheet'!H26,0) -> 2143.74 | K24: =IFERROR('Data Sheet'!I26,0) -> 2529.43 | ... M24: =IFERROR('Data Sheet'!K26,0) -> 2575.39 | N24: =IFERROR(SUM('Data Sheet'!H45:K45),0) -> 2575.39
B25: Depreciation % Sales | D25: =D24/D5 -> 0.036421136 | E25: =E24/E5 -> 0.04005106 | F25: =F24/F5 -> 0.056620256 | G25: =G24/G5 -> 0.060319804 | H25: =H24/H5 -> 0.062513285 | I25: =I24/I5 -> 0.062091507 | J25: =J24/J5 -> 0.055459017 | K25: =K24/K5 -> 0.057636796 | ... N25: =N24/N5 -> 0.048981864
B27: Earning before Taxes | D27: =IFERROR(D17-SUM(D21,D24),0) -> 6613.13 | E27: =IFERROR(E17-SUM(E21,E24),0) -> 8437.47 | F27: =IFERROR(F17-SUM(F21,F24),0) -> 3614.01 | G27: =IFERROR(G17-SUM(G21,G24),0) -> 4068.48 | H27: =IFERROR(H17-SUM(H21,H24),0) -> 4627.33 | I27: =IFERROR(I17-SUM(I21,I24),0) -> 6248.58 | J27: =IFERROR(J17-SUM(J21,J24),0) -> 7986.48 | K27: =IFERROR(K17-SUM(K21,K24),0) -> 8949.01 | ... N27: =IFERROR(N17-SUM(N21,N24),0) -> 12696.3
B28: EBT % Sales | D28: =D27/D5 -> 0.2321453 | E28: =E27/E5 -> 0.26719084 | F28: =F27/F5 -> 0.136432 | G28: =G27/G5 -> 0.13997429 | H28: =H27/H5 -> 0.14091603 | I28: =I27/I5 -> 0.18653513 | J28: =J27/J5 -> 0.20661196 | K28: =K27/K5 -> 0.2039164 | ... N28: =N27/N5 -> 0.2414735
B30: Tax | D30: =IFERROR('Data Sheet'!B29,0) -> 913.77 | E30: =IFERROR('Data Sheet'!C29,0) -> 1211.57 | F30: =IFERROR('Data Sheet'!D29,0) -> 911.04 | G30: =IFERROR('Data Sheet'!E29,0) -> 600.88 | H30: =IFERROR('Data Sheet'!F29,0) -> 822.8 | I30: =IFERROR('Data Sheet'!G29,0) -> 514.69 | J30: =IFERROR('Data Sheet'!H29,0) -> 1075.5 | K30: =IFERROR('Data Sheet'!I29,0) -> 847.59 | ... M30: =IFERROR('Data Sheet'!K29,0) -> 2772.03 | N30: =IFERROR(SUM('Data Sheet'!H48:K48),0) -> 2772.03
B31: Effective Tax Rate | D31: =D30/D27 -> 0.13817512 | E31: =E30/E27 -> 0.14359399 | F31: =F30/F27 -> 0.25208563 | G31: =G30/G27 -> 0.14769152 | H31: =H30/H27 -> 0.17781312 | I31: =I30/I27 -> 0.082369114 | J31: =J30/J27 -> 0.13466508 | K31: =K30/K27 -> 0.09471327 | ... N31: =N30/N27 -> 0.21833369
B33: Net Profit | D33: =IFERROR(D27-D30,0) -> 5699.36 | E33: =IFERROR(E27-E30,0) -> 7225.9 | F33: =IFERROR(F27-F30,0) -> 2702.97 | G33: =IFERROR(G27-G30,0) -> 3467.6 | H33: =IFERROR(H27-H30,0) -> 3804.53 | I33: =IFERROR(I27-I30,0) -> 5733.89 | J33: =IFERROR(J27-J30,0) -> 6910.98 | K33: =IFERROR(K27-K30,0) -> 8101.42 | ... N33: =IFERROR(N27-N30,0) -> 9924.27
B34: Net Margins | D34: =D33/D5 -> 0.20006859 | E34: =E33/E5 -> 0.22882384 | F34: =F33/F5 -> 0.10203945 | G34: =G33/G5 -> 0.11930127 | H34: =H33/H5 -> 0.11585931 | I34: =I33/I5 -> 0.1711704 | J34: =J33/J5 -> 0.17878854 | K34: =K33/K5 -> 0.18460281 | ... N34: =N33/N5 -> 0.1887517
B36: No. of Equity Shares | D36: =IFERROR('Data Sheet'!B93,0) -> 240.67 | E36: =IFERROR('Data Sheet'!C93,0) -> 239.93 | F36: =IFERROR('Data Sheet'!D93,0) -> 239.93 | G36: =IFERROR('Data Sheet'!E93,0) -> 239.93 | H36: =IFERROR('Data Sheet'!F93,0) -> 239.93 | I36: =IFERROR('Data Sheet'!G93,0) -> 239.93 | J36: =IFERROR('Data Sheet'!H93,0) -> 239.93 | K36: =IFERROR('Data Sheet'!I93,0) -> 239.93 | ... M36: =IFERROR('Data Sheet'!K93,0) -> 239.93
B38: EPS(Earning per share) | D38: =IFERROR(D33/D36,0) -> 23.681223 | E38: =IFERROR(E33/E36,0) -> 30.116701 | F38: =IFERROR(F33/F36,0) -> 11.265661 | G38: =IFERROR(G33/G36,0) -> 14.452549 | H38: =IFERROR(H33/H36,0) -> 15.856833 | I38: =IFERROR(I33/I36,0) -> 23.898179 | J38: =IFERROR(J33/J36,0) -> 28.804151 | K38: =IFERROR(K33/K36,0) -> 33.765765 | ... M38: =IFERROR(M33/M36,0) -> 40.398908
B39: EPS Growth%) | E39: =E38/D38-1 -> 0.27175444 | F39: =F38/E38-1 -> -0.6259331 | G39: =G38/F38-1 -> 0.28288512 | H39: =H38/G38-1 -> 0.097165186 | I39: =I38/H38-1 -> 0.50712177 | J39: =J38/I38-1 -> 0.20528646 | K39: =K38/J38-1 -> 0.17225343 | L39: =L38/K38-1 -> 0.084156852 | M39: =M38/L38-1 -> 0.10357261
B41: Dividend per share | D41: =IFERROR('Data Sheet'!B31/'Historical FS'!D36,0) -> 0.99995845 | E41: =IFERROR('Data Sheet'!C31/'Historical FS'!E36,0) -> 3.5000208 | F41: =IFERROR('Data Sheet'!D31/'Historical FS'!F36,0) -> 2 | G41: =IFERROR('Data Sheet'!E31/'Historical FS'!G36,0) -> 2.7500104 | H41: =IFERROR('Data Sheet'!F31/'Historical FS'!H36,0) -> 4 | I41: =IFERROR('Data Sheet'!G31/'Historical FS'!I36,0) -> 7.5000208 | J41: =IFERROR('Data Sheet'!H31/'Historical FS'!J36,0) -> 10 | K41: =IFERROR('Data Sheet'!I31/'Historical FS'!K36,0) -> 11.500021 | ... M41: =IFERROR('Data Sheet'!K31/'Historical FS'!M36,0) -> 16
B42: Dividend payout ratio | D42: =IFERROR(D41/D38,0) -> 0.042225794 | E42: =IFERROR(E41/E38,0) -> 0.11621528 | F42: =IFERROR(F41/F38,0) -> 0.17753064 | G42: =IFERROR(G41/G38,0) -> 0.19027858 | H42: =IFERROR(H41/H38,0) -> 0.25225718 | I42: =IFERROR(I41/I38,0) -> 0.31383232 | J42: =IFERROR(J41/J38,0) -> 0.34717218 | K42: =IFERROR(K41/K38,0) -> 0.34058227 | ... M42: =IFERROR(M41/M38,0) -> 0.39605031
B44: Retained Earnings | D44: =IFERROR(IF(D41<D38,1-D41/D38,0),0) -> 0.95777421 | E44: =IFERROR(IF(E41<E38,1-E41/E38,0),0) -> 0.88378472 | F44: =IFERROR(IF(F41<F38,1-F41/F38,0),0) -> 0.82246936 | G44: =IFERROR(IF(G41<G38,1-G41/G38,0),0) -> 0.80972142 | H44: =IFERROR(IF(H41<H38,1-H41/H38,0),0) -> 0.74774282 | I44: =IFERROR(IF(I41<I38,1-I41/I38,0),0) -> 0.68616768 | J44: =IFERROR(IF(J41<J38,1-J41/J38,0),0) -> 0.65282782 | K44: =IFERROR(IF(K41<K38,1-K41/K38,0),0) -> 0.65941773 | ... M44: =IFERROR(IF(M41<M38,1-M41/M38,0),0) -> 0.60394969
A47: # | B47: Balance Sheet
B48: Equity Share Capital | D48: =IFERROR('Data Sheet'!B57,0) -> 240.66 | E48: =IFERROR('Data Sheet'!C57,0) -> 239.93 | F48: =IFERROR('Data Sheet'!D57,0) -> 239.93 | G48: =IFERROR('Data Sheet'!E57,0) -> 239.93 | H48: =IFERROR('Data Sheet'!F57,0) -> 239.93 | I48: =IFERROR('Data Sheet'!G57,0) -> 239.93 | J48: =IFERROR('Data Sheet'!H57,0) -> 239.93 | K48: =IFERROR('Data Sheet'!I57,0) -> 239.93 | ... M48: =IFERROR('Data Sheet'!K57,0) -> 239.93
B49: Reserves | D49: =IFERROR('Data Sheet'!B58,0) -> 32741.82 | E49: =IFERROR('Data Sheet'!C58,0) -> 36399.74 | F49: =IFERROR('Data Sheet'!D58,0) -> 38074.18 | G49: =IFERROR('Data Sheet'!E58,0) -> 41169.13 | H49: =IFERROR('Data Sheet'!F58,0) -> 45024.52 | I49: =IFERROR('Data Sheet'!G58,0) -> 46222.85 | J49: =IFERROR('Data Sheet'!H58,0) -> 47771.29 | K49: =IFERROR('Data Sheet'!I58,0) -> 55755.45 | ... M49: =IFERROR('Data Sheet'!K58,0) -> 71978.09
B50: Borrowings | D50: =IFERROR('Data Sheet'!B59,0) -> 8496.76 | E50: =IFERROR('Data Sheet'!C59,0) -> 9831.77 | F50: =IFERROR('Data Sheet'!D59,0) -> 10385.27 | G50: =IFERROR('Data Sheet'!E59,0) -> 10514.36 | H50: =IFERROR('Data Sheet'!F59,0) -> 8314.88 | I50: =IFERROR('Data Sheet'!G59,0) -> 3868.58 | J50: =IFERROR('Data Sheet'!H59,0) -> 1290.3 | K50: =IFERROR('Data Sheet'!I59,0) -> 6885.87 | ... M50: =IFERROR('Data Sheet'!K59,0) -> 2362.19
B51: Other Liabilities | D51: =IFERROR('Data Sheet'!B60,0) -> 13948.26 | E51: =IFERROR('Data Sheet'!C60,0) -> 14624.01 | F51: =IFERROR('Data Sheet'!D60,0) -> 15598.01 | G51: =IFERROR('Data Sheet'!E60,0) -> 12666.11 | H51: =IFERROR('Data Sheet'!F60,0) -> 14614.99 | I51: =IFERROR('Data Sheet'!G60,0) -> 17290.86 | J51: =IFERROR('Data Sheet'!H60,0) -> 20474.39 | K51: =IFERROR('Data Sheet'!I60,0) -> 17830.65 | ... M51: =IFERROR('Data Sheet'!K60,0) -> 17520.37
B52: Total Liabilities | D52: =IFERROR('Data Sheet'!B61,0) -> 55427.5 | E52: =IFERROR('Data Sheet'!C61,0) -> 61095.45 | F52: =IFERROR('Data Sheet'!D61,0) -> 64297.39 | G52: =IFERROR('Data Sheet'!E61,0) -> 64589.53 | H52: =IFERROR('Data Sheet'!F61,0) -> 68194.32 | I52: =IFERROR('Data Sheet'!G61,0) -> 67622.22 | J52: =IFERROR('Data Sheet'!H61,0) -> 69775.91 | K52: =IFERROR('Data Sheet'!I61,0) -> 80711.9 | ... M52: =IFERROR('Data Sheet'!K61,0) -> 92100.58
B54: Fixed Assets Net Block | D54: =IFERROR('Data Sheet'!B62,0) -> 15872.25 | E54: =IFERROR('Data Sheet'!C62,0) -> 17675.17 | F54: =IFERROR('Data Sheet'!D62,0) -> 18852.65 | G54: =IFERROR('Data Sheet'!E62,0) -> 21836.54 | H54: =IFERROR('Data Sheet'!F62,0) -> 22846.91 | I54: =IFERROR('Data Sheet'!G62,0) -> 21552.98 | J54: =IFERROR('Data Sheet'!H62,0) -> 22665.16 | K54: =IFERROR('Data Sheet'!I62,0) -> 24065.44 | ... M54: =IFERROR('Data Sheet'!K62,0) -> 27995.9
B55: Capital Work in Progress | D55: =IFERROR('Data Sheet'!B63,0) -> 2175.45 | E55: =IFERROR('Data Sheet'!C63,0) -> 2801.38 | F55: =IFERROR('Data Sheet'!D63,0) -> 2465.16 | G55: =IFERROR('Data Sheet'!E63,0) -> 1411.15 | H55: =IFERROR('Data Sheet'!F63,0) -> 1220.34 | I55: =IFERROR('Data Sheet'!G63,0) -> 1566.83 | J55: =IFERROR('Data Sheet'!H63,0) -> 1286.8 | K55: =IFERROR('Data Sheet'!I63,0) -> 4973.16 | ... M55: =IFERROR('Data Sheet'!K63,0) -> 1234.34
B56: Investments | D56: =IFERROR('Data Sheet'!B64,0) -> 1829.88 | E56: =IFERROR('Data Sheet'!C64,0) -> 1191.88 | F56: =IFERROR('Data Sheet'!D64,0) -> 7142.87 | G56: =IFERROR('Data Sheet'!E64,0) -> 7902.53 | H56: =IFERROR('Data Sheet'!F64,0) -> 10143.11 | I56: =IFERROR('Data Sheet'!G64,0) -> 9612.45 | J56: =IFERROR('Data Sheet'!H64,0) -> 12848.59 | K56: =IFERROR('Data Sheet'!I64,0) -> 14824.34 | ... M56: =IFERROR('Data Sheet'!K64,0) -> 18353.8
B57: Other Assets | D57: =IFERROR('Data Sheet'!B65-SUM('Data Sheet'!B67:B69),0) -> 9170.07 | E57: =IFERROR('Data Sheet'!C65-SUM('Data Sheet'!C67:C69),0) -> 10250.76 | F57: =IFERROR('Data Sheet'!D65-SUM('Data Sheet'!D67:D69),0) -> 11211.36 | G57: =IFERROR('Data Sheet'!E65-SUM('Data Sheet'!E67:E69),0) -> 9393.53 | H57: =IFERROR('Data Sheet'!F65-SUM('Data Sheet'!F67:F69),0) -> 10200.18 | I57: =IFERROR('Data Sheet'!G65-SUM('Data Sheet'!G67:G69),0) -> 10386.03 | J57: =IFERROR('Data Sheet'!H65-SUM('Data Sheet'!H67:H69),0) -> 8532.29 | K57: =IFERROR('Data Sheet'!I65-SUM('Data Sheet'!I67:I69),0) -> 9127.11 | ... M57: =IFERROR('Data Sheet'!K65-SUM('Data Sheet'!K67:K69),0) -> 9895.48
...

Sheet Cash Flow Data
C2: 41334 | D2: 41699 | E2: 42064 | F2: 42430 | G2: 42795 | H2: 43160 | I2: 43525 | J2: 43891 | K2: 44256 | L2: 44621 | M2: 44986 | N2: 45352
B3: Cash from Operating Activity | C3: 22163 | D3: 36151 | E3: 35531 | F3: 37900 | G3: 30199 | H3: 23857 | I3: 18891 | J3: 26633 | K3: 29001 | L3: 14283 | M3: 35388 | N3: 67915
B4: Profit from operations | C4: 24406 | D4: 36303 | E4: 43397 | F4: 38626 | G4: 28840 | H4: 33312 | I4: 28771 | J4: 23352 | K4: 31198 | L4: 26943 | M4: 41694 | N4: 65106
B5: Receivables | C5: -5177 | D5: 445 | E5: -3179 | F5: -2223 | G5: -4152 | H5: -10688 | I5: -9109 | J5: 9950 | K5: -5505 | L5: 185 | M5: -2213 | N5: -1875
B6: Inventory | C6: -2656 | D6: -2853 | E6: -3692 | F6: -5743 | G6: -6621 | H6: -3560 | I6: 2069 | J6: 2326 | K6: 3814 | L6: 472 | M6: -5665 | N6: -7265
B7: Payables | C7: 8132 | D7: 4694 | E7: 3598 | F7: 3947 | G7: 9301 | H7: 7320 | I7: -4692 | J7: -8085 | K7: 5748 | L7: -7012 | M7: 6945 | N7: 13706
B8: Loans Advances | C8: 0 | D8: 0 | E8: 0 | F8: -520 | G8: 0 | H8: 0 | I8: 0 | J8: 0 | K8: 0 | L8: 0 | M8: 0 | N8: 0
B9: Other WC items | C9: -303 | D9: 1870 | E9: -398 | F9: 5852 | G9: 4727 | H9: 494 | I9: 4512 | J9: 875 | K9: -4150 | L9: -4396 | M9: -2194 | N9: 2760
B10: Working capital changes | C10: -3 | D10: 4157 | E10: -3672 | F10: 1313 | G10: 3254 | H10: -6434 | I10: -7221 | J10: 5065 | K10: -93 | L10: -10750 | M10: -3127 | N10: 7325
B11: Direct taxes | C11: -2240 | D11: -4308 | E11: -4194 | F11: -2040 | G11: -1895 | H11: -3021 | I11: -2659 | J11: -1785 | K11: -2105 | L11: -1910 | M11: -3179 | N11: -4516
B12: Cash from Investing Activity | C12: -22969 | D12: -27991 | E12: -36232 | F12: -36694 | G12: -39571 | H12: -25139 | I12: -20878 | J12: -33115 | K12: -25672 | L12: -4444 | M12: -15417 | N12: -22782
B13: Fixed assets purchased | C13: -18863 | D13: -26975 | E13: -31962 | F13: -31503 | G13: -16072 | H13: -35079 | I13: -35304 | J13: -29702 | K13: -20205 | L13: -15168 | M13: -19230 | N13: -31414
B14: Fixed assets sold | C14: 37 | D14: 50 | E14: 74 | F14: 59 | G14: 53 | H14: 30 | I14: 67 | J14: 171 | K14: 351 | L14: 230 | M14: 285 | N14: 231
... B33: Net Cash Flow | C33: -2499 | D33: 4277 | E33: 4500 | F33: -2589 | G33: -3167 | H33: 730 | I33: 6843 | J33: -3092 | K33: 13232 | L33: 6459 | M33: -6272 | N33: 8128

Sheet Ratio Analysis
B2: ="Ratio Analysis of - "&'Data Sheet'!B1 -> Ratio Analysis of - SUN PHARMACEUTICAL INDUSTRIES LTD
B3: Years | D3: ='Data Sheet'!B16 -> 42460 | E3: ='Data Sheet'!C16 -> 42825 | F3: ='Data Sheet'!D16 -> 43190 | G3: ='Data Sheet'!E16 -> 43555 | H3: ='Data Sheet'!F16 -> 43921 | I3: ='Data Sheet'!G16 -> 44286 | J3: ='Data Sheet'!H16 -> 44651 | K3: ='Data Sheet'!I16 -> 45016 | ... M3: ='Data Sheet'!K16 -> 45747 | N3: Trend | O3: Mean | P3: Median
B5: Sales Growth | E5: =IFERROR('Historical FS'!E6,0) -> 0.10851991 | F5: =IFERROR('Historical FS'!F6,0) -> -0.16115362 | G5: =IFERROR('Historical FS'!G6,0) -> 0.097263213 | H5: =IFERROR('Historical FS'!H6,0) -> 0.12975991 | I5: =IFERROR('Historical FS'!I6,0) -> 0.020118462 | J5: =IFERROR('Historical FS'!J6,0) -> 0.15392944 | K5: =IFERROR('Historical FS'!K6,0) -> 0.13533201 | L5: =IFERROR('Historical FS'!L6,0) -> 0.10507232 | M5: =IFERROR('Historical FS'!M6,0) -> 0.084161961 | O5: =IFERROR(AVERAGE(E5:M5),0) -> 0.074778179 | P5: =IFERROR(MEDIAN(E5:M5),0) -> 0.10507232
B6: EBITDA Growth | E6: =IFERROR('Historical FS'!E17/'Historical FS'!D17-1,0) -> 0.2358874 | F6: =IFERROR('Historical FS'!F17/'Historical FS'!E17-1,0) -> -0.44254515 | G6: =IFERROR('Historical FS'!G17/'Historical FS'!F17-1,0) -> 0.1323929 | H6: =IFERROR('Historical FS'!H17/'Historical FS'!G17-1,0) -> 0.095007355 | I6: =IFERROR('Historical FS'!I17/'Historical FS'!H17-1,0) -> 0.21296779 | J6: =IFERROR('Historical FS'!J17/'Historical FS'!I17-1,0) -> 0.21105294 | K6: =IFERROR('Historical FS'!K17/'Historical FS'!J17-1,0) -> 0.13578947 | L6: =IFERROR('Historical FS'!L17/'Historical FS'!K17-1,0) -> 0.11736295 | M6: =IFERROR('Historical FS'!M17/'Historical FS'!L17-1,0) -> 0.17314179 | O6: =IFERROR(AVERAGE(E6:M6),0) -> 0.09678416 | P6: =IFERROR(MEDIAN(E6:M6),0) -> 0.13578947
B7: EBT Growth | E7: =IFERROR('Historical FS'!E27/'Historical FS'!D27-1,0) -> 0.27586634 | F7: =IFERROR('Historical FS'!F27/'Historical FS'!E27-1,0) -> -0.57167137 | G7: =IFERROR('Historical FS'!G27/'Historical FS'!F27-1,0) -> 0.12575228 | H7: =IFERROR('Historical FS'!H27/'Historical FS'!G27-1,0) -> 0.13736088 | I7: =IFERROR('Historical FS'!I27/'Historical FS'!H27-1,0) -> 0.35036403 | J7: =IFERROR('Historical FS'!J27/'Historical FS'!I27-1,0) -> 0.27812719 | K7: =IFERROR('Historical FS'!K27/'Historical FS'!J27-1,0) -> 0.12051993 | L7: =IFERROR('Historical FS'!L27/'Historical FS'!K27-1,0) -> 0.14232301 | M7: =IFERROR('Historical FS'!M27/'Historical FS'!L27-1,0) -> 0.21934408 | O7: =IFERROR(AVERAGE(E7:M7),0) -> 0.11977626 | P7: =IFERROR(MEDIAN(E7:M7),0) -> 0.14232301
B8: Net Profit Growth | E8: =IFERROR('Historical FS'!E33/'Historical FS'!D33-1,0) -> 0.26784411 | F8: =IFERROR('Historical FS'!F33/'Historical FS'!E33-1,0) -> -0.6259331 | G8: =IFERROR('Historical FS'!G33/'Historical FS'!F33-1,0) -> 0.28288512 | H8: =IFERROR('Historical FS'!H33/'Historical FS'!G33-1,0) -> 0.097165186 | I8: =IFERROR('Historical FS'!I33/'Historical FS'!H33-1,0) -> 0.50712177 | J8: =IFERROR('Historical FS'!J33/'Historical FS'!I33-1,0) -> 0.20528646 | K8: =IFERROR('Historical FS'!K33/'Historical FS'!J33-1,0) -> 0.17225343 | L8: =IFERROR('Historical FS'!L33/'Historical FS'!K33-1,0) -> 0.084156852 | M8: =IFERROR('Historical FS'!M33/'Historical FS'!L33-1,0) -> 0.10357261 | O8: =IFERROR(AVERAGE(E8:M8),0) -> 0.12159472 | P8: =IFERROR(MEDIAN(E8:M8),0) -> 0.17225343
B9: Dividend Growth | E9: =IFERROR('Historical FS'!E41/'Historical FS'!D41-1,0) -> 2.5001663 | F9: =IFERROR('Historical FS'!F41/'Historical FS'!E41-1,0) -> -0.42857483 | G9: =IFERROR('Historical FS'!G41/'Historical FS'!F41-1,0) -> 0.37500521 | H9: =IFERROR('Historical FS'!H41/'Historical FS'!G41-1,0) -> 0.45453994 | I9: =IFERROR('Historical FS'!I41/'Historical FS'!H41-1,0) -> 0.87500521 | J9: =IFERROR('Historical FS'!J41/'Historical FS'!I41-1,0) -> 0.33332963 | K9: =IFERROR('Historical FS'!K41/'Historical FS'!J41-1,0) -> 0.15000208 | L9: =IFERROR('Historical FS'!L41/'Historical FS'!K41-1,0) -> 0.17391273 | M9: =IFERROR('Historical FS'!M41/'Historical FS'!L41-1,0) -> 0.18518336 | O9: =IFERROR(AVERAGE(E9:M9),0) -> 0.5131744 | P9: =IFERROR(MEDIAN(E9:M9),0) -> 0.33332963
B11: Gross Margin | D11: =IFERROR('Historical FS'!D12,0) -> 0.52762082 | E11: =IFERROR('Historical FS'!E12,0) -> 0.50815841 | F11: =IFERROR('Historical FS'!F12,0) -> 0.42694 | G11: =IFERROR('Historical FS'!G12,0) -> 0.4380231 | H11: =IFERROR('Historical FS'!H12,0) -> 0.45474869 | I11: =IFERROR('Historical FS'!I12,0) -> 0.46554704 | J11: =IFERROR('Historical FS'!J12,0) -> 0.47649393 | K11: =IFERROR('Historical FS'!K12,0) -> 0.50496358 | ... M11: =IFERROR('Historical FS'!M12,0) -> 0.60591299 | O11: =IFERROR(AVERAGE(D11:M11),0) -> 0.49333453 | P11: =IFERROR(MEDIAN(D11:M11),0) -> 0.49072876
B12: EBITDA Margin | D12: =IFERROR('Historical FS'!D18,0) -> 0.28693409 | E12: =IFERROR('Historical FS'!E18,0) -> 0.31990244 | F12: =IFERROR('Historical FS'!F18,0) -> 0.21259097 | G12: =IFERROR('Historical FS'!G18,0) -> 0.21939723 | H12: =IFERROR('Historical FS'!H18,0) -> 0.21264834 | I12: =IFERROR('Historical FS'!I18,0) -> 0.25284867 | J12: =IFERROR('Historical FS'!J18,0) -> 0.26536555 | K12: =IFERROR('Historical FS'!K18,0) -> 0.26547247 | ... M12: =IFERROR('Historical FS'!M18,0) -> 0.29045537 | O12: =IFERROR(AVERAGE(D12:M12),0) -> 0.25940402 | P12: =IFERROR(MEDIAN(D12:M12),0) -> 0.26541901
B13: EBIT Margin | D13: =IFERROR(('Historical FS'!D17-'Historical FS'!D24)/'Historical FS'!D5,0) -> 0.25051295 | E13: =IFERROR(('Historical FS'!E17-'Historical FS'!E24)/'Historical FS'!E5,0) -> 0.27985138 | F13: =IFERROR(('Historical FS'!F17-'Historical FS'!F24)/'Historical FS'!F5,0) -> 0.15597071 | G13: =IFERROR(('Historical FS'!G17-'Historical FS'!G24)/'Historical FS'!G5,0) -> 0.15907742 | H13: =IFERROR(('Historical FS'!H17-'Historical FS'!H24)/'Historical FS'!H5,0) -> 0.15013506 | I13: =IFERROR(('Historical FS'!I17-'Historical FS'!I24)/'Historical FS'!I5,0) -> 0.19075716 | J13: =IFERROR(('Historical FS'!J17-'Historical FS'!J24)/'Historical FS'!J5,0) -> 0.20990653 | K13: =IFERROR(('Historical FS'!K17-'Historical FS'!K24)/'Historical FS'!K5,0) -> 0.20783568 | ... M13: =IFERROR(('Historical FS'!M17-'Historical FS'!M24)/'Historical FS'!M5,0) -> 0.2414735 | O13: =IFERROR(AVERAGE(D13:M13),0) -> 0.20612278 | P13: =IFERROR(MEDIAN(D13:M13),0) -> 0.20887111
B14: EBT Margin | D14: =IFERROR('Historical FS'!D28,0) -> 0.2321453 | E14: =IFERROR('Historical FS'!E28,0) -> 0.26719084 | F14: =IFERROR('Historical FS'!F28,0) -> 0.136432 | G14: =IFERROR('Historical FS'!G28,0) -> 0.13997429 | H14: =IFERROR('Historical FS'!H28,0) -> 0.14091603 | I14: =IFERROR('Historical FS'!I28,0) -> 0.18653513 | J14: =IFERROR('Historical FS'!J28,0) -> 0.20661196 | K14: =IFERROR('Historical FS'!K28,0) -> 0.2039164 | ... M14: =IFERROR('Historical FS'!M28,0) -> 0.23707322 | O14: =IFERROR(AVERAGE(D14:M14),0) -> 0.19615854 | P14: =IFERROR(MEDIAN(D14:M14),0) -> 0.20526418
B15: Net Profit Margin | D15: =IFERROR('Historical FS'!D34,0) -> 0.20006859 | E15: =IFERROR('Historical FS'!E34,0) -> 0.22882384 | F15: =IFERROR('Historical FS'!F34,0) -> 0.10203945 | G15: =IFERROR('Historical FS'!G34,0) -> 0.11930127 | H15: =IFERROR('Historical FS'!H34,0) -> 0.11585931 | I15: =IFERROR('Historical FS'!I34,0) -> 0.1711704 | J15: =IFERROR('Historical FS'!J34,0) -> 0.17878854 | K15: =IFERROR('Historical FS'!K34,0) -> 0.18460281 | ... M15: =IFERROR('Historical FS'!M34,0) -> 0.18435142 | O15: =IFERROR(AVERAGE(D15:M15),0) -> 0.16661145 | P15: =IFERROR(MEDIAN(D15:M15),0) -> 0.17994871
B17: SalesExpenses%Sales | D17: =IFERROR('Historical FS'!D15,0) -> 0.24068673 | E17: =IFERROR('Historical FS'!E15,0) -> 0.18825597 | F17: =IFERROR('Historical FS'!F15,0) -> 0.21434903 | G17: =IFERROR('Historical FS'!G15,0) -> 0.21862587 | H17: =IFERROR('Historical FS'!H15,0) -> 0.24210034 | I17: =IFERROR('Historical FS'!I15,0) -> 0.21269838 | J17: =IFERROR('Historical FS'!J15,0) -> 0.21112838 | K17: =IFERROR('Historical FS'!K15,0) -> 0.23949111 | ... M17: =IFERROR('Historical FS'!M15,0) -> 0.31545763 | O17: =IFERROR(AVERAGE(D17:M17),0) -> 0.23393052 | P17: =IFERROR(MEDIAN(D17:M17),0) -> 0.22905849
B18: Depreciation%Sales | D18: =IFERROR('Historical FS'!D25,0) -> 0.036421136 | E18: =IFERROR('Historical FS'!E25,0) -> 0.04005106 | F18: =IFERROR('Historical FS'!F25,0) -> 0.056620256 | G18: =IFERROR('Historical FS'!G25,0) -> 0.060319804 | H18: =IFERROR('Historical FS'!H25,0) -> 0.062513285 | I18: =IFERROR('Historical FS'!I25,0) -> 0.062091507 | J18: =IFERROR('Historical FS'!J25,0) -> 0.055459017 | K18: =IFERROR('Historical FS'!K25,0) -> 0.057636796 | ... M18: =IFERROR('Historical FS'!M25,0) -> 0.048981864 | O18: =IFERROR(AVERAGE(D18:M18),0) -> 0.053281238 | P18: =IFERROR(MEDIAN(D18:M18),0) -> 0.056039636
B19: OperatingIncome%Sales | D19: =D13 -> 0.25051295 | E19: =E13 -> 0.27985138 | F19: =F13 -> 0.15597071 | G19: =G13 -> 0.15907742 | H19: =H13 -> 0.15013506 | I19: =I13 -> 0.19075716 | J19: =J13 -> 0.20990653 | K19: =K13 -> 0.20783568 | ... M19: =M13 -> 0.2414735 | O19: =IFERROR(AVERAGE(D19:M19),0) -> 0.20612278 | P19: =IFERROR(MEDIAN(D19:M19),0) -> 0.20887111
B21: Return on Capital Employed | D21: =IFERROR(('Historical FS'!D17-'Historical FS'!D24)/SUM('Historical FS'!D48:D50),0) -> 0.17204679 | E21: =IFERROR(('Historical FS'!E17-'Historical FS'!E24)/SUM('Historical FS'!E48:E50),0) -> 0.19016562 | F21: =IFERROR(('Historical FS'!F17-'Historical FS'!F24)/SUM('Historical FS'!F48:F50),0) -> 0.084838452 | G21: =IFERROR(('Historical FS'!G17-'Historical FS'!G24)/SUM('Historical FS'!G48:G50),0) -> 0.089049026 | H21: =IFERROR(('Historical FS'!H17-'Historical FS'!H24)/SUM('Historical FS'!H48:H50),0) -> 0.092014215 | I21: =IFERROR(('Historical FS'!I17-'Historical FS'!I24)/SUM('Historical FS'!I48:I50),0) -> 0.12695882 | J21: =IFERROR(('Historical FS'!J17-'Historical FS'!J24)/SUM('Historical FS'!J48:J50),0) -> 0.16457566 | K21: =IFERROR(('Historical FS'!K17-'Historical FS'!K24)/SUM('Historical FS'!K48:K50),0) -> 0.14505135 | ... M21: =IFERROR(('Historical FS'!M17-'Historical FS'!M24)/SUM('Historical FS'!M48:M50),0) -> 0.17023685 | O21: =IFERROR(AVERAGE(D21:M21),0) -> 0.1391212 | P21: =IFERROR(MEDIAN(D21:M21),0) -> 0.15066329
B22: Retained Earnings% | D22: =IFERROR('Historical FS'!D44,0) -> 0.95777421 | E22: =IFERROR('Historical FS'!E44,0) -> 0.88378472 | F22: =IFERROR('Historical FS'!F44,0) -> 0.82246936 | G22: =IFERROR('Historical FS'!G44,0) -> 0.80972142 | H22: =IFERROR('Historical FS'!H44,0) -> 0.74774282 | I22: =IFERROR('Historical FS'!I44,0) -> 0.68616768 | J22: =IFERROR('Historical FS'!J44,0) -> 0.65282782 | K22: =IFERROR('Historical FS'!K44,0) -> 0.65941773 | ... M22: =IFERROR('Historical FS'!M44,0) -> 0.60394969 | O22: =IFERROR(AVERAGE(D22:M22),0) -> 0.74550768 | P22: =IFERROR(MEDIAN(D22:M22),0) -> 0.71695525
B23: Return on Equity% | D23: =IFERROR('Historical FS'!D33/SUM('Historical FS'!D48:D49),0) -> 0.17279962 | E23: =IFERROR('Historical FS'!E33/SUM('Historical FS'!E48:E49),0) -> 0.1972152 | F23: =IFERROR('Historical FS'!F33/SUM('Historical FS'!F48:F49),0) -> 0.070547639 | G23: =IFERROR('Historical FS'!G33/SUM('Historical FS'!G48:G49),0) -> 0.083740128 | H23: =IFERROR('Historical FS'!H33/SUM('Historical FS'!H48:H49),0) -> 0.08405117 | I23: =IFERROR('Historical FS'!I33/SUM('Historical FS'!I48:I49),0) -> 0.12340824 | J23: =IFERROR('Historical FS'!J33/SUM('Historical FS'!J48:J49),0) -> 0.1439451 | K23: =IFERROR('Historical FS'!K33/SUM('Historical FS'!K48:K49),0) -> 0.14468015 | ... M23: =IFERROR('Historical FS'!M33/SUM('Historical FS'!M48:M49),0) -> 0.13421733 | O23: =IFERROR(AVERAGE(D23:M23),0) -> 0.12925606 | P23: =IFERROR(MEDIAN(D23:M23),0) -> 0.13608666
B24: Self Sustained Growth Rate | D24: =IFERROR(D22*D23,0) -> 0.16550302 | E24: =IFERROR(E22*E23,0) -> 0.17429578 | F24: =IFERROR(F22*F23,0) -> 0.058023271 | G24: =IFERROR(G22*G23,0) -> 0.067806176 | H24: =IFERROR(H22*H23,0) -> 0.062848659 | I24: =IFERROR(I22*I23,0) -> 0.084678747 | J24: =IFERROR(J22*J23,0) -> 0.093971368 | K24: =IFERROR(K22*K23,0) -> 0.095404657 | ... M24: =IFERROR(M22*M23,0) -> 0.081060516 | O24: =IFERROR(AVERAGE(D24:M24),0) -> 0.097067297 | P24: =IFERROR(MEDIAN(D24:M24),0) -> 0.085879762
B25: Interest Coverage Ratio | D25: =IFERROR(('Historical FS'!D17-'Historical FS'!D24)/'Historical FS'!D21,0) -> 13.638808 | E25: =IFERROR(('Historical FS'!E17-'Historical FS'!E24)/'Historical FS'!E21,0) -> 22.104227 | F25: =IFERROR(('Historical FS'!F17-'Historical FS'!F24)/'Historical FS'!F21,0) -> 7.9826497 | G25: =IFERROR(('Historical FS'!G17-'Historical FS'!G24)/'Historical FS'!G21,0) -> 8.327294 | H25: =IFERROR(('Historical FS'!H17-'Historical FS'!H24)/'Historical FS'!H21,0) -> 16.285337 | I25: =IFERROR(('Historical FS'!I17-'Historical FS'!I24)/'Historical FS'!I21,0) -> 45.181433 | J25: =IFERROR(('Historical FS'!J17-'Historical FS'!J24)/'Historical FS'!J21,0) -> 63.712839 | K25: =IFERROR(('Historical FS'!K17-'Historical FS'!K24)/'Historical FS'!K21,0) -> 53.029128 | ... M25: =IFERROR(('Historical FS'!M17-'Historical FS'!M24)/'Historical FS'!M21,0) -> 54.876815 | O25: =IFERROR(AVERAGE(D25:M25),0) -> 32.900623 | P25: =IFERROR(MEDIAN(D25:M25),0) -> 32.985963
B27: Debtor Turnover Ratio | D27: =IFERROR('Historical FS'!D5/'Historical FS'!D60,0) -> 4.2043181 | E27: =IFERROR('Historical FS'!E5/'Historical FS'!E60,0) -> 4.3843051 | F27: =IFERROR('Historical FS'!F5/'Historical FS'!F60,0) -> 3.3894448 | G27: =IFERROR('Historical FS'!G5/'Historical FS'!G60,0) -> 3.2716407 | H27: =IFERROR('Historical FS'!H5/'Historical FS'!H60,0) -> 3.4854754 | I27: =IFERROR('Historical FS'!I5/'Historical FS'!I60,0) -> 3.6967952 | J27: =IFERROR('Historical FS'!J5/'Historical FS'!J60,0) -> 3.6867908 | K27: =IFERROR('Historical FS'!K5/'Historical FS'!K60,0) -> 3.8366605 | ... M27: =IFERROR('Historical FS'!M5/'Historical FS'!M60,0) -> 4.0302006 | O27: =IFERROR(AVERAGE(D27:M27),0) -> 3.8296704 | P27: =IFERROR(MEDIAN(D27:M27),0) -> 3.7667279
